Workbook

Sheet 01-05-24
C1: 45296
C3: MANAGED ACCT | X3: Current | AC3: IBD
H4: Cost | J4: P/L | N4: Group | P4: EPS | R4: pivot | S4: last | W4: cost | X4: Stop | Y4: Stop | Z4: % | AB4: EPS | AC4: Comp
A5: Symbol | B5: Position | C5: Name | D5: Qty | E5: Current | F5: Value | G5: Cost | H5: per share | I5: P/L $ | J5: per sh | K5: Date purch | L5: days held | M5: % incr | N5: Rank | O5: RS | P5: RS | Q5: pivot | R5: -0.07 | S5: low | T5: 0.25 | U5: 0.5 | V5: 1 | W5: -0.07 | X5: Loss | Y5: Loss% | Z5: of port | AB5: Due | AC5: Rank
A7: MNSO | B7: Long | C7: Minoso | D7: =1211.7123+804.6763 -> 2016.3886 | E7: 21.38 | F7: =E7*D7 -> 43110.388 | G7: =25318.9+15999 -> 41317.9 | H7: =G7/D7 -> 20.49104 | I7: =F7-G7 -> 1792.4883 | J7: =E7-H7 -> 0.88895973 | K7: 45135 | L7: =DAYS360(K7,$C$1) -> 157 | M7: =(I7/G7) -> 0.04338285 | N7: 163 | O7: 84 | P7: 98 | Q7: 19.48 | R7: =Q7*0.93 -> 18.1164 | S7: 18.27 | T7: =Q7*1.25 -> 24.35 | U7: =Q7*1.5 -> 29.22 | V7: =Q7*2 -> 38.96 | W7: =H7-(H7*0.07) -> 19.056667 | X7: 26 | Y7: =(X7-H7)/H7 -> 0.26884725 | Z7: =F7/F$19 -> 0.092164222 | AB7: 45350 | AC7: 90 | AD7: Bought after 07/24 b/o. Added at the 21dema.
A8: TS | B8: Long | C8: Tenaris | D8: 1166.935 | E8: 33.95 | F8: =E8*D8 -> 39617.443 | G8: 40941.92 | H8: =G8/D8 -> 35.085005 | I8: =F8-G8 -> -1324.4767 | J8: =E8-H8 -> -1.1350047 | K8: 45233 | L8: =DAYS360(K8,$C$1) -> 62 | M8: =(I8/G8) -> -0.032350138 | N8: 69 | O8: 71 | P8: 69 | Q8: 34.2 | R8: =Q8*0.93 -> 31.806 | S8: 32.69 | T8: =Q8*1.25 -> 42.75 | U8: =Q8*1.5 -> 51.3 | V8: =Q8*2 -> 68.4 | W8: =H8-(H8*0.07) -> 32.629054 | X8: 32.75 | Y8: =(X8-H8)/H8 -> -0.066552784 | Z8: =F8/F$19 -> 0.084696775 | AB8: 45343 | AC8: 80 | AD8: Bought day after gapping out of base.
A9: AXON | B9: Long | C9: Axon Enterprise | D9: 267.8431 | E9: 244.21 | F9: =E9*D9 -> 65409.963 | G9: 61166.24 | H9: =G9/D9 -> 228.36594 | I9: =F9-G9 -> 4243.7235 | J9: =E9-H9 -> 15.844065 | K9: 45238 | L9: =DAYS360(K9,$C$1) -> 57 | M9: =(I9/G9) -> 0.069380159 | N9: 33 | O9: 88 | P9: 99 | Q9: 223.3 | R9: =Q9*0.93 -> 207.669 | S9: 224.28 | T9: =Q9*1.25 -> 279.125 | U9: =Q9*1.5 -> 334.95 | V9: =Q9*2 -> 446.6 | W9: =H9-(H9*0.07) -> 212.38032 | X9: 234 | Y9: =(X9-H9)/H9 -> 0.024671214 | Z9: =F9/F$19 -> 0.13983772 | AB9: 45349 | AC9: 99 | AD9: Bought as it gapped out of base on EPS.
A10: KD | B10: Long | C10: Kyndryl Hldgs | D10: =1160.2602+1046.0778 -> 2206.338 | E10: 19.59 | F10: =E10*D10 -> 43222.161 | G10: =20288.83+19170.47 -> 39459.3 | H10: =G10/D10 -> 17.884522 | I10: =F10-G10 -> 3762.8614 | J10: =E10-H10 -> 1.7054782 | K10: 45243 | L10: =DAYS360(K10,$C$1) -> 52 | M10: =(I10/G10) -> 0.095360572 | N10: 44 | O10: 93 | P10: 73 | Q10: 17.32 | R10: =Q10*0.93 -> 16.1076 | S10: 18.05 | T10: =Q10*1.25 -> 21.65 | U10: =Q10*1.5 -> 25.98 | V10: =Q10*2 -> 34.64 | W10: =H10-(H10*0.07) -> 16.632605 | X10: 18 | Y10: =(X10-H10)/H10 -> 0.0064568809 | Z10: =F10/F$19 -> 0.092403178 | AB10: 45350 | AC10: 86 | AD10: Bought after 11/08 b/o. Trading tightly here.
A11: DDOG | B11: Long | C11: Datadog | D11: 308.2955 | E11: 115.99 | F11: =E11*D11 -> 35759.195 | G11: 38082.35 | H11: =G11/D11 -> 123.52548 | I11: =F11-G11 -> -2323.155 | J11: =E11-H11 -> -7.5354812 | K11: 45286 | L11: =DAYS360(K11,$C$1) -> 9 | M11: =(I11/G11) -> -0.061003456 | N11: 44 | O11: 94 | P11: 99 | Q11: 120.26 | R11: =Q11*0.93 -> 111.8418 | S11: 110.7 | T11: =Q11*1.25 -> 150.325 | U11: =Q11*1.5 -> 180.39 | V11: =Q11*2 -> 240.52 | W11: =H11-(H11*0.07) -> 114.8787 | X11: 116 | Y11: =(X11-H11)/H11 -> -0.060922501 | Z11: =F11/F$19 -> 0.076448358 | AB11: 45337 | AC11: 99 | AD11: Trading tightly since b/o.
A12: YELP | B12: Long | C12: Yelp Inc | D12: 808.573 | E12: 44.97 | F12: =E12*D12 -> 36361.528 | G12: 38349.05 | H12: =G12/D12 -> 47.428062 | I12: =F12-G12 -> -1987.5222 | J12: =E12-H12 -> -2.4580615 | K12: 45288 | L12: =DAYS360(K12,$C$1) -> 7 | M12: =(I12/G12) -> -0.051827156 | N12: 61 | O12: 89 | P12: 83 | Q12: 47 | R12: =Q12*0.93 -> 43.71 | S12: 42.57 | T12: =Q12*1.25 -> 58.75 | U12: =Q12*1.5 -> 70.5 | V12: =Q12*2 -> 94 | W12: =H12-(H12*0.07) -> 44.108097 | X12: 45.75 | Y12: =(X12-H12)/H12 -> -0.035381196 | Z12: =F12/F$19 -> 0.077736065 | AB12: 45330 | AC12: 96 | AD12: Bought the pivot test.
F13: =E13*D13 -> 0 | H13: =G13/D13 -> #DIV/0! | I13: =F13-G13 -> 0 | J13: =E13-H13 -> #DIV/0! | L13: =DAYS360(K13,$C$1) -> 44645 | M13: =(I13/G13) -> #DIV/0! | R13: =Q13*0.93 -> 0 | T13: =Q13*1.25 -> 0 | U13: =Q13*1.5 -> 0 | V13: =Q13*2 -> 0 | W13: =H13-(H13*0.07) -> #DIV/0! | Y13: =(X13-H13)/H13 -> #DIV/0! | Z13: =F13/F$19 -> 0
A14: BIL | B14: Long | C14: Tbill ETF | D14: =2223.78-868.0181 -> 1355.7619 | E14: 91.47 | F14: =E14*D14 -> 124011.54 | G14: =203698.25-79510.46 -> 124187.79 | H14: =G14/D14 -> 91.6 | I14: =F14-G14 -> -176.24901 | J14: =E14-H14 -> -0.12999997 | M14: =(I14/G14) -> -0.0014192137 | R14: =Q14*0.93 -> 0 | T14: =Q14*1.25 -> 0 | U14: =Q14*1.5 -> 0 | V14: =Q14*2 -> 0 | W14: =H14-(H14*0.07) -> 85.188 | Y14: =(X14-H14)/H14 -> -1 | Z14: =F14/F$19 -> 0.26512003
F15: =E15*D15 -> 0 | H15: =G15/D15 -> #DIV/0! | I15: =F15-G15 -> 0 | J15: =E15-H15 -> #DIV/0! | M15: =(I15/G15) -> #DIV/0! | R15: =Q15*0.93 -> 0 | T15: =Q15*1.25 -> 0 | U15: =Q15*1.5 -> 0 | V15: =Q15*2 -> 0 | W15: =H15-(H15*0.07) -> #DIV/0! | Y15: =(X15-H15)/H15 -> #DIV/0! | Z15: =F15/F$19 -> 0
F16: =E16*D16 -> 0 | H16: =G16/D16 -> #DIV/0! | I16: =F16-G16 -> 0 | J16: =E16-H16 -> #DIV/0! | L16: =DAYS360(K16,$C$1) -> 44645 | M16: =(I16/G16) -> #DIV/0! | R16: =Q16*0.93 -> 0 | T16: =Q16*1.25 -> 0 | U16: =Q16*1.5 -> 0 | V16: =Q16*2 -> 0 | W16: =H16-(H16*0.07) -> #DIV/0! | Y16: =(X16-H16)/H16 -> #DIV/0! | Z16: =F16/F$19 -> 0
A17: Sub-Total | F17: =SUM(F6:F16) -> 387492.22 | G17: =SUM(G6:G16) -> 383504.55 | I17: =SUM(I6:I16) -> 3987.6702
D18: Cash, other | F18: 80264 | G18: =F18/F19 -> 0.17159366
D19: Total | F19: =SUM(F17:F18) -> 467756.22
H20: Last week's close | I20: 476160.6 | K20: 45291 | L20: 476160.6
A21: * | H21: Week's change | I21: =(F19-I20)/I20 -> -0.017650305 | K21: chg % | L21: =(F19-L20)/L20 -> -0.017650305
M23: days
A24: 2024 Closed Trades - Managed Acct | D24: Qty | E24: Cost/sh | F24: $ cost | G24: $Proc | H24: Proc/sh | I24: Profit/loss | J24: % | K24: Date purch | L24: Date sold | M24: held | P24: Comments
I39: =SUM(I26:I38) -> 0 | J39: Avg
H40: # of losses
H41: # of wins

Sheet 01-12-24
C1: 45303
C3: MANAGED ACCT | X3: Current | AC3: IBD
H4: Cost | J4: P/L | N4: Group | P4: EPS | R4: pivot | S4: last | W4: cost | X4: Stop | Y4: Stop | Z4: % | AB4: EPS | AC4: Comp
A5: Symbol | B5: Position | C5: Name | D5: Qty | E5: Current | F5: Value | G5: Cost | H5: per share | I5: P/L $ | J5: per sh | K5: Date purch | L5: days held | M5: % incr | N5: Rank | O5: RS | P5: RS | Q5: pivot | R5: -0.07 | S5: low | T5: 0.25 | U5: 0.5 | V5: 1 | W5: -0.07 | X5: Loss | Y5: Loss% | Z5: of port | AB5: Due | AC5: Rank
A7: MNSO | B7: Long | C7: Minoso | D7: =1211.7123+804.6763 -> 2016.3886 | E7: 22.49 | F7: =E7*D7 -> 45348.58 | G7: =25318.9+15999 -> 41317.9 | H7: =G7/D7 -> 20.49104 | I7: =F7-G7 -> 4030.6796 | J7: =E7-H7 -> 1.9989597 | K7: 45135 | L7: =DAYS360(K7,$C$1) -> 164 | M7: =(I7/G7) -> 0.097552867 | N7: 178 | O7: 83 | P7: 98 | Q7: 19.48 | R7: =Q7*0.93 -> 18.1164 | S7: 18.27 | T7: =Q7*1.25 -> 24.35 | U7: =Q7*1.5 -> 29.22 | V7: =Q7*2 -> 38.96 | W7: =H7-(H7*0.07) -> 19.056667 | X7: 26 | Y7: =(X7-H7)/H7 -> 0.26884725 | Z7: =F7/F$19 -> 0.095391952 | AB7: 45350 | AC7: 89 | AD7: Bought after 07/24 b/o. Added at the 21dema.
A8: TS | B8: Long | C8: Tenaris | D8: 1166.935 | E8: 32.31 | F8: =E8*D8 -> 37703.67 | G8: 40941.92 | H8: =G8/D8 -> 35.085005 | I8: =F8-G8 -> -3238.2501 | J8: =E8-H8 -> -2.7750047 | K8: 45233 | L8: =DAYS360(K8,$C$1) -> 69 | M8: =(I8/G8) -> -0.079093754 | N8: 111 | O8: 35 | P8: 69 | Q8: 34.2 | R8: =Q8*0.93 -> 31.806 | S8: 32.69 | T8: =Q8*1.25 -> 42.75 | U8: =Q8*1.5 -> 51.3 | V8: =Q8*2 -> 68.4 | W8: =H8-(H8*0.07) -> 32.629054 | X8: 32.75 | Y8: =(X8-H8)/H8 -> -0.066552784 | Z8: =F8/F$19 -> 0.07931068 | AB8: 45343 | AC8: 58 | AD8: Bought day after gapping out of base.
A9: AXON | B9: Long | C9: Axon Enterprise | D9: 267.8431 | E9: 250.69 | F9: =E9*D9 -> 67145.587 | G9: 61166.24 | H9: =G9/D9 -> 228.36594 | I9: =F9-G9 -> 5979.3467 | J9: =E9-H9 -> 22.324065 | K9: 45238 | L9: =DAYS360(K9,$C$1) -> 64 | M9: =(I9/G9) -> 0.097755669 | N9: 29 | O9: 87 | P9: 99 | Q9: 223.3 | R9: =Q9*0.93 -> 207.669 | S9: 224.28 | T9: =Q9*1.25 -> 279.125 | U9: =Q9*1.5 -> 334.95 | V9: =Q9*2 -> 446.6 | W9: =H9-(H9*0.07) -> 212.38032 | X9: 234 | Y9: =(X9-H9)/H9 -> 0.024671214 | Z9: =F9/F$19 -> 0.14124254 | AB9: 45349 | AC9: 99 | AD9: Bought as it gapped out of base on EPS.
A10: KD | B10: Long | C10: Kyndryl Hldgs | D10: =1160.2602+1046.0778 -> 2206.338 | E10: 21.08 | F10: =E10*D10 -> 46509.605 | G10: =20288.83+19170.47 -> 39459.3 | H10: =G10/D10 -> 17.884522 | I10: =F10-G10 -> 7050.305 | J10: =E10-H10 -> 3.1954782 | K10: 45243 | L10: =DAYS360(K10,$C$1) -> 59 | M10: =(I10/G10) -> 0.17867284 | N10: 34 | O10: 93 | P10: 73 | Q10: 17.32 | R10: =Q10*0.93 -> 16.1076 | S10: 18.05 | T10: =Q10*1.25 -> 21.65 | U10: =Q10*1.5 -> 25.98 | V10: =Q10*2 -> 34.64 | W10: =H10-(H10*0.07) -> 16.632605 | X10: 18 | Y10: =(X10-H10)/H10 -> 0.0064568809 | Z10: =F10/F$19 -> 0.0978342 | AB10: 45328 | AC10: 90 | AD10: Bought after 11/08 b/o. Trading tightly here.
A11: DDOG | B11: Long | C11: Datadog | D11: 308.2955 | E11: 123 | F11: =E11*D11 -> 37920.346 | G11: 38082.35 | H11: =G11/D11 -> 123.52548 | I11: =F11-G11 -> -162.0035 | J11: =E11-H11 -> -0.52548123 | K11: 45286 | L11: =DAYS360(K11,$C$1) -> 16 | M11: =(I11/G11) -> -0.0042540311 | N11: 34 | O11: 95 | P11: 99 | Q11: 120.26 | R11: =Q11*0.93 -> 111.8418 | S11: 110.7 | T11: =Q11*1.25 -> 150.325 | U11: =Q11*1.5 -> 180.39 | V11: =Q11*2 -> 240.52 | W11: =H11-(H11*0.07) -> 114.8787 | X11: 116 | Y11: =(X11-H11)/H11 -> -0.060922501 | Z11: =F11/F$19 -> 0.079766465 | AB11: 45337 | AC11: 99 | AD11: Trading tightly since b/o.
F12: =E12*D12 -> 0 | H12: =G12/D12 -> #DIV/0! | I12: =F12-G12 -> 0 | J12: =E12-H12 -> #DIV/0! | L12: =DAYS360(K12,$C$1) -> 44652 | M12: =(I12/G12) -> #DIV/0! | R12: =Q12*0.93 -> 0 | T12: =Q12*1.25 -> 0 | U12: =Q12*1.5 -> 0 | V12: =Q12*2 -> 0 | W12: =H12-(H12*0.07) -> #DIV/0! | Y12: =(X12-H12)/H12 -> #DIV/0! | Z12: =F12/F$19 -> 0
A13: ACMR | B13: Long | C13: ACM Research | D13: 1339.9646 | E13: 21.81 | F13: =E13*D13 -> 29224.628 | G13: 28457.8 | H13: =G13/D13 -> 21.237725 | I13: =F13-G13 -> 766.82793 | J13: =E13-H13 -> 0.57227476 | K13: 45302 | L13: =DAYS360(K13,$C$1) -> 1 | M13: =(I13/G13) -> 0.026946142 | N13: 85 | O13: 95 | P13: 99 | Q13: 20.43 | R13: =Q13*0.93 -> 18.9999 | S13: 16.66 | T13: =Q13*1.25 -> 25.5375 | U13: =Q13*1.5 -> 30.645 | V13: =Q13*2 -> 40.86 | W13: =H13-(H13*0.07) -> 19.751084 | X13: 19.75 | Y13: =(X13-H13)/H13 -> -0.070051063 | Z13: =F13/F$19 -> 0.061474788 | AB13: 45345 | AC13: 98 | AD13: B/o Jan 10in big vol.
A14: BIL | B14: Long | C14: Tbill ETF | D14: =2223.78-868.0181 -> 1355.7619 | E14: 91.58 | F14: =E14*D14 -> 124160.67 | G14: =203698.25-79510.46 -> 124187.79 | H14: =G14/D14 -> 91.6 | I14: =F14-G14 -> -27.115198 | J14: =E14-H14 -> -0.01999997 | M14: =(I14/G14) -> -0.00021834029 | R14: =Q14*0.93 -> 0 | T14: =Q14*1.25 -> 0 | U14: =Q14*1.5 -> 0 | V14: =Q14*2 -> 0 | W14: =H14-(H14*0.07) -> 85.188 | Y14: =(X14-H14)/H14 -> -1 | Z14: =F14/F$19 -> 0.26117531
F15: =E15*D15 -> 0 | H15: =G15/D15 -> #DIV/0! | I15: =F15-G15 -> 0 | J15: =E15-H15 -> #DIV/0! | M15: =(I15/G15) -> #DIV/0! | R15: =Q15*0.93 -> 0 | T15: =Q15*1.25 -> 0 | U15: =Q15*1.5 -> 0 | V15: =Q15*2 -> 0 | W15: =H15-(H15*0.07) -> #DIV/0! | Y15: =(X15-H15)/H15 -> #DIV/0! | Z15: =F15/F$19 -> 0
F16: =E16*D16 -> 0 | H16: =G16/D16 -> #DIV/0! | I16: =F16-G16 -> 0 | J16: =E16-H16 -> #DIV/0! | L16: =DAYS360(K16,$C$1) -> 44652 | M16: =(I16/G16) -> #DIV/0! | R16: =Q16*0.93 -> 0 | T16: =Q16*1.25 -> 0 | U16: =Q16*1.5 -> 0 | V16: =Q16*2 -> 0 | W16: =H16-(H16*0.07) -> #DIV/0! | Y16: =(X16-H16)/H16 -> #DIV/0! | Z16: =F16/F$19 -> 0
A17: Sub-Total | F17: =SUM(F6:F16) -> 388013.09 | G17: =SUM(G6:G16) -> 373613.3 | I17: =SUM(I6:I16) -> 14399.79
D18: Cash, other | F18: 87379 | G18: =F18/F19 -> 0.18380407
D19: Total | F19: =SUM(F17:F18) -> 475392.09
H20: Last week's close | I20: ='01-05-24'!F19 -> 467756.22 | K20: 45291 | L20: 476160.6
A21: * | H21: Week's change | I21: =(F19-I20)/I20 -> 0.016324465 | K21: chg % | L21: =(F19-L20)/L20 -> -0.0016139713
M23: days
A24: 2024 Closed Trades - Managed Acct | D24: Qty | E24: Cost/sh | F24: $ cost | G24: $Proc | H24: Proc/sh | I24: Profit/loss | J24: % | K24: Date purch | L24: Date sold | M24: held | P24: Comments
A25: YELP | B25: Long | C25: Yelp Inc | D25: 808.573 | E25: =F25/D25 -> 47.428062 | F25: 38349.05 | G25: 35186.18 | H25: =G25/D25 -> 43.516392 | I25: =G25-F25 -> -3162.87 | J25: =I25/F25 -> -0.082475837 | K25: 45286 | L25: 45302 | M25: =DAYS360(K25,L25) -> 15 | O25: Closed below stop for 2 days.
I39: =SUM(I26:I38) -> 0 | J39: Avg
H40: # of losses
H41: # of wins

Sheet 01-19-24
C1: 45310
C3: MANAGED ACCT | X3: Current | AC3: IBD
H4: Cost | J4: P/L | N4: Group | P4: EPS | R4: pivot | S4: last | W4: cost | X4: Stop | Y4: Stop | Z4: % | AB4: EPS | AC4: Comp
A5: Symbol | B5: Position | C5: Name | D5: Qty | E5: Current | F5: Value | G5: Cost | H5: per share | I5: P/L $ | J5: per sh | K5: Date purch | L5: days held | M5: % incr | N5: Rank | O5: RS | P5: RS | Q5: pivot | R5: -0.07 | S5: low | T5: 0.25 | U5: 0.5 | V5: 1 | W5: -0.07 | X5: Loss | Y5: Loss% | Z5: of port | AB5: Due | AC5: Rank
A7: AXON | B7: Long | C7: Axon Enterprise | D7: 267.8431 | E7: 256.79 | F7: =E7*D7 -> 68779.43 | G7: 61166.24 | H7: =G7/D7 -> 228.36594 | I7: =F7-G7 -> 7613.1896 | J7: =E7-H7 -> 28.424065 | K7: 45238 | L7: =DAYS360(K7,$C$1) -> 71 | M7: =(I7/G7) -> 0.12446718 | N7: 25 | O7: 89 | P7: 99 | Q7: 223.3 | R7: =Q7*0.93 -> 207.669 | S7: 224.28 | T7: =Q7*1.25 -> 279.125 | U7: =Q7*1.5 -> 334.95 | V7: =Q7*2 -> 446.6 | W7: =H7-(H7*0.07) -> 212.38032 | X7: 234 | Y7: =(X7-H7)/H7 -> 0.024671214 | Z7: =F7/F$19 -> 0.14531856 | AB7: 45349 | AC7: 99 | AD7: Bought as it gapped out of base on EPS.
A8: KD | B8: Long | C8: Kyndryl Hldgs | D8: =1160.2602+1046.0778 -> 2206.338 | E8: 20.88 | F8: =E8*D8 -> 46068.337 | G8: =20288.83+19170.47 -> 39459.3 | H8: =G8/D8 -> 17.884522 | I8: =F8-G8 -> 6609.0374 | J8: =E8-H8 -> 2.9954782 | K8: 45243 | L8: =DAYS360(K8,$C$1) -> 66 | M8: =(I8/G8) -> 0.16748998 | N8: 28 | O8: 95 | P8: 74 | Q8: 17.32 | R8: =Q8*0.93 -> 16.1076 | S8: 18.05 | T8: =Q8*1.25 -> 21.65 | U8: =Q8*1.5 -> 25.98 | V8: =Q8*2 -> 34.64 | W8: =H8-(H8*0.07) -> 16.632605 | X8: 19 | Y8: =(X8-H8)/H8 -> 0.062371152 | Z8: =F8/F$19 -> 0.097334108 | AB8: 45328 | AC8: 91 | AD8: Bought after 11/08 b/o. Trading tightly here.
A9: DDOG | B9: Long | C9: Datadog | D9: 308.2955 | E9: 130.31 | F9: =E9*D9 -> 40173.987 | G9: 38082.35 | H9: =G9/D9 -> 123.52548 | I9: =F9-G9 -> 2091.6366 | J9: =E9-H9 -> 6.7845188 | K9: 45286 | L9: =DAYS360(K9,$C$1) -> 23 | M9: =(I9/G9) -> 0.054924042 | N9: 28 | O9: 96 | P9: 99 | Q9: 120.26 | R9: =Q9*0.93 -> 111.8418 | S9: 110.7 | T9: =Q9*1.25 -> 150.325 | U9: =Q9*1.5 -> 180.39 | V9: =Q9*2 -> 240.52 | W9: =H9-(H9*0.07) -> 114.8787 | X9: 116 | Y9: =(X9-H9)/H9 -> -0.060922501 | Z9: =F9/F$19 -> 0.084880405 | AB9: 45335 | AC9: 99 | AD9: Trading tightly since b/o.
A10: ACMR | B10: Long | C10: ACM Research | D10: 1339.9646 | E10: 20.46 | F10: =E10*D10 -> 27415.676 | G10: 28457.8 | H10: =G10/D10 -> 21.237725 | I10: =F10-G10 -> -1042.1243 | J10: =E10-H10 -> -0.77772524 | K10: 45302 | L10: =DAYS360(K10,$C$1) -> 8 | M10: =(I10/G10) -> -0.036619988 | N10: 23 | O10: 95 | P10: 99 | Q10: 20.43 | R10: =Q10*0.93 -> 18.9999 | S10: 16.66 | T10: =Q10*1.25 -> 25.5375 | U10: =Q10*1.5 -> 30.645 | V10: =Q10*2 -> 40.86 | W10: =H10-(H10*0.07) -> 19.751084 | X10: 19.75 | Y10: =(X10-H10)/H10 -> -0.070051063 | Z10: =F10/F$19 -> 0.05792439 | AB10: 45345 | AC10: 99 | AD10: B/o Jan 10in big vol.
A11: VKTX | B11: Long | C11: Viking Therap | D11: =1286.8297+948.5633 -> 2235.393 | E11: 21.77 | F11: =E11*D11 -> 48664.506 | G11: =28174.78+19947.6 -> 48122.38 | H11: =G11/D11 -> 21.527481 | I11: =F11-G11 -> 542.12561 | J11: =E11-H11 -> 0.24251915 | K11: 45309 | L11: =DAYS360(K11,$C$1) -> 1 | M11: =(I11/G11) -> 0.011265561 | N11: 4 | O11: 98 | P11: 22 | Q11: 20.03 | R11: =Q11*0.93 -> 18.6279 | S11: 20.28 | T11: =Q11*1.25 -> 25.0375 | U11: =Q11*1.5 -> 30.045 | V11: =Q11*2 -> 40.06 | W11: =H11-(H11*0.07) -> 20.020557 | X11: 19.75 | Y11: =(X11-H11)/H11 -> -0.082567991 | Z11: =F11/F$19 -> 0.10281934 | AB11: 45329 | AC11: 74 | AD11: Bought after pivot test.
F12: =E12*D12 -> 0 | H12: =G12/D12 -> #DIV/0! | I12: =F12-G12 -> 0 | J12: =E12-H12 -> #DIV/0! | L12: =DAYS360(K12,$C$1) -> 44659 | M12: =(I12/G12) -> #DIV/0! | R12: =Q12*0.93 -> 0 | T12: =Q12*1.25 -> 0 | U12: =Q12*1.5 -> 0 | V12: =Q12*2 -> 0 | W12: =H12-(H12*0.07) -> #DIV/0! | Y12: =(X12-H12)/H12 -> #DIV/0! | Z12: =F12/F$19 -> 0
F13: =E13*D13 -> 0 | H13: =G13/D13 -> #DIV/0! | I13: =F13-G13 -> 0 | J13: =E13-H13 -> #DIV/0! | L13: =DAYS360(K13,$C$1) -> 44659 | M13: =(I13/G13) -> #DIV/0! | R13: =Q13*0.93 -> 0 | T13: =Q13*1.25 -> 0 | U13: =Q13*1.5 -> 0 | V13: =Q13*2 -> 0 | W13: =H13-(H13*0.07) -> #DIV/0! | Y13: =(X13-H13)/H13 -> #DIV/0! | Z13: =F13/F$19 -> 0
A14: BIL | B14: Long | C14: Tbill ETF | D14: =2223.78-868.0181 -> 1355.7619 | E14: 91.66 | F14: =E14*D14 -> 124269.14 | G14: =203698.25-79510.46 -> 124187.79 | H14: =G14/D14 -> 91.6 | I14: =F14-G14 -> 81.345754 | J14: =E14-H14 -> 0.06000003 | M14: =(I14/G14) -> 0.00065502216 | R14: =Q14*0.93 -> 0 | T14: =Q14*1.25 -> 0 | U14: =Q14*1.5 -> 0 | V14: =Q14*2 -> 0 | W14: =H14-(H14*0.07) -> 85.188 | Y14: =(X14-H14)/H14 -> -1 | Z14: =F14/F$19 -> 0.26255832
F15: =E15*D15 -> 0 | H15: =G15/D15 -> #DIV/0! | I15: =F15-G15 -> 0 | J15: =E15-H15 -> #DIV/0! | M15: =(I15/G15) -> #DIV/0! | R15: =Q15*0.93 -> 0 | T15: =Q15*1.25 -> 0 | U15: =Q15*1.5 -> 0 | V15: =Q15*2 -> 0 | W15: =H15-(H15*0.07) -> #DIV/0! | Y15: =(X15-H15)/H15 -> #DIV/0! | Z15: =F15/F$19 -> 0
F16: =E16*D16 -> 0 | H16: =G16/D16 -> #DIV/0! | I16: =F16-G16 -> 0 | J16: =E16-H16 -> #DIV/0! | L16: =DAYS360(K16,$C$1) -> 44659 | M16: =(I16/G16) -> #DIV/0! | R16: =Q16*0.93 -> 0 | T16: =Q16*1.25 -> 0 | U16: =Q16*1.5 -> 0 | V16: =Q16*2 -> 0 | W16: =H16-(H16*0.07) -> #DIV/0! | Y16: =(X16-H16)/H16 -> #DIV/0! | Z16: =F16/F$19 -> 0
A17: Sub-Total | F17: =SUM(F6:F16) -> 355371.07 | G17: =SUM(G6:G16) -> 339475.86 | I17: =SUM(I6:I16) -> 15895.211
D18: Cash, other | F18: 117930 | G18: =F18/F19 -> 0.24916487
D19: Total | F19: =SUM(F17:F18) -> 473301.07
H20: Last week's close | I20: ='01-12-24'!F19 -> 475392.09 | K20: 45291 | L20: 476160.6
A21: * | H21: Week's change | I21: =(F19-I20)/I20 -> -0.004398516 | K21: chg % | L21: =(F19-L20)/L20 -> -0.0060053882
M23: days
A24: 2024 Closed Trades - Managed Acct | D24: Qty | E24: Cost/sh | F24: $ cost | G24: $Proc | H24: Proc/sh | I24: Profit/loss | J24: % | K24: Date purch | L24: Date sold | M24: held | P24: Comments
A25: YELP | B25: Long | C25: Yelp Inc | D25: 808.573 | E25: =F25/D25 -> 47.428062 | F25: 38349.05 | G25: 35186.18 | H25: =G25/D25 -> 43.516392 | I25: =G25-F25 -> -3162.87 | J25: =I25/F25 -> -0.082475837 | K25: 45286 | L25: 45302 | M25: =DAYS360(K25,L25) -> 15 | O25: Closed below stop for 2 days.
A26: TS | B26: Long | C26: Tenaris | D26: 1166.935 | E26: =F26/D26 -> 35.085005 | F26: 40941.92 | G26: 36634.59 | H26: =G26/D26 -> 31.393857 | I26: =G26-F26 -> -4307.33 | J26: =I26/F26 -> -0.10520586 | K26: 45233 | L26: 45307 | M26: =DAYS360(K26,L26) -> 73
B27: Long | C27: Minoso | D27: =1211.7123+804.6763 -> 2016.3886 | E27: =F27/D27 -> 20.49104 | F27: 41317.9 | G27: 42071.53 | H27: =G27/D27 -> 20.864793 | I27: =G27-F27 -> 753.63 | J27: =I27/F27 -> 0.018239794 | K27: 45135 | L27: 45308 | M27: =DAYS360(K27,L27) -> 169 | O27: Totally blew this trade. Had a nearly 50% profit.
I39: =SUM(I26:I38) -> -3553.7 | J39: Avg
H40: # of losses
H41: # of wins

Sheet 01-26-24
C1: 45317
C3: MANAGED ACCT | X3: Current | AC3: IBD
H4: Cost | J4: P/L | N4: Group | P4: EPS | R4: pivot | S4: last | W4: cost | X4: Stop | Y4: Stop | Z4: % | AB4: EPS | AC4: Comp
A5: Symbol | B5: Position | C5: Name | D5: Qty | E5: Current | F5: Value | G5: Cost | H5: per share | I5: P/L $ | J5: per sh | K5: Date purch | L5: days held | M5: % incr | N5: Rank | O5: RS | P5: RS | Q5: pivot | R5: -0.07 | S5: low | T5: 0.25 | U5: 0.5 | V5: 1 | W5: -0.07 | X5: Loss | Y5: Loss% | Z5: of port | AB5: Due | AC5: Rank
A7: AXON | B7: Long | C7: Axon Enterprise | D7: 267.8431 | E7: 251.36 | F7: =E7*D7 -> 67325.042 | G7: 61166.24 | H7: =G7/D7 -> 228.36594 | I7: =F7-G7 -> 6158.8016 | J7: =E7-H7 -> 22.994065 | K7: 45238 | L7: =DAYS360(K7,$C$1) -> 78 | M7: =(I7/G7) -> 0.10068956 | N7: 27 | O7: 87 | P7: 99 | Q7: 223.3 | R7: =Q7*0.93 -> 207.669 | S7: 241.72 | T7: =Q7*1.25 -> 279.125 | U7: =Q7*1.5 -> 334.95 | V7: =Q7*2 -> 446.6 | W7: =H7-(H7*0.07) -> 212.38032 | X7: 234 | Y7: =(X7-H7)/H7 -> 0.024671214 | Z7: =F7/F$19 -> 0.144941 | AB7: 45349 | AC7: 99 | AD7: Bought as it gapped out of base on EPS.
A8: KD | B8: Long | C8: Kyndryl Hldgs | D8: =1160.2602+1046.0778 -> 2206.338 | E8: 21.21 | F8: =E8*D8 -> 46796.429 | G8: =20288.83+19170.47 -> 39459.3 | H8: =G8/D8 -> 17.884522 | I8: =F8-G8 -> 7337.129 | J8: =E8-H8 -> 3.3254782 | K8: 45243 | L8: =DAYS360(K8,$C$1) -> 73 | M8: =(I8/G8) -> 0.18594169 | N8: 26 | O8: 95 | P8: 74 | Q8: 17.32 | R8: =Q8*0.93 -> 16.1076 | S8: 18.05 | T8: =Q8*1.25 -> 21.65 | U8: =Q8*1.5 -> 25.98 | V8: =Q8*2 -> 34.64 | W8: =H8-(H8*0.07) -> 16.632605 | X8: 19 | Y8: =(X8-H8)/H8 -> 0.062371152 | Z8: =F8/F$19 -> 0.10074589 | AB8: 45328 | AC8: 90 | AD8: Bought after 11/08 b/o. Trading tightly here.
A9: DDOG | B9: Long | C9: Datadog | D9: =308.2955+142.5312 -> 450.8267 | E9: 123.95 | F9: =E9*D9 -> 55879.969 | G9: =38082.35+18004.55 -> 56086.9 | H9: =G9/D9 -> 124.409 | I9: =F9-G9 -> -206.93053 | J9: =E9-H9 -> -0.45900239 | K9: 45286 | L9: =DAYS360(K9,$C$1) -> 30 | M9: =(I9/G9) -> -0.0036894629 | N9: 26 | O9: 94 | P9: 99 | Q9: 120.26 | R9: =Q9*0.93 -> 111.8418 | S9: 110.7 | T9: =Q9*1.25 -> 150.325 | U9: =Q9*1.5 -> 180.39 | V9: =Q9*2 -> 240.52 | W9: =H9-(H9*0.07) -> 115.70037 | X9: 116 | Y9: =(X9-H9)/H9 -> -0.067591591 | Z9: =F9/F$19 -> 0.12030143 | AB9: 45335 | AC9: 99 | AD9: Trading tightly since b/o.
A10: ACMR | B10: Long | C10: ACM Research | D10: =1339.9646+918.07 -> 2258.0346 | E10: 18.98 | F10: =E10*D10 -> 42857.497 | G10: =28457.8+19398.39 -> 47856.19 | H10: =G10/D10 -> 21.193736 | I10: =F10-G10 -> -4998.6933 | J10: =E10-H10 -> -2.2137364 | K10: 45302 | L10: =DAYS360(K10,$C$1) -> 15 | M10: =(I10/G10) -> -0.10445239 | N10: 23 | O10: 95 | P10: 99 | Q10: 20.43 | R10: =Q10*0.93 -> 18.9999 | S10: 16.66 | T10: =Q10*1.25 -> 25.5375 | U10: =Q10*1.5 -> 30.645 | V10: =Q10*2 -> 40.86 | W10: =H10-(H10*0.07) -> 19.710175 | X10: 19.75 | Y10: =(X10-H10)/H10 -> -0.068120898 | Z10: =F10/F$19 -> 0.092265941 | AB10: 45345 | AC10: 99 | AD10: B/o Jan 10in big vol.
A11: VKTX | B11: Long | C11: Viking Therap | D11: =1286.8297+948.5633 -> 2235.393 | E11: 21.37 | F11: =E11*D11 -> 47770.348 | G11: =28174.78+19947.6 -> 48122.38 | H11: =G11/D11 -> 21.527481 | I11: =F11-G11 -> -352.03159 | J11: =E11-H11 -> -0.15748085 | K11: 45309 | L11: =DAYS360(K11,$C$1) -> 8 | M11: =(I11/G11) -> -0.0073153404 | N11: 3 | O11: 98 | P11: 23 | Q11: 20.03 | R11: =Q11*0.93 -> 18.6279 | S11: 20.28 | T11: =Q11*1.25 -> 25.0375 | U11: =Q11*1.5 -> 30.045 | V11: =Q11*2 -> 40.06 | W11: =H11-(H11*0.07) -> 20.020557 | X11: 19.75 | Y11: =(X11-H11)/H11 -> -0.082567991 | Z11: =F11/F$19 -> 0.10284259 | AB11: 45329 | AC11: 74 | AD11: Bought after pivot test.
A12: AAON | B12: Long | C12: AAON | D12: 532.4164 | E12: 69.94 | F12: =E12*D12 -> 37237.203 | G12: 38270.34 | H12: =G12/D12 -> 71.880468 | I12: =F12-G12 -> -1033.137 | J12: =E12-H12 -> -1.940468 | K12: 45313 | L12: =DAYS360(K12,$C$1) -> 4 | M12: =(I12/G12) -> -0.026995762 | N12: 42 | O12: 84 | P12: 98 | Q12: 71.39 | R12: =Q12*0.93 -> 66.3927 | S12: 70.32 | T12: =Q12*1.25 -> 89.2375 | U12: =Q12*1.5 -> 107.085 | V12: =Q12*2 -> 142.78 | W12: =H12-(H12*0.07) -> 66.848835 | X12: 67.5 | Y12: =(X12-H12)/H12 -> -0.060941005 | Z12: =F12/F$19 -> 0.080166268 | AB12: 45351 | AC12: 99 | AD12: Bought after pivot test.
F13: =E13*D13 -> 0 | H13: =G13/D13 -> #DIV/0! | I13: =F13-G13 -> 0 | J13: =E13-H13 -> #DIV/0! | L13: =DAYS360(K13,$C$1) -> 44666 | M13: =(I13/G13) -> #DIV/0! | R13: =Q13*0.93 -> 0 | T13: =Q13*1.25 -> 0 | U13: =Q13*1.5 -> 0 | V13: =Q13*2 -> 0 | W13: =H13-(H13*0.07) -> #DIV/0! | Y13: =(X13-H13)/H13 -> #DIV/0! | Z13: =F13/F$19 -> 0
A14: BIL | B14: Long | C14: Tbill ETF | D14: =2223.78-868.0181 -> 1355.7619 | E14: 91.75 | F14: =E14*D14 -> 124391.15 | G14: =203698.25-79510.46 -> 124187.79 | H14: =G14/D14 -> 91.6 | I14: =F14-G14 -> 203.36433 | J14: =E14-H14 -> 0.15000003 | M14: =(I14/G14) -> 0.0016375549 | R14: =Q14*0.93 -> 0 | T14: =Q14*1.25 -> 0 | U14: =Q14*1.5 -> 0 | V14: =Q14*2 -> 0 | W14: =H14-(H14*0.07) -> 85.188 | Y14: =(X14-H14)/H14 -> -1 | Z14: =F14/F$19 -> 0.26779602
F15: =E15*D15 -> 0 | H15: =G15/D15 -> #DIV/0! | I15: =F15-G15 -> 0 | J15: =E15-H15 -> #DIV/0! | M15: =(I15/G15) -> #DIV/0! | R15: =Q15*0.93 -> 0 | T15: =Q15*1.25 -> 0 | U15: =Q15*1.5 -> 0 | V15: =Q15*2 -> 0 | W15: =H15-(H15*0.07) -> #DIV/0! | Y15: =(X15-H15)/H15 -> #DIV/0! | Z15: =F15/F$19 -> 0
F16: =E16*D16 -> 0 | H16: =G16/D16 -> #DIV/0! | I16: =F16-G16 -> 0 | J16: =E16-H16 -> #DIV/0! | L16: =DAYS360(K16,$C$1) -> 44666 | M16: =(I16/G16) -> #DIV/0! | R16: =Q16*0.93 -> 0 | T16: =Q16*1.25 -> 0 | U16: =Q16*1.5 -> 0 | V16: =Q16*2 -> 0 | W16: =H16-(H16*0.07) -> #DIV/0! | Y16: =(X16-H16)/H16 -> #DIV/0! | Z16: =F16/F$19 -> 0
A17: Sub-Total | F17: =SUM(F6:F16) -> 422257.64 | G17: =SUM(G6:G16) -> 415149.14 | I17: =SUM(I6:I16) -> 7108.5025
D18: Cash, other | F18: 42242 | G18: =F18/F19 -> 0.090940867
D19: Total | F19: =SUM(F17:F18) -> 464499.64
H20: Last week's close | I20: ='01-19-24'!F19 -> 473301.07 | K20: 45291 | L20: 476160.6
A21: * | H21: Week's change | I21: =(F19-I20)/I20 -> -0.018595834 | K21: chg % | L21: =(F19-L20)/L20 -> -0.024489547
M23: days
A24: 2024 Closed Trades - Managed Acct | D24: Qty | E24: Cost/sh | F24: $ cost | G24: $Proc | H24: Proc/sh | I24: Profit/loss | J24: % | K24: Date purch | L24: Date sold | M24: held | P24: Comments
A25: YELP | B25: Long | C25: Yelp Inc | D25: 808.573 | E25: =F25/D25 -> 47.428062 | F25: 38349.05 | G25: 35186.18 | H25: =G25/D25 -> 43.516392 | I25: =G25-F25 -> -3162.87 | J25: =I25/F25 -> -0.082475837 | K25: 45286 | L25: 45302 | M25: =DAYS360(K25,L25) -> 15 | O25: Closed below stop for 2 days.
A26: TS | B26: Long | C26: Tenaris | D26: 1166.935 | E26: =F26/D26 -> 35.085005 | F26: 40941.92 | G26: 36634.59 | H26: =G26/D26 -> 31.393857 | I26: =G26-F26 -> -4307.33 | J26: =I26/F26 -> -0.10520586 | K26: 45233 | L26: 45307 | M26: =DAYS360(K26,L26) -> 73
B27: Long | C27: Minoso | D27: =1211.7123+804.6763 -> 2016.3886 | E27: =F27/D27 -> 20.49104 | F27: 41317.9 | G27: 42071.53 | H27: =G27/D27 -> 20.864793 | I27: =G27-F27 -> 753.63 | J27: =I27/F27 -> 0.018239794 | K27: 45135 | L27: 45308 | M27: =DAYS360(K27,L27) -> 169 | O27: Totally blew this trade. Had a nearly 50% profit.
I39: =SUM(I26:I38) -> -3553.7 | J39: Avg
H40: # of losses
H41: # of wins

Sheet 02-02-24
C1: 45324
C3: MANAGED ACCT | X3: Current | AC3: IBD
H4: Cost | J4: P/L | N4: Group | P4: EPS | R4: pivot | S4: last | W4: cost | X4: Stop | Y4: Stop | Z4: % | AB4: EPS | AC4: Comp
A5: Symbol | B5: Position | C5: Name | D5: Qty | E5: Current | F5: Value | G5: Cost | H5: per share | I5: P/L $ | J5: per sh | K5: Date purch | L5: days held | M5: % incr | N5: Rank | O5: RS | P5: RS | Q5: pivot | R5: -0.07 | S5: low | T5: 0.25 | U5: 0.5 | V5: 1 | W5: -0.07 | X5: Loss | Y5: Loss% | Z5: of port | AB5: Due | AC5: Rank
A7: AXON | B7: Long | C7: Axon Enterprise | D7: 267.8431 | E7: 256.99 | F7: =E7*D7 -> 68832.998 | G7: 61166.24 | H7: =G7/D7 -> 228.36594 | I7: =F7-G7 -> 7666.7583 | J7: =E7-H7 -> 28.624065 | K7: 45238 | L7: =DAYS360(K7,$C$1) -> 84 | M7: =(I7/G7) -> 0.12534297 | N7: 23 | O7: 87 | P7: 99 | Q7: 223.3 | R7: =Q7*0.93 -> 207.669 | S7: 241.72 | T7: =Q7*1.25 -> 279.125 | U7: =Q7*1.5 -> 334.95 | V7: =Q7*2 -> 446.6 | W7: =H7-(H7*0.07) -> 212.38032 | X7: 239 | Y7: =(X7-H7)/H7 -> 0.046565898 | Z7: =F7/F$19 -> 0.14537012 | AB7: 45349 | AC7: 99 | AD7: Bought as it gapped out of base on EPS.
A8: KD | B8: Long | C8: Kyndryl Hldgs | D8: =1160.2602+1046.0778 -> 2206.338 | E8: 20.9 | F8: =E8*D8 -> 46112.464 | G8: =20288.83+19170.47 -> 39459.3 | H8: =G8/D8 -> 17.884522 | I8: =F8-G8 -> 6653.1642 | J8: =E8-H8 -> 3.0154782 | K8: 45243 | L8: =DAYS360(K8,$C$1) -> 79 | M8: =(I8/G8) -> 0.16860827 | N8: 16 | O8: 95 | P8: 74 | Q8: 17.32 | R8: =Q8*0.93 -> 16.1076 | S8: 18.05 | T8: =Q8*1.25 -> 21.65 | U8: =Q8*1.5 -> 25.98 | V8: =Q8*2 -> 34.64 | W8: =H8-(H8*0.07) -> 16.632605 | X8: 19 | Y8: =(X8-H8)/H8 -> 0.062371152 | Z8: =F8/F$19 -> 0.097386063 | AB8: 45328 | AC8: 90 | AD8: Bought after 11/08 b/o. Trading tightly here.
A9: DDOG | B9: Long | C9: Datadog | D9: =308.2955+142.5312 -> 450.8267 | E9: 134.31 | F9: =E9*D9 -> 60550.534 | G9: =38082.35+18004.55 -> 56086.9 | H9: =G9/D9 -> 124.409 | I9: =F9-G9 -> 4463.6341 | J9: =E9-H9 -> 9.9009976 | K9: 45286 | L9: =DAYS360(K9,$C$1) -> 36 | M9: =(I9/G9) -> 0.079584254 | N9: 16 | O9: 95 | P9: 99 | Q9: 120.26 | R9: =Q9*0.93 -> 111.8418 | S9: 119.34 | T9: =Q9*1.25 -> 150.325 | U9: =Q9*1.5 -> 180.39 | V9: =Q9*2 -> 240.52 | W9: =H9-(H9*0.07) -> 115.70037 | X9: 119 | Y9: =(X9-H9)/H9 -> -0.04347758 | Z9: =F9/F$19 -> 0.12787818 | AB9: 45335 | AC9: 99 | AD9: Trading tightly since b/o.
A10: VKTX | B10: Long | C10: Viking Therap | D10: =1286.8297+948.5633 -> 2235.393 | E10: 23.45 | F10: =E10*D10 -> 52419.966 | G10: =28174.78+19947.6 -> 48122.38 | H10: =G10/D10 -> 21.527481 | I10: =F10-G10 -> 4297.5859 | J10: =E10-H10 -> 1.9225191 | K10: 45309 | L10: =DAYS360(K10,$C$1) -> 14 | M10: =(I10/G10) -> 0.089305347 | N10: 2 | O10: 98 | P10: 23 | Q10: 20.03 | R10: =Q10*0.93 -> 18.6279 | S10: 20.92 | T10: =Q10*1.25 -> 25.0375 | U10: =Q10*1.5 -> 30.045 | V10: =Q10*2 -> 40.06 | W10: =H10-(H10*0.07) -> 20.020557 | X10: 19.75 | Y10: =(X10-H10)/H10 -> -0.082567991 | Z10: =F10/F$19 -> 0.11070703 | AB10: 45329 | AC10: 79 | AD10: Bought after pivot test.
A11: AAON | B11: Long | C11: AAON | D11: =532.4164+77.1815 -> 609.5979 | E11: 73.32 | F11: =E11*D11 -> 44695.718 | G11: =38270.34+5640.4 -> 43910.74 | H11: =G11/D11 -> 72.032302 | I11: =F11-G11 -> 784.97803 | J11: =E11-H11 -> 1.2876981 | K11: 45313 | L11: =DAYS360(K11,$C$1) -> 10 | M11: =(I11/G11) -> 0.017876675 | N11: 36 | O11: 84 | P11: 98 | Q11: 71.39 | R11: =Q11*0.93 -> 66.3927 | S11: 68.38 | T11: =Q11*1.25 -> 89.2375 | U11: =Q11*1.5 -> 107.085 | V11: =Q11*2 -> 142.78 | W11: =H11-(H11*0.07) -> 66.990041 | X11: 67.5 | Y11: =(X11-H11)/H11 -> -0.06292041 | Z11: =F11/F$19 -> 0.094394001 | AB11: 45351 | AC11: 99 | AD11: Bought after pivot test.
A12: BLBD | B12: Long | C12: Bluebird | D12: 952.002 | E12: 30.91 | F12: =E12*D12 -> 29426.382 | G12: 28303.96 | H12: =G12/D12 -> 29.730988 | I12: =F12-G12 -> 1122.4218 | J12: =E12-H12 -> 1.179012 | K12: 45321 | L12: =DAYS360(K12,$C$1) -> 2 | M12: =(I12/G12) -> 0.039655999 | N12: 57 | O12: 97 | P12: 81 | Q12: 28.39 | R12: =Q12*0.93 -> 26.4027 | S12: 24.09 | T12: =Q12*1.25 -> 35.4875 | U12: =Q12*1.5 -> 42.585 | V12: =Q12*2 -> 56.78 | W12: =H12-(H12*0.07) -> 27.649819 | X12: 27.5 | Y12: =(X12-H12)/H12 -> -0.075039146 | Z12: =F12/F$19 -> 0.062146309 | AB12: 45329 | AC12: 99 | AD12: Bought day 2 after b/o.
F13: =E13*D13 -> 0 | H13: =G13/D13 -> #DIV/0! | I13: =F13-G13 -> 0 | J13: =E13-H13 -> #DIV/0! | L13: =DAYS360(K13,$C$1) -> 44672 | M13: =(I13/G13) -> #DIV/0! | R13: =Q13*0.93 -> 0 | T13: =Q13*1.25 -> 0 | U13: =Q13*1.5 -> 0 | V13: =Q13*2 -> 0 | W13: =H13-(H13*0.07) -> #DIV/0! | Y13: =(X13-H13)/H13 -> #DIV/0! | Z13: =F13/F$19 -> 0
A14: BIL | B14: Long | C14: Tbill ETF | D14: 1236.0085 | E14: 91.44 | F14: =E14*D14 -> 113020.62 | G14: 113020.62 | H14: =G14/D14 -> 91.440002 | I14: =F14-G14 -> -0.00276 | J14: =E14-H14 -> -2.2329944e-06 | M14: =(I14/G14) -> -2.4420323e-08 | R14: =Q14*0.93 -> 0 | T14: =Q14*1.25 -> 0 | U14: =Q14*1.5 -> 0 | V14: =Q14*2 -> 0 | W14: =H14-(H14*0.07) -> 85.039202 | Y14: =(X14-H14)/H14 -> -1 | Z14: =F14/F$19 -> 0.23869106
F15: =E15*D15 -> 0 | H15: =G15/D15 -> #DIV/0! | I15: =F15-G15 -> 0 | J15: =E15-H15 -> #DIV/0! | M15: =(I15/G15) -> #DIV/0! | R15: =Q15*0.93 -> 0 | T15: =Q15*1.25 -> 0 | U15: =Q15*1.5 -> 0 | V15: =Q15*2 -> 0 | W15: =H15-(H15*0.07) -> #DIV/0! | Y15: =(X15-H15)/H15 -> #DIV/0! | Z15: =F15/F$19 -> 0
F16: =E16*D16 -> 0 | H16: =G16/D16 -> #DIV/0! | I16: =F16-G16 -> 0 | J16: =E16-H16 -> #DIV/0! | L16: =DAYS360(K16,$C$1) -> 44672 | M16: =(I16/G16) -> #DIV/0! | R16: =Q16*0.93 -> 0 | T16: =Q16*1.25 -> 0 | U16: =Q16*1.5 -> 0 | V16: =Q16*2 -> 0 | W16: =H16-(H16*0.07) -> #DIV/0! | Y16: =(X16-H16)/H16 -> #DIV/0! | Z16: =F16/F$19 -> 0
A17: Sub-Total | F17: =SUM(F6:F16) -> 415058.68 | G17: =SUM(G6:G16) -> 390070.14 | I17: =SUM(I6:I16) -> 24988.539
D18: Cash, other | F18: 58443 | G18: =F18/F19 -> 0.12342723
D19: Total | F19: =SUM(F17:F18) -> 473501.68
H20: Last week's close | I20: ='01-26-24'!F19 -> 464499.64 | K20: 45291 | L20: 476160.6
A21: * | H21: Week's change | I21: =(F19-I20)/I20 -> 0.019380073 | K21: chg % | L21: =(F19-L20)/L20 -> -0.0055840834
M23: days
A24: 2024 Closed Trades - Managed Acct | D24: Qty | E24: Cost/sh | F24: $ cost | G24: $Proc | H24: Proc/sh | I24: Profit/loss | J24: % | K24: Date purch | L24: Date sold | M24: held | P24: Comments
A25: YELP | B25: Long | C25: Yelp Inc | D25: 808.573 | E25: =F25/D25 -> 47.428062 | F25: 38349.05 | G25: 35186.18 | H25: =G25/D25 -> 43.516392 | I25: =G25-F25 -> -3162.87 | J25: =I25/F25 -> -0.082475837 | K25: 45286 | L25: 45302 | M25: =DAYS360(K25,L25) -> 15 | O25: Closed below stop for 2 days.
A26: TS | B26: Long | C26: Tenaris | D26: 1166.935 | E26: =F26/D26 -> 35.085005 | F26: 40941.92 | G26: 36634.59 | H26: =G26/D26 -> 31.393857 | I26: =G26-F26 -> -4307.33 | J26: =I26/F26 -> -0.10520586 | K26: 45233 | L26: 45307 | M26: =DAYS360(K26,L26) -> 73
A27: MNSO | B27: Long | C27: Minoso | D27: =1211.7123+804.6763 -> 2016.3886 | E27: =F27/D27 -> 20.49104 | F27: 41317.9 | G27: 42071.53 | H27: =G27/D27 -> 20.864793 | I27: =G27-F27 -> 753.63 | J27: =I27/F27 -> 0.018239794 | K27: 45135 | L27: 45308 | M27: =DAYS360(K27,L27) -> 169 | O27: Totally blew this trade. Had a nearly 50% profit.
A28: ACMR | B28: Long | C28: ACM Research | D28: =1339.9646+918.07 -> 2258.0346 | E28: =F28/D28 -> 21.193736 | F28: =28457.8+19398.39 -> 47856.19 | G28: 39178.27 | H28: =G28/D28 -> 17.350607 | I28: =G28-F28 -> -8677.92 | J28: =I28/F28 -> -0.18133328 | K28: 45302 | L28: 45322 | M28: =DAYS360(K28,L28) -> 20
I39: =SUM(I26:I38) -> -12231.62 | J39: Avg
H40: # of losses
H41: # of wins

Sheet 02-09-24
C1: 45331
C3: MANAGED ACCT | X3: Current | AC3: IBD
H4: Cost | J4: P/L | N4: Group | P4: EPS | R4: pivot | S4: last | W4: cost | X4: Stop | Y4: Stop | Z4: % | AB4: EPS | AC4: Comp
A5: Symbol | B5: Position | C5: Name | D5: Qty | E5: Current | F5: Value | G5: Cost | H5: per share | I5: P/L $ | J5: per sh | K5: Date purch | L5: days held | M5: % incr | N5: Rank | O5: RS | P5: RS | Q5: pivot | R5: -0.07 | S5: low | T5: 0.25 | U5: 0.5 | V5: 1 | W5: -0.07 | X5: Loss | Y5: Loss% | Z5: of port | AB5: Due | AC5: Rank
A7: AXON | B7: Long | C7: Axon Enterprise | D7: 267.8431 | E7: 270.98 | F7: =E7*D7 -> 72580.123 | G7: 61166.24 | H7: =G7/D7 -> 228.36594 | I7: =F7-G7 -> 11413.883 | J7: =E7-H7 -> 42.614065 | K7: 45238 | L7: =DAYS360(K7,$C$1) -> 91 | M7: =(I7/G7) -> 0.1866043 | N7: 39 | O7: 90 | P7: 99 | Q7: 223.3 | R7: =Q7*0.93 -> 207.669 | S7: 241.72 | T7: =Q7*1.25 -> 279.125 | U7: =Q7*1.5 -> 334.95 | V7: =Q7*2 -> 446.6 | W7: =H7-(H7*0.07) -> 212.38032 | X7: 239 | Y7: =(X7-H7)/H7 -> 0.046565898 | Z7: =F7/F$19 -> 0.14273203 | AB7: 45349 | AC7: 99 | AD7: Bought as it gapped out of base on EPS.
A8: KD | B8: Long | C8: Kyndryl Hldgs | D8: =1160.2602+1046.0778 -> 2206.338 | E8: 21.96 | F8: =E8*D8 -> 48451.182 | G8: =20288.83+19170.47 -> 39459.3 | H8: =G8/D8 -> 17.884522 | I8: =F8-G8 -> 8991.8825 | J8: =E8-H8 -> 4.0754782 | K8: 45243 | L8: =DAYS360(K8,$C$1) -> 86 | M8: =(I8/G8) -> 0.22787739 | N8: 14 | O8: 91 | P8: 22 | Q8: 17.32 | R8: =Q8*0.93 -> 16.1076 | S8: 20.03 | T8: =Q8*1.25 -> 21.65 | U8: =Q8*1.5 -> 25.98 | V8: =Q8*2 -> 34.64 | W8: =H8-(H8*0.07) -> 16.632605 | X8: 19.75 | Y8: =(X8-H8)/H8 -> 0.10430686 | Z8: =F8/F$19 -> 0.095281398 | AB8: 45427 | AC8: 90 | AD8: Bought after 11/08 b/o. Trading tightly here.
A9: DDOG | B9: Long | C9: Datadog | D9: =308.2955+142.5312 -> 450.8267 | E9: 134.91 | F9: =E9*D9 -> 60821.03 | G9: =38082.35+18004.55 -> 56086.9 | H9: =G9/D9 -> 124.409 | I9: =F9-G9 -> 4734.1301 | J9: =E9-H9 -> 10.500998 | K9: 45286 | L9: =DAYS360(K9,$C$1) -> 43 | M9: =(I9/G9) -> 0.084407056 | N9: 14 | O9: 93 | P9: 99 | Q9: 120.26 | R9: =Q9*0.93 -> 111.8418 | S9: 119.34 | T9: =Q9*1.25 -> 150.325 | U9: =Q9*1.5 -> 180.39 | V9: =Q9*2 -> 240.52 | W9: =H9-(H9*0.07) -> 115.70037 | X9: 119 | Y9: =(X9-H9)/H9 -> -0.04347758 | Z9: =F9/F$19 -> 0.11960725 | AB9: 45335 | AC9: 99 | AD9: Trading tightly since b/o.
A10: VKTX | B10: Long | C10: Viking Therap | D10: =1286.8297+948.5633 -> 2235.393 | E10: 30.86 | F10: =E10*D10 -> 68984.228 | G10: =28174.78+19947.6 -> 48122.38 | H10: =G10/D10 -> 21.527481 | I10: =F10-G10 -> 20861.848 | J10: =E10-H10 -> 9.3325191 | K10: 45309 | L10: =DAYS360(K10,$C$1) -> 21 | M10: =(I10/G10) -> 0.43351655 | N10: 2 | O10: 99 | P10: 22 | Q10: 20.03 | R10: =Q10*0.93 -> 18.6279 | S10: 22.51 | T10: =Q10*1.25 -> 25.0375 | U10: =Q10*1.5 -> 30.045 | V10: =Q10*2 -> 40.06 | W10: =H10-(H10*0.07) -> 20.020557 | X10: 22 | Y10: =(X10-H10)/H10 -> 0.021949579 | Z10: =F10/F$19 -> 0.13566054 | AB10: 45406 | AC10: 82 | AD10: Bought after pivot test.
A11: AAON | B11: Long | C11: AAON | D11: =532.4164+77.1815 -> 609.5979 | E11: 81.4 | F11: =E11*D11 -> 49621.269 | G11: =38270.34+5640.4 -> 43910.74 | H11: =G11/D11 -> 72.032302 | I11: =F11-G11 -> 5710.5291 | J11: =E11-H11 -> 9.3676981 | K11: 45313 | L11: =DAYS360(K11,$C$1) -> 17 | M11: =(I11/G11) -> 0.13004857 | N11: 41 | O11: 91 | P11: 98 | Q11: 71.39 | R11: =Q11*0.93 -> 66.3927 | S11: 68.38 | T11: =Q11*1.25 -> 89.2375 | U11: =Q11*1.5 -> 107.085 | V11: =Q11*2 -> 142.78 | W11: =H11-(H11*0.07) -> 66.990041 | X11: 67.5 | Y11: =(X11-H11)/H11 -> -0.06292041 | Z11: =F11/F$19 -> 0.097582425 | AB11: 45351 | AC11: 99 | AD11: Bought after pivot test.
A12: BLBD | B12: Long | C12: Bluebird | D12: 952.002 | E12: 30.55 | F12: =E12*D12 -> 29083.661 | G12: 28303.96 | H12: =G12/D12 -> 29.730988 | I12: =F12-G12 -> 779.7011 | J12: =E12-H12 -> 0.81901204 | K12: 45321 | L12: =DAYS360(K12,$C$1) -> 9 | M12: =(I12/G12) -> 0.027547421 | N12: 45 | O12: 96 | P12: 81 | Q12: 28.39 | R12: =Q12*0.93 -> 26.4027 | S12: 24.09 | T12: =Q12*1.25 -> 35.4875 | U12: =Q12*1.5 -> 42.585 | V12: =Q12*2 -> 56.78 | W12: =H12-(H12*0.07) -> 27.649819 | X12: 27.5 | Y12: =(X12-H12)/H12 -> -0.075039146 | Z12: =F12/F$19 -> 0.057194309 | AB12: 45421 | AC12: 98 | AD12: Bought day 2 after b/o.
A13: MDB | B13: Long | C13: MongoDB | D13: 126.054 | E13: 500.9 | F13: =E13*D13 -> 63140.449 | G13: 56759.55 | H13: =G13/D13 -> 450.27964 | I13: =F13-G13 -> 6380.8986 | J13: =E13-H13 -> 50.620358 | K13: 45327 | L13: =DAYS360(K13,$C$1) -> 4 | M13: =(I13/G13) -> 0.11241982 | N13: 12 | O13: 95 | P13: 83 | Q13: 442.84 | R13: =Q13*0.93 -> 411.8412 | S13: 400.52 | T13: =Q13*1.25 -> 553.55 | U13: =Q13*1.5 -> 664.26 | V13: =Q13*2 -> 885.68 | W13: =H13-(H13*0.07) -> 418.76007 | X13: 419 | Y13: =(X13-H13)/H13 -> -0.069467147 | Z13: =F13/F$19 -> 0.12416849 | AB13: 45358 | AC13: 99 | AD13: Bought day 1 of b/o.
A14: IOT | B14: Long | C14: Samsara | D14: 846.327 | E14: 35.47 | F14: =E14*D14 -> 30019.219 | G14: 30020.93 | H14: =G14/D14 -> 35.472022 | I14: =F14-G14 -> -1.71131 | J14: =E14-H14 -> -0.0020220435 | K14: 45331 | L14: =DAYS360(K14,$C$1) -> 0 | M14: =(I14/G14) -> -5.7003897e-05 | N14: 14 | O14: 96 | P14: 81 | Q14: 32.41 | R14: =Q14*0.93 -> 30.1413 | S14: 29.8 | T14: =Q14*1.25 -> 40.5125 | U14: =Q14*1.5 -> 48.615 | V14: =Q14*2 -> 64.82 | W14: =H14-(H14*0.07) -> 32.988981 | X14: 32.75 | Y14: =(X14-H14)/H14 -> -0.076737155 | Z14: =F14/F$19 -> 0.059034124 | AB14: 45358 | AC14: 97 | AD14: Broke out of consolidation above pivot.
F15: =E15*D15 -> 0 | H15: =G15/D15 -> #DIV/0! | I15: =F15-G15 -> 0 | J15: =E15-H15 -> #DIV/0! | L15: =DAYS360(K15,$C$1) -> 44679 | M15: =(I15/G15) -> #DIV/0! | R15: =Q15*0.93 -> 0 | T15: =Q15*1.25 -> 0 | U15: =Q15*1.5 -> 0 | V15: =Q15*2 -> 0 | W15: =H15-(H15*0.07) -> #DIV/0! | Y15: =(X15-H15)/H15 -> #DIV/0! | Z15: =F15/F$19 -> 0
A16: BIL | B16: Long | C16: Tbill ETF | D16: 540.5774 | E16: 91.53 | F16: =E16*D16 -> 49479.049 | G16: 49473.64 | H16: =G16/D16 -> 91.519993 | I16: =F16-G16 -> 5.409422 | J16: =E16-H16 -> 0.010006748 | M16: =(I16/G16) -> 0.00010933948 | R16: =Q16*0.93 -> 0 | T16: =Q16*1.25 -> 0 | U16: =Q16*1.5 -> 0 | V16: =Q16*2 -> 0 | W16: =H16-(H16*0.07) -> 85.113594 | Y16: =(X16-H16)/H16 -> -1 | Z16: =F16/F$19 -> 0.097302744
A17: Sub-Total | F17: =SUM(F6:F16) -> 472180.21 | G17: =SUM(G6:G16) -> 413303.64 | I17: =SUM(I6:I16) -> 58876.571
D18: Cash, other | F18: 36326 | G18: =F18/F19 -> 0.071436689
D19: Total | F19: =SUM(F17:F18) -> 508506.21
H20: Last week's close | I20: ='02-02-24'!F19 -> 473501.68 | K20: 45291 | L20: 476160.6
A21: * | H21: Week's change | I21: =(F19-I20)/I20 -> 0.073926942 | K21: chg % | L21: =(F19-L20)/L20 -> 0.067930044
M23: days
A24: 2024 Closed Trades - Managed Acct | D24: Qty | E24: Cost/sh | F24: $ cost | G24: $Proc | H24: Proc/sh | I24: Profit/loss | J24: % | K24: Date purch | L24: Date sold | M24: held | P24: Comments
A25: YELP | B25: Long | C25: Yelp Inc | D25: 808.573 | E25: =F25/D25 -> 47.428062 | F25: 38349.05 | G25: 35186.18 | H25: =G25/D25 -> 43.516392 | I25: =G25-F25 -> -3162.87 | J25: =I25/F25 -> -0.082475837 | K25: 45286 | L25: 45302 | M25: =DAYS360(K25,L25) -> 15 | O25: Closed below stop for 2 days.
A26: TS | B26: Long | C26: Tenaris | D26: 1166.935 | E26: =F26/D26 -> 35.085005 | F26: 40941.92 | G26: 36634.59 | H26: =G26/D26 -> 31.393857 | I26: =G26-F26 -> -4307.33 | J26: =I26/F26 -> -0.10520586 | K26: 45233 | L26: 45307 | M26: =DAYS360(K26,L26) -> 73
A27: MNSO | B27: Long | C27: Minoso | D27: =1211.7123+804.6763 -> 2016.3886 | E27: =F27/D27 -> 20.49104 | F27: 41317.9 | G27: 42071.53 | H27: =G27/D27 -> 20.864793 | I27: =G27-F27 -> 753.63 | J27: =I27/F27 -> 0.018239794 | K27: 45135 | L27: 45308 | M27: =DAYS360(K27,L27) -> 169 | O27: Totally blew this trade. Had a nearly 50% profit.
A28: ACMR | B28: Long | C28: ACM Research | D28: =1339.9646+918.07 -> 2258.0346 | E28: =F28/D28 -> 21.193736 | F28: =28457.8+19398.39 -> 47856.19 | G28: 39178.27 | H28: =G28/D28 -> 17.350607 | I28: =G28-F28 -> -8677.92 | J28: =I28/F28 -> -0.18133328 | K28: 45302 | L28: 45322 | M28: =DAYS360(K28,L28) -> 20
I39: =SUM(I26:I38) -> -12231.62 | J39: Avg
H40: # of losses
H41: # of wins

Sheet 02-16-24
C1: 45338
C3: MANAGED ACCT | X3: Current | AC3: IBD
H4: Cost | J4: P/L | N4: Group | P4: EPS | R4: pivot | S4: last | W4: cost | X4: Stop | Y4: Stop | Z4: % | AB4: EPS | AC4: Comp
A5: Symbol | B5: Position | C5: Name | D5: Qty | E5: Current | F5: Value | G5: Cost | H5: per share | I5: P/L $ | J5: per sh | K5: Date purch | L5: days held | M5: % incr | N5: Rank | O5: RS | P5: RS | Q5: pivot | R5: -0.07 | S5: low | T5: 0.25 | U5: 0.5 | V5: 1 | W5: -0.07 | X5: Loss | Y5: Loss% | Z5: of port | AB5: Due | AC5: Rank
A7: AXON | B7: Long | C7: Axon Enterprise | D7: 267.8431 | E7: 269.8 | F7: =E7*D7 -> 72264.068 | G7: 61166.24 | H7: =G7/D7 -> 228.36594 | I7: =F7-G7 -> 11097.828 | J7: =E7-H7 -> 41.434065 | K7: 45238 | L7: =DAYS360(K7,$C$1) -> 98 | M7: =(I7/G7) -> 0.18143715 | N7: 33 | O7: 89 | P7: 99 | Q7: 223.3 | R7: =Q7*0.93 -> 207.669 | S7: 241.72 | T7: =Q7*1.25 -> 279.125 | U7: =Q7*1.5 -> 334.95 | V7: =Q7*2 -> 446.6 | W7: =H7-(H7*0.07) -> 212.38032 | X7: 250 | Y7: =(X7-H7)/H7 -> 0.094734203 | Z7: =F7/F$19 -> 0.1400933 | AB7: 45349 | AC7: 99 | AD7: Bought as it gapped out of base on EPS.
A8: KD | B8: Long | C8: Kyndryl Hldgs | D8: =1160.2602+1046.0778 -> 2206.338 | E8: 21.44 | F8: =E8*D8 -> 47303.887 | G8: =20288.83+19170.47 -> 39459.3 | H8: =G8/D8 -> 17.884522 | I8: =F8-G8 -> 7844.5867 | J8: =E8-H8 -> 3.5554782 | K8: 45243 | L8: =DAYS360(K8,$C$1) -> 93 | M8: =(I8/G8) -> 0.19880197 | N8: 16 | O8: 91 | P8: 22 | Q8: 17.32 | R8: =Q8*0.93 -> 16.1076 | S8: 20.03 | T8: =Q8*1.25 -> 21.65 | U8: =Q8*1.5 -> 25.98 | V8: =Q8*2 -> 34.64 | W8: =H8-(H8*0.07) -> 16.632605 | X8: 19.75 | Y8: =(X8-H8)/H8 -> 0.10430686 | Z8: =F8/F$19 -> 0.091704739 | AB8: 45427 | AC8: 67 | AD8: Bought after 11/08 b/o. Trading tightly here.
A9: DDOG | B9: Long | C9: Datadog | D9: =308.2955+142.5312 -> 450.8267 | E9: 129.74 | F9: =E9*D9 -> 58490.256 | G9: =38082.35+18004.55 -> 56086.9 | H9: =G9/D9 -> 124.409 | I9: =F9-G9 -> 2403.3561 | J9: =E9-H9 -> 5.3309976 | K9: 45286 | L9: =DAYS360(K9,$C$1) -> 50 | M9: =(I9/G9) -> 0.042850578 | N9: 16 | O9: 91 | P9: 99 | Q9: 120.26 | R9: =Q9*0.93 -> 111.8418 | S9: 119.34 | T9: =Q9*1.25 -> 150.325 | U9: =Q9*1.5 -> 180.39 | V9: =Q9*2 -> 240.52 | W9: =H9-(H9*0.07) -> 115.70037 | X9: 122 | Y9: =(X9-H9)/H9 -> -0.01936357 | Z9: =F9/F$19 -> 0.11339097 | AB9: 45414 | AC9: 99 | AD9: Trading tightly since b/o.
A10: VKTX | B10: Long | C10: Viking Therap | D10: =1286.8297+948.5633 -> 2235.393 | E10: 36.2 | F10: =E10*D10 -> 80921.227 | G10: =28174.78+19947.6 -> 48122.38 | H10: =G10/D10 -> 21.527481 | I10: =F10-G10 -> 32798.847 | J10: =E10-H10 -> 14.672519 | K10: 45309 | L10: =DAYS360(K10,$C$1) -> 28 | M10: =(I10/G10) -> 0.68157158 | N10: 2 | O10: 99 | P10: 22 | Q10: 20.03 | R10: =Q10*0.93 -> 18.6279 | S10: 22.51 | T10: =Q10*1.25 -> 25.0375 | U10: =Q10*1.5 -> 30.045 | V10: =Q10*2 -> 40.06 | W10: =H10-(H10*0.07) -> 20.020557 | X10: 26 | Y10: =(X10-H10)/H10 -> 0.20775859 | Z10: =F10/F$19 -> 0.15687633 | AB10: 45406 | AC10: 82 | AD10: Bought after pivot test.
A11: AAON | B11: Long | C11: AAON | D11: =532.4164+77.1815 -> 609.5979 | E11: 84.3 | F11: =E11*D11 -> 51389.103 | G11: =38270.34+5640.4 -> 43910.74 | H11: =G11/D11 -> 72.032302 | I11: =F11-G11 -> 7478.363 | J11: =E11-H11 -> 12.267698 | K11: 45313 | L11: =DAYS360(K11,$C$1) -> 24 | M11: =(I11/G11) -> 0.17030829 | N11: 38 | O11: 92 | P11: 98 | Q11: 71.39 | R11: =Q11*0.93 -> 66.3927 | S11: 68.38 | T11: =Q11*1.25 -> 89.2375 | U11: =Q11*1.5 -> 107.085 | V11: =Q11*2 -> 142.78 | W11: =H11-(H11*0.07) -> 66.990041 | X11: 72 | Y11: =(X11-H11)/H11 -> -0.00044843699 | Z11: =F11/F$19 -> 0.099624462 | AB11: 45350 | AC11: 99 | AD11: Bought after pivot test.
A12: BLBD | B12: Long | C12: Bluebird | D12: =952.002+512.6146 -> 1464.6166 | E12: 32.31 | F12: =E12*D12 -> 47321.762 | G12: =28303.96+15646.4 -> 43950.36 | H12: =G12/D12 -> 30.008099 | I12: =F12-G12 -> 3371.4023 | J12: =E12-H12 -> 2.301901 | K12: 45321 | L12: =DAYS360(K12,$C$1) -> 16 | M12: =(I12/G12) -> 0.076709323 | N12: 50 | O12: 96 | P12: 81 | Q12: 28.39 | R12: =Q12*0.93 -> 26.4027 | S12: 24.09 | T12: =Q12*1.25 -> 35.4875 | U12: =Q12*1.5 -> 42.585 | V12: =Q12*2 -> 56.78 | W12: =H12-(H12*0.07) -> 27.907532 | X12: 29 | Y12: =(X12-H12)/H12 -> -0.033594232 | Z12: =F12/F$19 -> 0.091739393 | AB12: 45421 | AC12: 99 | AD12: Bought day 2 after b/o.
A13: MDB | B13: Long | C13: MongoDB | D13: 126.054 | E13: 465.06 | F13: =E13*D13 -> 58622.673 | G13: 56759.55 | H13: =G13/D13 -> 450.27964 | I13: =F13-G13 -> 1863.1232 | J13: =E13-H13 -> 14.780358 | K13: 45327 | L13: =DAYS360(K13,$C$1) -> 11 | M13: =(I13/G13) -> 0.032824842 | N13: 9 | O13: 94 | P13: 83 | Q13: 442.84 | R13: =Q13*0.93 -> 411.8412 | S13: 400.52 | T13: =Q13*1.25 -> 553.55 | U13: =Q13*1.5 -> 664.26 | V13: =Q13*2 -> 885.68 | W13: =H13-(H13*0.07) -> 418.76007 | X13: 445 | Y13: =(X13-H13)/H13 -> -0.011725252 | Z13: =F13/F$19 -> 0.11364768 | AB13: 45358 | AC13: 99 | AD13: Bought day 1 of b/o.
A14: IOT | B14: Long | C14: Samsara | D14: =846.327+640.0668 -> 1486.3938 | E14: 34.44 | F14: =E14*D14 -> 51191.402 | G14: =30020.93+21858.29 -> 51879.22 | H14: =G14/D14 -> 34.902742 | I14: =F14-G14 -> -687.81753 | J14: =E14-H14 -> -0.46274246 | K14: 45331 | L14: =DAYS360(K14,$C$1) -> 7 | M14: =(I14/G14) -> -0.013258055 | N14: 16 | O14: 95 | P14: 81 | Q14: 32.41 | R14: =Q14*0.93 -> 30.1413 | S14: 29.8 | T14: =Q14*1.25 -> 40.5125 | U14: =Q14*1.5 -> 48.615 | V14: =Q14*2 -> 64.82 | W14: =H14-(H14*0.07) -> 32.45955 | X14: 32.75 | Y14: =(X14-H14)/H14 -> -0.061678318 | Z14: =F14/F$19 -> 0.099241194 | AB14: 45358 | AC14: 95 | AD14: Broke out of consolidation above pivot.
F15: =E15*D15 -> 0 | H15: =G15/D15 -> #DIV/0! | I15: =F15-G15 -> 0 | J15: =E15-H15 -> #DIV/0! | L15: =DAYS360(K15,$C$1) -> 44686 | M15: =(I15/G15) -> #DIV/0! | R15: =Q15*0.93 -> 0 | T15: =Q15*1.25 -> 0 | U15: =Q15*1.5 -> 0 | V15: =Q15*2 -> 0 | W15: =H15-(H15*0.07) -> #DIV/0! | Y15: =(X15-H15)/H15 -> #DIV/0! | Z15: =F15/F$19 -> 0
A16: BIL | B16: Long | C16: Tbill ETF | D16: 277.4286 | E16: 91.63 | F16: =E16*D16 -> 25420.783 | G16: 25401.36 | H16: =G16/D16 -> 91.559991 | I16: =F16-G16 -> 19.422618 | J16: =E16-H16 -> 0.070009429 | M16: =(I16/G16) -> 0.00076462906 | R16: =Q16*0.93 -> 0 | T16: =Q16*1.25 -> 0 | U16: =Q16*1.5 -> 0 | V16: =Q16*2 -> 0 | W16: =H16-(H16*0.07) -> 85.150791 | Y16: =(X16-H16)/H16 -> -1 | Z16: =F16/F$19 -> 0.049281494
A17: Sub-Total | F17: =SUM(F6:F16) -> 492925.16 | G17: =SUM(G6:G16) -> 426736.05 | I17: =SUM(I6:I16) -> 66189.111
D18: Cash, other | F18: 22903 | G18: =F18/F19 -> 0.044400445
D19: Total | F19: =SUM(F17:F18) -> 515828.16
H20: Last week's close | I20: ='02-09-24'!F19 -> 508506.21 | K20: 45291 | L20: 476160.6
A21: * | H21: Week's change | I21: =(F19-I20)/I20 -> 0.014398941 | K21: chg % | L21: =(F19-L20)/L20 -> 0.083307106
M23: days
A24: 2024 Closed Trades - Managed Acct | D24: Qty | E24: Cost/sh | F24: $ cost | G24: $Proc | H24: Proc/sh | I24: Profit/loss | J24: % | K24: Date purch | L24: Date sold | M24: held | P24: Comments
A25: YELP | B25: Long | C25: Yelp Inc | D25: 808.573 | E25: =F25/D25 -> 47.428062 | F25: 38349.05 | G25: 35186.18 | H25: =G25/D25 -> 43.516392 | I25: =G25-F25 -> -3162.87 | J25: =I25/F25 -> -0.082475837 | K25: 45286 | L25: 45302 | M25: =DAYS360(K25,L25) -> 15 | O25: Closed below stop for 2 days.
A26: TS | B26: Long | C26: Tenaris | D26: 1166.935 | E26: =F26/D26 -> 35.085005 | F26: 40941.92 | G26: 36634.59 | H26: =G26/D26 -> 31.393857 | I26: =G26-F26 -> -4307.33 | J26: =I26/F26 -> -0.10520586 | K26: 45233 | L26: 45307 | M26: =DAYS360(K26,L26) -> 73
A27: MNSO | B27: Long | C27: Minoso | D27: =1211.7123+804.6763 -> 2016.3886 | E27: =F27/D27 -> 20.49104 | F27: 41317.9 | G27: 42071.53 | H27: =G27/D27 -> 20.864793 | I27: =G27-F27 -> 753.63 | J27: =I27/F27 -> 0.018239794 | K27: 45135 | L27: 45308 | M27: =DAYS360(K27,L27) -> 169 | O27: Totally blew this trade. Had a nearly 50% profit.
A28: ACMR | B28: Long | C28: ACM Research | D28: =1339.9646+918.07 -> 2258.0346 | E28: =F28/D28 -> 21.193736 | F28: =28457.8+19398.39 -> 47856.19 | G28: 39178.27 | H28: =G28/D28 -> 17.350607 | I28: =G28-F28 -> -8677.92 | J28: =I28/F28 -> -0.18133328 | K28: 45302 | L28: 45322 | M28: =DAYS360(K28,L28) -> 20
I32: =SUM(I25:I31) -> -15394.49
I39: =SUM(I26:I38) -> -27626.11 | J39: Avg
H40: # of losses
H41: # of wins

Sheet 02-23-24
C1: 45345
C3: MANAGED ACCT | X3: Current | AC3: IBD
H4: Cost | J4: P/L | N4: Group | P4: EPS | R4: pivot | S4: last | W4: cost | X4: Stop | Y4: Stop | Z4: % | AB4: EPS | AC4: Comp
A5: Symbol | B5: Position | C5: Name | D5: Qty | E5: Current | F5: Value | G5: Cost | H5: per share | I5: P/L $ | J5: per sh | K5: Date purch | L5: days held | M5: % incr | N5: Rank | O5: RS | P5: RS | Q5: pivot | R5: -0.07 | S5: low | T5: 0.25 | U5: 0.5 | V5: 1 | W5: -0.07 | X5: Loss | Y5: Loss% | Z5: of port | AB5: Due | AC5: Rank
A7: AXON | B7: Long | C7: Axon Enterprise | D7: 267.8431 | E7: 270.63 | F7: =E7*D7 -> 72486.378 | G7: 61166.24 | H7: =G7/D7 -> 228.36594 | I7: =F7-G7 -> 11320.138 | J7: =E7-H7 -> 42.264065 | K7: 45238 | L7: =DAYS360(K7,$C$1) -> 105 | M7: =(I7/G7) -> 0.18507167 | N7: 26 | O7: 89 | P7: 99 | Q7: 223.3 | R7: =Q7*0.93 -> 207.669 | S7: 241.72 | T7: =Q7*1.25 -> 279.125 | U7: =Q7*1.5 -> 334.95 | V7: =Q7*2 -> 446.6 | W7: =H7-(H7*0.07) -> 212.38032 | X7: 250 | Y7: =(X7-H7)/H7 -> 0.094734203 | Z7: =F7/F$19 -> 0.14235115 | AB7: 45349 | AC7: 99 | AD7: Bought as it gapped out of base on EPS.
A8: KD | B8: Long | C8: Kyndryl Hldgs | D8: =1160.2602+1046.0778 -> 2206.338 | E8: 21.54 | F8: =E8*D8 -> 47524.521 | G8: =20288.83+19170.47 -> 39459.3 | H8: =G8/D8 -> 17.884522 | I8: =F8-G8 -> 8065.2205 | J8: =E8-H8 -> 3.6554782 | K8: 45243 | L8: =DAYS360(K8,$C$1) -> 100 | M8: =(I8/G8) -> 0.2043934 | N8: 21 | O8: 91 | P8: 22 | Q8: 17.32 | R8: =Q8*0.93 -> 16.1076 | S8: 20.03 | T8: =Q8*1.25 -> 21.65 | U8: =Q8*1.5 -> 25.98 | V8: =Q8*2 -> 34.64 | W8: =H8-(H8*0.07) -> 16.632605 | X8: 19.75 | Y8: =(X8-H8)/H8 -> 0.10430686 | Z8: =F8/F$19 -> 0.093330228 | AB8: 45427 | AC8: 66 | AD8: Bought after 11/08 b/o. Trading tightly here.
A9: DDOG | B9: Long | C9: Datadog | D9: =308.2955+142.5312 -> 450.8267 | E9: 129.51 | F9: =E9*D9 -> 58386.566 | G9: =38082.35+18004.55 -> 56086.9 | H9: =G9/D9 -> 124.409 | I9: =F9-G9 -> 2299.6659 | J9: =E9-H9 -> 5.1009976 | K9: 45286 | L9: =DAYS360(K9,$C$1) -> 57 | M9: =(I9/G9) -> 0.041001837 | N9: 21 | O9: 91 | P9: 99 | Q9: 120.26 | R9: =Q9*0.93 -> 111.8418 | S9: 119.34 | T9: =Q9*1.25 -> 150.325 | U9: =Q9*1.5 -> 180.39 | V9: =Q9*2 -> 240.52 | W9: =H9-(H9*0.07) -> 115.70037 | X9: 122 | Y9: =(X9-H9)/H9 -> -0.01936357 | Z9: =F9/F$19 -> 0.11466147 | AB9: 45414 | AC9: 99 | AD9: Trading tightly since b/o.
A10: VKTX | B10: Long | C10: Viking Therap | D10: =1286.8297+948.5633-808.6324 -> 1426.7606 | E10: 37.42 | F10: =E10*D10 -> 53389.382 | G10: =28174.78+19947.6-17409.86 -> 30712.52 | H10: =G10/D10 -> 21.52605 | I10: =F10-G10 -> 22676.862 | J10: =E10-H10 -> 15.89395 | K10: 45309 | L10: =DAYS360(K10,$C$1) -> 35 | M10: =(I10/G10) -> 0.73835887 | N10: 4 | O10: 99 | P10: 22 | Q10: 20.03 | R10: =Q10*0.93 -> 18.6279 | S10: 22.51 | T10: =Q10*1.25 -> 25.0375 | U10: =Q10*1.5 -> 30.045 | V10: =Q10*2 -> 40.06 | W10: =H10-(H10*0.07) -> 20.019226 | X10: 28 | Y10: =(X10-H10)/H10 -> 0.30074956 | Z10: =F10/F$19 -> 0.10484784 | AB10: 45406 | AC10: 83 | AD10: Bought after pivot test.
A11: AAON | B11: Long | C11: AAON | D11: =532.4164+77.1815 -> 609.5979 | E11: 84.05 | F11: =E11*D11 -> 51236.703 | G11: =38270.34+5640.4 -> 43910.74 | H11: =G11/D11 -> 72.032302 | I11: =F11-G11 -> 7325.9635 | J11: =E11-H11 -> 12.017698 | K11: 45313 | L11: =DAYS360(K11,$C$1) -> 31 | M11: =(I11/G11) -> 0.16683762 | N11: 51 | O11: 92 | P11: 98 | Q11: 71.39 | R11: =Q11*0.93 -> 66.3927 | S11: 68.38 | T11: =Q11*1.25 -> 89.2375 | U11: =Q11*1.5 -> 107.085 | V11: =Q11*2 -> 142.78 | W11: =H11-(H11*0.07) -> 66.990041 | X11: 77 | Y11: =(X11-H11)/H11 -> 0.068964866 | Z11: =F11/F$19 -> 0.10062034 | AB11: 45350 | AC11: 99 | AD11: Bought after pivot test.
A12: BLBD | B12: Long | C12: Bluebird | D12: =952.002+512.6146 -> 1464.6166 | E12: 31.5 | F12: =E12*D12 -> 46135.423 | G12: =28303.96+15646.4 -> 43950.36 | H12: =G12/D12 -> 30.008099 | I12: =F12-G12 -> 2185.0629 | J12: =E12-H12 -> 1.491901 | K12: 45321 | L12: =DAYS360(K12,$C$1) -> 23 | M12: =(I12/G12) -> 0.04971661 | N12: 46 | O12: 95 | P12: 81 | Q12: 28.39 | R12: =Q12*0.93 -> 26.4027 | S12: 24.09 | T12: =Q12*1.25 -> 35.4875 | U12: =Q12*1.5 -> 42.585 | V12: =Q12*2 -> 56.78 | W12: =H12-(H12*0.07) -> 27.907532 | X12: 29 | Y12: =(X12-H12)/H12 -> -0.033594232 | Z12: =F12/F$19 -> 0.090602272 | AB12: 45421 | AC12: 99 | AD12: Bought day 2 after b/o.
A13: IOT | B13: Long | C13: Samsara | D13: =846.327+640.0668 -> 1486.3938 | E13: 33.31 | F13: =E13*D13 -> 49511.777 | G13: =30020.93+21858.29 -> 51879.22 | H13: =G13/D13 -> 34.902742 | I13: =F13-G13 -> -2367.4425 | J13: =E13-H13 -> -1.5927425 | K13: 45331 | L13: =DAYS360(K13,$C$1) -> 14 | M13: =(I13/G13) -> -0.045633734 | N13: 21 | O13: 94 | P13: 81 | Q13: 32.41 | R13: =Q13*0.93 -> 30.1413 | S13: 29.8 | T13: =Q13*1.25 -> 40.5125 | U13: =Q13*1.5 -> 48.615 | V13: =Q13*2 -> 64.82 | W13: =H13-(H13*0.07) -> 32.45955 | X13: 32.75 | Y13: =(X13-H13)/H13 -> -0.061678318 | Z13: =F13/F$19 -> 0.097232869 | AB13: 45358 | AC13: 95 | AD13: Broke out of consolidation above pivot.
A14: BIRK | B14: Long | C14: Birkenstock Hldg | D14: =567.3728+414.8485 -> 982.2213 | E14: 52 | F14: =E14*D14 -> 51075.508 | G14: =30558.32+21471.26 -> 52029.58 | H14: =G14/D14 -> 52.971342 | I14: =F14-G14 -> -954.0724 | J14: =E14-H14 -> -0.97134159 | K14: 45344 | L14: =DAYS360(K14,$C$1) -> 1 | M14: =(I14/G14) -> -0.018337115 | N14: 2 | O14: 87 | P14: 60 | Q14: 51.09 | R14: =Q14*0.93 -> 47.5137 | S14: 48.63 | T14: =Q14*1.25 -> 63.8625 | U14: =Q14*1.5 -> 76.635 | V14: =Q14*2 -> 102.18 | W14: =H14-(H14*0.07) -> 49.263348 | X14: 50.25 | Y14: =(X14-H14)/H14 -> -0.051373847 | Z14: =F14/F$19 -> 0.10030377 | AB14: 45351 | AC14: 94 | AD14: Bought day 2 after b/o.
F15: =E15*D15 -> 0 | H15: =G15/D15 -> #DIV/0! | I15: =F15-G15 -> 0 | J15: =E15-H15 -> #DIV/0! | L15: =DAYS360(K15,$C$1) -> 44693 | M15: =(I15/G15) -> #DIV/0! | R15: =Q15*0.93 -> 0 | T15: =Q15*1.25 -> 0 | U15: =Q15*1.5 -> 0 | V15: =Q15*2 -> 0 | W15: =H15-(H15*0.07) -> #DIV/0! | Y15: =(X15-H15)/H15 -> #DIV/0! | Z15: =F15/F$19 -> 0
A16: BIL | B16: Long | C16: Tbill ETF | D16: 277.4286 | E16: 91.71 | F16: =E16*D16 -> 25442.977 | G16: 25401.36 | H16: =G16/D16 -> 91.559991 | I16: =F16-G16 -> 41.616906 | J16: =E16-H16 -> 0.15000943 | M16: =(I16/G16) -> 0.0016383731 | R16: =Q16*0.93 -> 0 | T16: =Q16*1.25 -> 0 | U16: =Q16*1.5 -> 0 | V16: =Q16*2 -> 0 | W16: =H16-(H16*0.07) -> 85.150791 | Y16: =(X16-H16)/H16 -> -1 | Z16: =F16/F$19 -> 0.049965761
A17: Sub-Total | F17: =SUM(F6:F16) -> 455189.23 | G17: =SUM(G6:G16) -> 404596.22 | I17: =SUM(I6:I16) -> 50593.015
D18: Cash, other | F18: 54019 | G18: =F18/F19 -> 0.1060843
D19: Total | F19: =SUM(F17:F18) -> 509208.23
H20: Last week's close | I20: ='02-16-24'!F19 -> 515828.16 | K20: 45291 | L20: 476160.6
A21: * | H21: Week's change | I21: =(F19-I20)/I20 -> -0.012833589 | K21: chg % | L21: =(F19-L20)/L20 -> 0.069404387
M23: days
A24: 2024 Closed Trades - Managed Acct | D24: Qty | E24: Cost/sh | F24: $ cost | G24: $Proc | H24: Proc/sh | I24: Profit/loss | J24: % | K24: Date purch | L24: Date sold | M24: held | P24: Comments
A25: YELP | B25: Long | C25: Yelp Inc | D25: 808.573 | E25: =F25/D25 -> 47.428062 | F25: 38349.05 | G25: 35186.18 | H25: =G25/D25 -> 43.516392 | I25: =G25-F25 -> -3162.87 | J25: =I25/F25 -> -0.082475837 | K25: 45286 | L25: 45302 | M25: =DAYS360(K25,L25) -> 15 | O25: Closed below stop for 2 days.
A26: TS | B26: Long | C26: Tenaris | D26: 1166.935 | E26: =F26/D26 -> 35.085005 | F26: 40941.92 | G26: 36634.59 | H26: =G26/D26 -> 31.393857 | I26: =G26-F26 -> -4307.33 | J26: =I26/F26 -> -0.10520586 | K26: 45233 | L26: 45307 | M26: =DAYS360(K26,L26) -> 73
A27: MNSO | B27: Long | C27: Minoso | D27: =1211.7123+804.6763 -> 2016.3886 | E27: =F27/D27 -> 20.49104 | F27: 41317.9 | G27: 42071.53 | H27: =G27/D27 -> 20.864793 | I27: =G27-F27 -> 753.63 | J27: =I27/F27 -> 0.018239794 | K27: 45135 | L27: 45308 | M27: =DAYS360(K27,L27) -> 169 | O27: Totally blew this trade. Had a nearly 50% profit.
A28: ACMR | B28: Long | C28: ACM Research | D28: =1339.9646+918.07 -> 2258.0346 | E28: =F28/D28 -> 21.193736 | F28: =28457.8+19398.39 -> 47856.19 | G28: 39178.27 | H28: =G28/D28 -> 17.350607 | I28: =G28-F28 -> -8677.92 | J28: =I28/F28 -> -0.18133328 | K28: 45302 | L28: 45322 | M28: =DAYS360(K28,L28) -> 20
A29: MDB | B29: Long | C29: MongoDB | D29: 126.054 | E29: =F29/D29 -> 450.27964 | F29: 56759.55 | G29: 54939.36 | H29: =G29/D29 -> 435.83988 | I29: =G29-F29 -> -1820.19 | J29: =I29/F29 -> -0.032068436 | K29: 45327 | L29: 45342 | M29: =DAYS360(K29,L29) -> 15 | O29: Stopped out.
A30: VKTX | B30: Long | C30: Viking Therap | D30: 808.6324 | E30: =F30/D30 -> 21.530005 | F30: 17409.86 | G30: 28227.27 | H30: =G30/D30 -> 34.907419 | I30: =G30-F30 -> 10817.41 | J30: =I30/F30 -> 0.62133814 | K30: 45309 | L30: 45343 | M30: =DAYS360(K30,L30) -> 33 | O30: Took partial profit.
I32: =SUM(I25:I31) -> -6397.27
I39: =SUM(I26:I38) -> -9631.67 | J39: Avg
H40: # of losses
H41: # of wins

