Workbook

Sheet 12-31-25
C1: 46022
C3: MANAGED ACCT | X3: Current | AC3: IBD
H4: Cost | J4: P/L | N4: Group | P4: EPS | R4: pivot | S4: last | W4: cost | X4: Stop | Y4: Stop | Z4: % | AB4: EPS | AC4: Comp
A5: Symbol | B5: Position | C5: Name | D5: Qty | E5: Current | F5: Value | G5: Cost | H5: per share | I5: P/L $ | J5: per sh | K5: Date purch | L5: days held | M5: % incr | N5: Rank | O5: RS | P5: RS | Q5: pivot | R5: -0.07 | S5: low | T5: 0.25 | U5: 0.5 | V5: 1 | W5: -0.07 | X5: Loss | Y5: Loss% | Z5: of port | AB5: Due | AC5: Rank
A7: AAPL | B7: Long | C7: Apple | D7: 288.5853 | E7: 271.86 | F7: =E7*D7 -> 78454.8 | G7: 78305 | H7: =G7/D7 -> 271.34092 | I7: =F7-G7 -> 149.79966 | J7: =E7-H7 -> 0.51908277 | K7: 45971 | L7: =DAYS360(K7,$C$1) -> 51 | M7: =(I7/G7) -> 0.001913028 | N7: 138 | O7: 79 | P7: 84 | Q7: 259.24 | R7: =Q7*0.93 -> 241.0932 | S7: 255.43 | T7: =Q7*1.25 -> 324.05 | U7: =Q7*1.5 -> 388.86 | V7: =Q7*2 -> 518.48 | W7: =H7-(H7*0.07) -> 252.34705 | X7: 265 | Y7: =(X7-H7)/H7 -> -0.023368821 | Z7: =F7/F$20 -> 0.13039822 | AB7: 46051 | AC7: 88
A8: APP | B8: Long | C8: Applovin | D8: 90.3434 | E8: 673.82 | F8: =E8*D8 -> 60875.19 | G8: 61276.76 | H8: =G8/D8 -> 678.26493 | I8: =F8-G8 -> -401.57021 | J8: =E8-H8 -> -4.4449314 | K8: 45995 | L8: =DAYS360(K8,$C$1) -> 27 | M8: =(I8/G8) -> -0.0065533852 | N8: 33 | O8: 95 | P8: 80 | Q8: 675 | R8: =Q8*0.93 -> 627.75 | S8: 489.3 | T8: =Q8*1.25 -> 843.75 | U8: =Q8*1.5 -> 1012.5 | V8: =Q8*2 -> 1350 | W8: =H8-(H8*0.07) -> 630.78639 | X8: 650 | Y8: =(X8-H8)/H8 -> -0.041672406 | Z8: =F8/F$20 -> 0.10117949 | AB8: 46071 | AC8: 99
A9: GEV | B9: Long | C9: GE Vernova | D9: =97.1506+30.2251 -> 127.3757 | E9: 653.57 | F9: =E9*D9 -> 83248.936 | G9: =61467.93+20488.3849 -> 81956.315 | H9: =G9/D9 -> 643.4219 | I9: =F9-G9 -> 1292.6213 | J9: =E9-H9 -> 10.1481 | K9: 46000 | L9: =DAYS360(K9,$C$1) -> 22 | M9: =(I9/G9) -> 0.015772077 | N9: 49 | O9: 93 | P9: 40 | Q9: 664.69 | R9: =Q9*0.93 -> 618.1617 | S9: 555.84 | T9: =Q9*1.25 -> 830.8625 | U9: =Q9*1.5 -> 997.035 | V9: =Q9*2 -> 1329.38 | W9: =H9-(H9*0.07) -> 598.38237 | X9: 630 | Y9: =(X9-H9)/H9 -> -0.020860185 | Z9: =F9/F$20 -> 0.13836647 | AB9: 46050 | AC9: 82
A10: TSLA | B10: Long | C10: Tesla | D10: 129.2645 | E10: 449.72 | F10: =E10*D10 -> 58132.831 | G10: 61897.92 | H10: =G10/D10 -> 478.84702 | I10: =F10-G10 -> -3765.0891 | J10: =E10-H10 -> -29.127015 | K10: 46006 | L10: =DAYS360(K10,$C$1) -> 16 | M10: =(I10/G10) -> -0.060827392 | N10: 23 | O10: 85 | P10: 46 | Q10: 458.87 | R10: =Q10*0.93 -> 426.7491 | S10: 435.25 | T10: =Q10*1.25 -> 573.5875 | U10: =Q10*1.5 -> 688.305 | V10: =Q10*2 -> 917.74 | W10: =H10-(H10*0.07) -> 445.32772 | X10: 445 | Y10: =(X10-H10)/H10 -> -0.070684403 | Z10: =F10/F$20 -> 0.096621468 | AB10: 46050 | AC10: 77
A11: URBN | B11: Long | C11: Urban Outfitters | D11: 747.3506 | E11: 75.26 | F11: =E11*D11 -> 56245.606 | G11: 61420 | H11: =G11/D11 -> 82.18365 | I11: =F11-G11 -> -5174.3938 | J11: =E11-H11 -> -6.9236498 | K11: 46009 | L11: =DAYS360(K11,$C$1) -> 13 | M11: =(I11/G11) -> -0.084246074 | N11: 36 | O11: 81 | P11: 94 | Q11: 79.92 | R11: =Q11*0.93 -> 74.3256 | S11: 73.66 | T11: =Q11*1.25 -> 99.9 | U11: =Q11*1.5 -> 119.88 | V11: =Q11*2 -> 159.84 | W11: =H11-(H11*0.07) -> 76.430794 | X11: 77 | Y11: =(X11-H11)/H11 -> -0.063073979 | Z11: =F11/F$20 -> 0.093484748 | AB11: 46084 | AC11: 98
A12: UFO | B12: Long | C12: Procure Space ETF | D12: 774.8271 | E12: 38.65 | F12: =E12*D12 -> 29947.067 | G12: 30380.12 | H12: =G12/D12 -> 39.208902 | I12: =F12-G12 -> -433.05259 | J12: =E12-H12 -> -0.55890222 | K12: 46021 | L12: =DAYS360(K12,$C$1) -> 0 | M12: =(I12/G12) -> -0.014254472 | N12: - | O12: 91 | P12: - | Q12: 40.68 | R12: =Q12*0.93 -> 37.8324 | S12: 35.32 | T12: =Q12*1.25 -> 50.85 | U12: =Q12*1.5 -> 61.02 | V12: =Q12*2 -> 81.36 | W12: =H12-(H12*0.07) -> 36.464279 | X12: 37 | Y12: =(X12-H12)/H12 -> -0.056336752 | Z12: =F12/F$20 -> 0.049774449 | AB12: - | AC12: -
F13: =E13*D13 -> 0 | H13: =G13/D13 -> #DIV/0! | I13: =F13-G13 -> 0 | J13: =E13-H13 -> #DIV/0! | L13: =DAYS360(K13,$C$1) -> 45361 | M13: =(I13/G13) -> #DIV/0! | R13: =Q13*0.93 -> 0 | T13: =Q13*1.25 -> 0 | U13: =Q13*1.5 -> 0 | V13: =Q13*2 -> 0 | W13: =H13-(H13*0.07) -> #DIV/0! | Y13: =(X13-H13)/H13 -> #DIV/0! | Z13: =F13/F$20 -> 0
F14: =E14*D14 -> 0 | H14: =G14/D14 -> #DIV/0! | I14: =F14-G14 -> 0 | J14: =E14-H14 -> #DIV/0! | L14: =DAYS360(K14,$C$1) -> 45361 | M14: =(I14/G14) -> #DIV/0! | R14: =Q14*0.93 -> 0 | T14: =Q14*1.25 -> 0 | U14: =Q14*1.5 -> 0 | V14: =Q14*2 -> 0 | W14: =H14-(H14*0.07) -> #DIV/0! | Y14: =(X14-H14)/H14 -> #DIV/0! | Z14: =F14/F$20 -> 0
F15: =E15*D15 -> 0 | H15: =G15/D15 -> #DIV/0! | I15: =F15-G15 -> 0 | J15: =E15-H15 -> #DIV/0! | L15: =DAYS360(K15,$C$1) -> 45361 | M15: =(I15/G15) -> #DIV/0! | R15: =Q15*0.93 -> 0 | T15: =Q15*1.25 -> 0 | U15: =Q15*1.5 -> 0 | V15: =Q15*2 -> 0 | W15: =H15-(H15*0.07) -> #DIV/0! | Y15: =(X15-H15)/H15 -> #DIV/0! | Z15: =F15/F$20 -> 0
F16: =E16*D16 -> 0 | H16: =G16/D16 -> #DIV/0! | I16: =F16-G16 -> 0 | J16: =E16-H16 -> #DIV/0! | L16: =DAYS360(K16,$C$1) -> 45361 | M16: =(I16/G16) -> #DIV/0! | R16: =Q16*0.93 -> 0 | T16: =Q16*1.25 -> 0 | U16: =Q16*1.5 -> 0 | V16: =Q16*2 -> 0 | W16: =H16-(H16*0.07) -> #DIV/0! | Y16: =(X16-H16)/H16 -> #DIV/0! | Z16: =F16/F$20 -> 0
F17: =E17*D17 -> 0 | H17: =G17/D17 -> #DIV/0! | I17: =F17-G17 -> 0 | J17: =E17-H17 -> #DIV/0! | L17: =DAYS360(K17,$C$1) -> 45361 | M17: =(I17/G17) -> #DIV/0! | R17: =Q17*0.93 -> 0 | T17: =Q17*1.25 -> 0 | U17: =Q17*1.5 -> 0 | V17: =Q17*2 -> 0 | W17: =H17-(H17*0.07) -> #DIV/0! | Y17: =(X17-H17)/H17 -> #DIV/0! | Z17: =F17/F$20 -> 0
A18: Sub-Total | F18: =SUM(F6:F17) -> 366904.43 | G18: =SUM(G6:G17) -> 375236.11 | I18: =SUM(I6:I17) -> -8331.6847
D19: Cash, other | F19: 234751 | G19: =F19/F20 -> 0.39017515
D20: Total | F20: =SUM(F18:F19) -> 601655.43 | K20: Control acct (Doug's IRA) | M20: Today
H21: Last week's close | I21: =#REF! -> #REF! | K21: 45657 | L21: 170762 | M21: 208334
H22: Week's change | I22: =(F20-I21)/I21 -> #REF! | K22: ytd chg % | L22: =(M21-L21)/L21 -> 0.22002553
M24: days
A25: 2026 Closed Trades - Managed Acct | D25: Qty | E25: Cost/sh | F25: $ cost | G25: $Proc | H25: Proc/sh | I25: Profit/loss | J25: % | K25: Date purch | L25: Date sold | M25: held
E26: =F26/D26 -> #DIV/0! | H26: =G26/D26 -> #DIV/0! | I26: =G26-F26 -> 0 | J26: =I26/F26 -> #DIV/0! | M26: =DAYS360(K26,L26) -> 0
E27: =F27/D27 -> #DIV/0! | H27: =G27/D27 -> #DIV/0! | I27: =G27-F27 -> 0 | J27: =I27/F27 -> #DIV/0! | M27: =DAYS360(K27,L27) -> 0
E28: =F28/D28 -> #DIV/0! | H28: =G28/D28 -> #DIV/0! | I28: =G28-F28 -> 0 | J28: =I28/F28 -> #DIV/0! | M28: =DAYS360(K28,L28) -> 0
E29: =F29/D29 -> #DIV/0! | H29: =G29/D29 -> #DIV/0! | I29: =G29-F29 -> 0 | J29: =I29/F29 -> #DIV/0! | M29: =DAYS360(K29,L29) -> 0
E30: =F30/D30 -> #DIV/0! | H30: =G30/D30 -> #DIV/0! | I30: =G30-F30 -> 0 | J30: =I30/F30 -> #DIV/0! | M30: =DAYS360(K30,L30) -> 0
E31: =F31/D31 -> #DIV/0! | H31: =G31/D31 -> #DIV/0! | I31: =G31-F31 -> 0 | J31: =I31/F31 -> #DIV/0! | M31: =DAYS360(K31,L31) -> 0
E32: =F32/D32 -> #DIV/0! | H32: =G32/D32 -> #DIV/0! | I32: =G32-F32 -> 0 | J32: =I32/F32 -> #DIV/0! | M32: =DAYS360(K32,L32) -> 0
E33: =F33/D33 -> #DIV/0! | H33: =G33/D33 -> #DIV/0! | I33: =G33-F33 -> 0 | J33: =I33/F33 -> #DIV/0! | M33: =DAYS360(K33,L33) -> 0
E34: =F34/D34 -> #DIV/0! | H34: =G34/D34 -> #DIV/0! | I34: =G34-F34 -> 0 | J34: =I34/F34 -> #DIV/0! | M34: =DAYS360(K34,L34) -> 0
E35: =F35/D35 -> #DIV/0! | H35: =G35/D35 -> #DIV/0! | I35: =G35-F35 -> 0 | J35: =I35/F35 -> #DIV/0! | M35: =DAYS360(K35,L35) -> 0
E36: =F36/D36 -> #DIV/0! | H36: =G36/D36 -> #DIV/0! | I36: =G36-F36 -> 0 | J36: =I36/F36 -> #DIV/0! | M36: =DAYS360(K36,L36) -> 0
E37: =F37/D37 -> #DIV/0! | H37: =G37/D37 -> #DIV/0! | I37: =G37-F37 -> 0 | J37: =I37/F37 -> #DIV/0! | M37: =DAYS360(K37,L37) -> 0
... E70: =F70/D70 -> #DIV/0! | H70: =G70/D70 -> #DIV/0! | I70: =G70-F70 -> 0 | J70: =I70/F70 -> #DIV/0! | M70: =DAYS360(K70,L70) -> 0
H73: Total gains | I73: =SUM(I26:I70) -> 0 | J73: Avg
H74: # of losses
H75: # of wins
I76: =SUM(I74:I75) -> 0
H77: W/L ratio | I77: =I75/I76 -> #DIV/0! | J77: =J75/J74*-1 -> #DIV/0!

Sheet 01-02-26
C1: 46024
C3: MANAGED ACCT | X3: Current | AC3: IBD
H4: Cost | J4: P/L | N4: Group | P4: EPS | R4: pivot | S4: last | W4: cost | X4: Stop | Y4: Stop | Z4: % | AB4: EPS | AC4: Comp
A5: Symbol | B5: Position | C5: Name | D5: Qty | E5: Current | F5: Value | G5: Cost | H5: per share | I5: P/L $ | J5: per sh | K5: Date purch | L5: days held | M5: % incr | N5: Rank | O5: RS | P5: RS | Q5: pivot | R5: -0.07 | S5: low | T5: 0.25 | U5: 0.5 | V5: 1 | W5: -0.07 | X5: Loss | Y5: Loss% | Z5: of port | AB5: Due | AC5: Rank
A7: AAPL | B7: Long | C7: Apple | D7: 288.5853 | E7: 271.86 | F7: =E7*D7 -> 78454.8 | G7: 78305 | H7: =G7/D7 -> 271.34092 | I7: =F7-G7 -> 149.79966 | J7: =E7-H7 -> 0.51908277 | K7: 45971 | L7: =DAYS360(K7,$C$1) -> 52 | M7: =(I7/G7) -> 0.001913028 | N7: 147 | O7: 80 | P7: 84 | Q7: 259.24 | R7: =Q7*0.93 -> 241.0932 | S7: 255.43 | T7: =Q7*1.25 -> 324.05 | U7: =Q7*1.5 -> 388.86 | V7: =Q7*2 -> 518.48 | W7: =H7-(H7*0.07) -> 252.34705 | X7: 265 | Y7: =(X7-H7)/H7 -> -0.023368821 | Z7: =F7/F$20 -> 0.13084972 | AB7: 46051 | AC7: 87
A8: APP | B8: Long | C8: Applovin | D8: 90.3434 | E8: 618.32 | F8: =E8*D8 -> 55861.131 | G8: 61276.76 | H8: =G8/D8 -> 678.26493 | I8: =F8-G8 -> -5415.6289 | J8: =E8-H8 -> -59.944931 | K8: 45995 | L8: =DAYS360(K8,$C$1) -> 28 | M8: =(I8/G8) -> -0.088379818 | N8: 57 | O8: 94 | P8: 80 | Q8: 675 | R8: =Q8*0.93 -> 627.75 | S8: 489.3 | T8: =Q8*1.25 -> 843.75 | U8: =Q8*1.5 -> 1012.5 | V8: =Q8*2 -> 1350 | W8: =H8-(H8*0.07) -> 630.78639 | X8: 650 | Y8: =(X8-H8)/H8 -> -0.041672406 | Z8: =F8/F$20 -> 0.093167191 | AB8: 46071 | AC8: 98
A9: GEV | B9: Long | C9: GE Vernova | D9: =97.1506+30.2251 -> 127.3757 | E9: 679.55 | F9: =E9*D9 -> 86558.157 | G9: =61467.93+20488.3849 -> 81956.315 | H9: =G9/D9 -> 643.4219 | I9: =F9-G9 -> 4601.842 | J9: =E9-H9 -> 36.1281 | K9: 46000 | L9: =DAYS360(K9,$C$1) -> 23 | M9: =(I9/G9) -> 0.056149938 | N9: 43 | O9: 94 | P9: 40 | Q9: 664.69 | R9: =Q9*0.93 -> 618.1617 | S9: 555.84 | T9: =Q9*1.25 -> 830.8625 | U9: =Q9*1.5 -> 997.035 | V9: =Q9*2 -> 1329.38 | W9: =H9-(H9*0.07) -> 598.38237 | X9: 630 | Y9: =(X9-H9)/H9 -> -0.020860185 | Z9: =F9/F$20 -> 0.14436479 | AB9: 46050 | AC9: 84
A10: TSLA | B10: Long | C10: Tesla | D10: 129.2645 | E10: 438.07 | F10: =E10*D10 -> 56626.9 | G10: 61897.92 | H10: =G10/D10 -> 478.84702 | I10: =F10-G10 -> -5271.0205 | J10: =E10-H10 -> -40.777015 | K10: 46006 | L10: =DAYS360(K10,$C$1) -> 17 | M10: =(I10/G10) -> -0.085156666 | N10: 30 | O10: 86 | P10: 45 | Q10: 458.87 | R10: =Q10*0.93 -> 426.7491 | S10: 435.25 | T10: =Q10*1.25 -> 573.5875 | U10: =Q10*1.5 -> 688.305 | V10: =Q10*2 -> 917.74 | W10: =H10-(H10*0.07) -> 445.32772 | X10: 445 | Y10: =(X10-H10)/H10 -> -0.070684403 | Z10: =F10/F$20 -> 0.094444367 | AB10: 46050 | AC10: 75
A11: URBN | B11: Long | C11: Urban Outfitters | D11: 747.3506 | E11: 75.26 | F11: =E11*D11 -> 56245.606 | G11: 61420 | H11: =G11/D11 -> 82.18365 | I11: =F11-G11 -> -5174.3938 | J11: =E11-H11 -> -6.9236498 | K11: 46009 | L11: =DAYS360(K11,$C$1) -> 14 | M11: =(I11/G11) -> -0.084246074 | N11: 36 | O11: 81 | P11: 94 | Q11: 79.92 | R11: =Q11*0.93 -> 74.3256 | S11: 73.66 | T11: =Q11*1.25 -> 99.9 | U11: =Q11*1.5 -> 119.88 | V11: =Q11*2 -> 159.84 | W11: =H11-(H11*0.07) -> 76.430794 | X11: 77 | Y11: =(X11-H11)/H11 -> -0.063073979 | Z11: =F11/F$20 -> 0.093808433 | AB11: 46084 | AC11: 98
A12: UFO | B12: Long | C12: Procure Space ETF | D12: =774.8271+421.3989 -> 1196.226 | E12: 40.32 | F12: =E12*D12 -> 48231.832 | G12: =30380.12+16944.65 -> 47324.77 | H12: =G12/D12 -> 39.56173 | I12: =F12-G12 -> 907.06232 | J12: =E12-H12 -> 0.75827003 | K12: 46021 | L12: =DAYS360(K12,$C$1) -> 2 | M12: =(I12/G12) -> 0.019166756 | N12: - | O12: 92 | P12: - | Q12: 40.68 | R12: =Q12*0.93 -> 37.8324 | S12: 35.32 | T12: =Q12*1.25 -> 50.85 | U12: =Q12*1.5 -> 61.02 | V12: =Q12*2 -> 81.36 | W12: =H12-(H12*0.07) -> 36.792409 | X12: 37 | Y12: =(X12-H12)/H12 -> -0.064752729 | Z12: =F12/F$20 -> 0.080442774 | AB12: - | AC12: -
F13: =E13*D13 -> 0 | H13: =G13/D13 -> #DIV/0! | I13: =F13-G13 -> 0 | J13: =E13-H13 -> #DIV/0! | L13: =DAYS360(K13,$C$1) -> 45362 | M13: =(I13/G13) -> #DIV/0! | R13: =Q13*0.93 -> 0 | T13: =Q13*1.25 -> 0 | U13: =Q13*1.5 -> 0 | V13: =Q13*2 -> 0 | W13: =H13-(H13*0.07) -> #DIV/0! | Y13: =(X13-H13)/H13 -> #DIV/0! | Z13: =F13/F$20 -> 0
F14: =E14*D14 -> 0 | H14: =G14/D14 -> #DIV/0! | I14: =F14-G14 -> 0 | J14: =E14-H14 -> #DIV/0! | L14: =DAYS360(K14,$C$1) -> 45362 | M14: =(I14/G14) -> #DIV/0! | R14: =Q14*0.93 -> 0 | T14: =Q14*1.25 -> 0 | U14: =Q14*1.5 -> 0 | V14: =Q14*2 -> 0 | W14: =H14-(H14*0.07) -> #DIV/0! | Y14: =(X14-H14)/H14 -> #DIV/0! | Z14: =F14/F$20 -> 0
F15: =E15*D15 -> 0 | H15: =G15/D15 -> #DIV/0! | I15: =F15-G15 -> 0 | J15: =E15-H15 -> #DIV/0! | L15: =DAYS360(K15,$C$1) -> 45362 | M15: =(I15/G15) -> #DIV/0! | R15: =Q15*0.93 -> 0 | T15: =Q15*1.25 -> 0 | U15: =Q15*1.5 -> 0 | V15: =Q15*2 -> 0 | W15: =H15-(H15*0.07) -> #DIV/0! | Y15: =(X15-H15)/H15 -> #DIV/0! | Z15: =F15/F$20 -> 0
F16: =E16*D16 -> 0 | H16: =G16/D16 -> #DIV/0! | I16: =F16-G16 -> 0 | J16: =E16-H16 -> #DIV/0! | L16: =DAYS360(K16,$C$1) -> 45362 | M16: =(I16/G16) -> #DIV/0! | R16: =Q16*0.93 -> 0 | T16: =Q16*1.25 -> 0 | U16: =Q16*1.5 -> 0 | V16: =Q16*2 -> 0 | W16: =H16-(H16*0.07) -> #DIV/0! | Y16: =(X16-H16)/H16 -> #DIV/0! | Z16: =F16/F$20 -> 0
F17: =E17*D17 -> 0 | H17: =G17/D17 -> #DIV/0! | I17: =F17-G17 -> 0 | J17: =E17-H17 -> #DIV/0! | L17: =DAYS360(K17,$C$1) -> 45362 | M17: =(I17/G17) -> #DIV/0! | R17: =Q17*0.93 -> 0 | T17: =Q17*1.25 -> 0 | U17: =Q17*1.5 -> 0 | V17: =Q17*2 -> 0 | W17: =H17-(H17*0.07) -> #DIV/0! | Y17: =(X17-H17)/H17 -> #DIV/0! | Z17: =F17/F$20 -> 0
A18: Sub-Total | F18: =SUM(F6:F17) -> 381978.43 | G18: =SUM(G6:G17) -> 392180.76 | I18: =SUM(I6:I17) -> -10202.339
D19: Cash, other | F19: 217601 | G19: =F19/F20 -> 0.36292273
D20: Total | F20: =SUM(F18:F19) -> 599579.43 | K20: Control acct (Doug's IRA) | M20: Today
H21: Last week's close | I21: 612079 | K21: 45657 | L21: 208334 | M21: 207891
H22: Week's change | I22: =(F20-I21)/I21 -> -0.020421505 | K22: ytd chg % | L22: =(M21-L21)/L21 -> -0.0021263932
M24: days
A25: 2026 Closed Trades - Managed Acct | D25: Qty | E25: Cost/sh | F25: $ cost | G25: $Proc | H25: Proc/sh | I25: Profit/loss | J25: % | K25: Date purch | L25: Date sold | M25: held
E26: =F26/D26 -> #DIV/0! | H26: =G26/D26 -> #DIV/0! | I26: =G26-F26 -> 0 | J26: =I26/F26 -> #DIV/0! | M26: =DAYS360(K26,L26) -> 0
E27: =F27/D27 -> #DIV/0! | H27: =G27/D27 -> #DIV/0! | I27: =G27-F27 -> 0 | J27: =I27/F27 -> #DIV/0! | M27: =DAYS360(K27,L27) -> 0
E28: =F28/D28 -> #DIV/0! | H28: =G28/D28 -> #DIV/0! | I28: =G28-F28 -> 0 | J28: =I28/F28 -> #DIV/0! | M28: =DAYS360(K28,L28) -> 0
E29: =F29/D29 -> #DIV/0! | H29: =G29/D29 -> #DIV/0! | I29: =G29-F29 -> 0 | J29: =I29/F29 -> #DIV/0! | M29: =DAYS360(K29,L29) -> 0
E30: =F30/D30 -> #DIV/0! | H30: =G30/D30 -> #DIV/0! | I30: =G30-F30 -> 0 | J30: =I30/F30 -> #DIV/0! | M30: =DAYS360(K30,L30) -> 0
E31: =F31/D31 -> #DIV/0! | H31: =G31/D31 -> #DIV/0! | I31: =G31-F31 -> 0 | J31: =I31/F31 -> #DIV/0! | M31: =DAYS360(K31,L31) -> 0
E32: =F32/D32 -> #DIV/0! | H32: =G32/D32 -> #DIV/0! | I32: =G32-F32 -> 0 | J32: =I32/F32 -> #DIV/0! | M32: =DAYS360(K32,L32) -> 0
H36: Total gains | I36: =SUM(I26:I33) -> 0 | J36: Avg
H37: # of losses
H38: # of wins
I39: =SUM(I37:I38) -> 0
H40: W/L ratio | I40: =I38/I39 -> #DIV/0! | J40: =J38/J37*-1 -> #DIV/0!

Sheet 01-09-26
C1: 46031
C3: MANAGED ACCT | X3: Current | AC3: IBD
H4: Cost | J4: P/L | N4: Group | P4: EPS | R4: pivot | S4: last | W4: cost | X4: Stop | Y4: Stop | Z4: % | AB4: EPS | AC4: Comp
A5: Symbol | B5: Position | C5: Name | D5: Qty | E5: Current | F5: Value | G5: Cost | H5: per share | I5: P/L $ | J5: per sh | K5: Date purch | L5: days held | M5: % incr | N5: Rank | O5: RS | P5: RS | Q5: pivot | R5: -0.07 | S5: low | T5: 0.25 | U5: 0.5 | V5: 1 | W5: -0.07 | X5: Loss | Y5: Loss% | Z5: of port | AB5: Due | AC5: Rank
A7: AAPL | B7: Long | C7: Apple | D7: 288.5853 | E7: 259.31 | F7: =E7*D7 -> 74833.054 | G7: 78305 | H7: =G7/D7 -> 271.34092 | I7: =F7-G7 -> -3471.9459 | J7: =E7-H7 -> -12.030917 | K7: 45971 | L7: =DAYS360(K7,$C$1) -> 59 | M7: =(I7/G7) -> -0.04433875 | N7: 76 | O7: 71 | P7: 84 | Q7: 259.24 | R7: =Q7*0.93 -> 241.0932 | S7: 255.43 | T7: =Q7*1.25 -> 324.05 | U7: =Q7*1.5 -> 388.86 | V7: =Q7*2 -> 518.48 | W7: =H7-(H7*0.07) -> 252.34705 | X7: 265 | Y7: =(X7-H7)/H7 -> -0.023368821 | Z7: =F7/F$20 -> 0.12066115 | AB7: 46051 | AC7: 81
A8: APP | B8: Long | C8: Applovin | D8: 90.3434 | E8: 647.72 | F8: =E8*D8 -> 58517.227 | G8: 61276.76 | H8: =G8/D8 -> 678.26493 | I8: =F8-G8 -> -2759.533 | J8: =E8-H8 -> -30.544931 | K8: 45995 | L8: =DAYS360(K8,$C$1) -> 35 | M8: =(I8/G8) -> -0.045033924 | N8: 55 | O8: 93 | P8: 80 | Q8: 675 | R8: =Q8*0.93 -> 627.75 | S8: 489.3 | T8: =Q8*1.25 -> 843.75 | U8: =Q8*1.5 -> 1012.5 | V8: =Q8*2 -> 1350 | W8: =H8-(H8*0.07) -> 630.78639 | X8: 650 | Y8: =(X8-H8)/H8 -> -0.041672406 | Z8: =F8/F$20 -> 0.09435344 | AB8: 46064 | AC8: 98
A9: GEV | B9: Long | C9: GE Vernova | D9: =97.1506+30.2251 -> 127.3757 | E9: 622.5 | F9: =E9*D9 -> 79291.373 | G9: =61467.93+20488.3849 -> 81956.315 | H9: =G9/D9 -> 643.4219 | I9: =F9-G9 -> -2664.9417 | J9: =E9-H9 -> -20.9219 | K9: 46000 | L9: =DAYS360(K9,$C$1) -> 30 | M9: =(I9/G9) -> -0.032516611 | N9: 56 | O9: 89 | P9: 40 | Q9: 664.69 | R9: =Q9*0.93 -> 618.1617 | S9: 555.84 | T9: =Q9*1.25 -> 830.8625 | U9: =Q9*1.5 -> 997.035 | V9: =Q9*2 -> 1329.38 | W9: =H9-(H9*0.07) -> 598.38237 | X9: 630 | Y9: =(X9-H9)/H9 -> -0.020860185 | Z9: =F9/F$20 -> 0.12784977 | AB9: 46050 | AC9: 75
A10: TSLA | B10: Long | C10: Tesla | D10: 129.2645 | E10: 445 | F10: =E10*D10 -> 57522.702 | G10: 61897.92 | H10: =G10/D10 -> 478.84702 | I10: =F10-G10 -> -4375.2175 | J10: =E10-H10 -> -33.847015 | K10: 46006 | L10: =DAYS360(K10,$C$1) -> 24 | M10: =(I10/G10) -> -0.070684403 | N10: 35 | O10: 83 | P10: 45 | Q10: 458.87 | R10: =Q10*0.93 -> 426.7491 | S10: 435.25 | T10: =Q10*1.25 -> 573.5875 | U10: =Q10*1.5 -> 688.305 | V10: =Q10*2 -> 917.74 | W10: =H10-(H10*0.07) -> 445.32772 | X10: 445 | Y10: =(X10-H10)/H10 -> -0.070684403 | Z10: =F10/F$20 -> 0.092749864 | AB10: 46050 | AC10: 67
A11: URBN | B11: Long | C11: Urban Outfitters | D11: 747.3506 | E11: 81.56 | F11: =E11*D11 -> 60953.915 | G11: 61420 | H11: =G11/D11 -> 82.18365 | I11: =F11-G11 -> -466.08506 | J11: =E11-H11 -> -0.62364982 | K11: 46009 | L11: =DAYS360(K11,$C$1) -> 21 | M11: =(I11/G11) -> -0.0075884901 | N11: 33 | O11: 86 | P11: 94 | Q11: 79.92 | R11: =Q11*0.93 -> 74.3256 | S11: 73.66 | T11: =Q11*1.25 -> 99.9 | U11: =Q11*1.5 -> 119.88 | V11: =Q11*2 -> 159.84 | W11: =H11-(H11*0.07) -> 76.430794 | X11: 77 | Y11: =(X11-H11)/H11 -> -0.063073979 | Z11: =F11/F$20 -> 0.098282366 | AB11: 46084 | AC11: 98
A12: UFO | B12: Long | C12: Procure Space ETF | D12: =774.8271+421.3989 -> 1196.226 | E12: 43.88 | F12: =E12*D12 -> 52490.397 | G12: =30380.12+16944.65 -> 47324.77 | H12: =G12/D12 -> 39.56173 | I12: =F12-G12 -> 5165.6269 | J12: =E12-H12 -> 4.31827 | K12: 46021 | L12: =DAYS360(K12,$C$1) -> 9 | M12: =(I12/G12) -> 0.10915271 | N12: - | O12: 92 | P12: - | Q12: 40.68 | R12: =Q12*0.93 -> 37.8324 | S12: 35.32 | T12: =Q12*1.25 -> 50.85 | U12: =Q12*1.5 -> 61.02 | V12: =Q12*2 -> 81.36 | W12: =H12-(H12*0.07) -> 36.792409 | X12: 39 | Y12: =(X12-H12)/H12 -> -0.014198822 | Z12: =F12/F$20 -> 0.084635752 | AB12: - | AC12: -
A13: KRMN | B13: Long | C13: Karman Hldgs | D13: 451.9359 | E13: 106.22 | F13: =E13*D13 -> 48004.631 | G13: 36213.63 | H13: =G13/D13 -> 80.130014 | I13: =F13-G13 -> 11791.001 | J13: =E13-H13 -> 26.089986 | K13: 46027 | L13: =DAYS360(K13,$C$1) -> 4 | M13: =(I13/G13) -> 0.32559567 | N13: 37 | O13: 98 | P13: 80 | Q13: 81 | R13: =Q13*0.93 -> 75.33 | S13: 72 | T13: =Q13*1.25 -> 101.25 | U13: =Q13*1.5 -> 121.5 | V13: =Q13*2 -> 162 | W13: =H13-(H13*0.07) -> 74.520913 | X13: 85 | Y13: =(X13-H13)/H13 -> 0.060776053 | Z13: =F13/F$20 -> 0.077402883 | AB13: 46126 | AC13: 99
A14: RKT | B14: Long | C14: Rocket Cos | D14: =1733.9964+1138.3726 -> 2872.369 | E14: 23.29 | F14: =E14*D14 -> 66897.474 | G14: =36288.78+24176.77 -> 60465.55 | H14: =G14/D14 -> 21.05076 | I14: =F14-G14 -> 6431.924 | J14: =E14-H14 -> 2.2392402 | K14: 46027 | L14: =DAYS360(K14,$C$1) -> 4 | M14: =(I14/G14) -> 0.10637336 | N14: 58 | O14: 94 | P14: 15 | Q14: 20.6 | R14: =Q14*0.93 -> 19.158 | S14: 17.76 | T14: =Q14*1.25 -> 25.75 | U14: =Q14*1.5 -> 30.9 | V14: =Q14*2 -> 41.2 | W14: =H14-(H14*0.07) -> 19.577207 | X14: 20.5 | Y14: =(X14-H14)/H14 -> -0.026163419 | Z14: =F14/F$20 -> 0.10786579 | AB14: 46072 | AC14: 81
F15: =E15*D15 -> 0 | H15: =G15/D15 -> #DIV/0! | I15: =F15-G15 -> 0 | J15: =E15-H15 -> #DIV/0! | L15: =DAYS360(K15,$C$1) -> 45369 | M15: =(I15/G15) -> #DIV/0! | R15: =Q15*0.93 -> 0 | T15: =Q15*1.25 -> 0 | U15: =Q15*1.5 -> 0 | V15: =Q15*2 -> 0 | W15: =H15-(H15*0.07) -> #DIV/0! | Y15: =(X15-H15)/H15 -> #DIV/0! | Z15: =F15/F$20 -> 0
F16: =E16*D16 -> 0 | H16: =G16/D16 -> #DIV/0! | I16: =F16-G16 -> 0 | J16: =E16-H16 -> #DIV/0! | L16: =DAYS360(K16,$C$1) -> 45369 | M16: =(I16/G16) -> #DIV/0! | R16: =Q16*0.93 -> 0 | T16: =Q16*1.25 -> 0 | U16: =Q16*1.5 -> 0 | V16: =Q16*2 -> 0 | W16: =H16-(H16*0.07) -> #DIV/0! | Y16: =(X16-H16)/H16 -> #DIV/0! | Z16: =F16/F$20 -> 0
F17: =E17*D17 -> 0 | H17: =G17/D17 -> #DIV/0! | I17: =F17-G17 -> 0 | J17: =E17-H17 -> #DIV/0! | L17: =DAYS360(K17,$C$1) -> 45369 | M17: =(I17/G17) -> #DIV/0! | R17: =Q17*0.93 -> 0 | T17: =Q17*1.25 -> 0 | U17: =Q17*1.5 -> 0 | V17: =Q17*2 -> 0 | W17: =H17-(H17*0.07) -> #DIV/0! | Y17: =(X17-H17)/H17 -> #DIV/0! | Z17: =F17/F$20 -> 0
A18: Sub-Total | F18: =SUM(F6:F17) -> 498510.77 | G18: =SUM(G6:G17) -> 488859.94 | I18: =SUM(I6:I17) -> 9650.8292
D19: Cash, other | F19: 121681 | G19: =F19/F20 -> 0.19619899
D20: Total | F20: =SUM(F18:F19) -> 620191.77 | K20: Control acct (Doug's IRA) | M20: Today
H21: Last week's close | I21: ='01-02-26'!F20 -> 599579.43 | K21: 45657 | L21: 208334 | M21: 215042
H22: Week's change | I22: =(F20-I21)/I21 -> 0.034378012 | K22: ytd chg % | L22: =(M21-L21)/L21 -> 0.032198297
M24: days
A25: 2026 Closed Trades - Managed Acct | D25: Qty | E25: Cost/sh | F25: $ cost | G25: $Proc | H25: Proc/sh | I25: Profit/loss | J25: % | K25: Date purch | L25: Date sold | M25: held
E26: =F26/D26 -> #DIV/0! | H26: =G26/D26 -> #DIV/0! | I26: =G26-F26 -> 0 | J26: =I26/F26 -> #DIV/0! | M26: =DAYS360(K26,L26) -> 0
E27: =F27/D27 -> #DIV/0! | H27: =G27/D27 -> #DIV/0! | I27: =G27-F27 -> 0 | J27: =I27/F27 -> #DIV/0! | M27: =DAYS360(K27,L27) -> 0
E28: =F28/D28 -> #DIV/0! | H28: =G28/D28 -> #DIV/0! | I28: =G28-F28 -> 0 | J28: =I28/F28 -> #DIV/0! | M28: =DAYS360(K28,L28) -> 0
E29: =F29/D29 -> #DIV/0! | H29: =G29/D29 -> #DIV/0! | I29: =G29-F29 -> 0 | J29: =I29/F29 -> #DIV/0! | M29: =DAYS360(K29,L29) -> 0
E30: =F30/D30 -> #DIV/0! | H30: =G30/D30 -> #DIV/0! | I30: =G30-F30 -> 0 | J30: =I30/F30 -> #DIV/0! | M30: =DAYS360(K30,L30) -> 0
E31: =F31/D31 -> #DIV/0! | H31: =G31/D31 -> #DIV/0! | I31: =G31-F31 -> 0 | J31: =I31/F31 -> #DIV/0! | M31: =DAYS360(K31,L31) -> 0
E32: =F32/D32 -> #DIV/0! | H32: =G32/D32 -> #DIV/0! | I32: =G32-F32 -> 0 | J32: =I32/F32 -> #DIV/0! | M32: =DAYS360(K32,L32) -> 0
H36: Total gains | I36: =SUM(I26:I33) -> 0 | J36: Avg
H37: # of losses
H38: # of wins
I39: =SUM(I37:I38) -> 0
H40: W/L ratio | I40: =I38/I39 -> #DIV/0! | J40: =J38/J37*-1 -> #DIV/0!

Sheet 01-16-26
C1: 46038
C3: MANAGED ACCT | X3: Current | AC3: IBD
H4: Cost | J4: P/L | N4: Group | P4: EPS | R4: pivot | S4: last | W4: cost | X4: Stop | Y4: Stop | Z4: % | AB4: EPS | AC4: Comp
A5: Symbol | B5: Position | C5: Name | D5: Qty | E5: Current | F5: Value | G5: Cost | H5: per share | I5: P/L $ | J5: per sh | K5: Date purch | L5: days held | M5: % incr | N5: Rank | O5: RS | P5: RS | Q5: pivot | R5: -0.07 | S5: low | T5: 0.25 | U5: 0.5 | V5: 1 | W5: -0.07 | X5: Loss | Y5: Loss% | Z5: of port | AB5: Due | AC5: Rank
A7: GEV | B7: Long | C7: GE Vernova | D7: =97.1506+30.2251 -> 127.3757 | E7: 681.55 | F7: =E7*D7 -> 86812.908 | G7: =61467.93+20488.3849 -> 81956.315 | H7: =G7/D7 -> 643.4219 | I7: =F7-G7 -> 4856.5934 | J7: =E7-H7 -> 38.1281 | K7: 46000 | L7: =DAYS360(K7,$C$1) -> 37 | M7: =(I7/G7) -> 0.059258319 | N7: 72 | O7: 88 | P7: 40 | Q7: 664.69 | R7: =Q7*0.93 -> 618.1617 | S7: 555.84 | T7: =Q7*1.25 -> 830.8625 | U7: =Q7*1.5 -> 997.035 | V7: =Q7*2 -> 1329.38 | W7: =H7-(H7*0.07) -> 598.38237 | X7: 630 | Y7: =(X7-H7)/H7 -> -0.020860185 | Z7: =F7/F$20 -> 0.13873943 | AB7: 46050 | AC7: 74
A8: TSLA | B8: Long | C8: Tesla | D8: 129.2645 | E8: 437.56 | F8: =E8*D8 -> 56560.975 | G8: 61897.92 | H8: =G8/D8 -> 478.84702 | I8: =F8-G8 -> -5336.9454 | J8: =E8-H8 -> -41.287015 | K8: 46006 | L8: =DAYS360(K8,$C$1) -> 31 | M8: =(I8/G8) -> -0.086221724 | N8: 44 | O8: 83 | P8: 46 | Q8: 458.87 | R8: =Q8*0.93 -> 426.7491 | S8: 435.25 | T8: =Q8*1.25 -> 573.5875 | U8: =Q8*1.5 -> 688.305 | V8: =Q8*2 -> 917.74 | W8: =H8-(H8*0.07) -> 445.32772 | X8: 445 | Y8: =(X8-H8)/H8 -> -0.070684403 | Z8: =F8/F$20 -> 0.090392518 | AB8: 46050 | AC8: 66
A9: UFO | B9: Long | C9: Procure Space ETF | D9: =774.8271+421.3989 -> 1196.226 | E9: 47.36 | F9: =E9*D9 -> 56653.263 | G9: =30380.12+16944.65 -> 47324.77 | H9: =G9/D9 -> 39.56173 | I9: =F9-G9 -> 9328.4934 | J9: =E9-H9 -> 7.79827 | K9: 46021 | L9: =DAYS360(K9,$C$1) -> 16 | M9: =(I9/G9) -> 0.19711651 | N9: - | O9: 93 | P9: - | Q9: 40.68 | R9: =Q9*0.93 -> 37.8324 | S9: 35.32 | T9: =Q9*1.25 -> 50.85 | U9: =Q9*1.5 -> 61.02 | V9: =Q9*2 -> 81.36 | W9: =H9-(H9*0.07) -> 36.792409 | X9: 39 | Y9: =(X9-H9)/H9 -> -0.014198822 | Z9: =F9/F$20 -> 0.090540008 | AB9: - | AC9: -
A10: KRMN | B10: Long | C10: Karman Hldgs | D10: 451.9359 | E10: 108.5 | F10: =E10*D10 -> 49035.045 | G10: 36213.63 | H10: =G10/D10 -> 80.130014 | I10: =F10-G10 -> 12821.415 | J10: =E10-H10 -> 28.369986 | K10: 46027 | L10: =DAYS360(K10,$C$1) -> 11 | M10: =(I10/G10) -> 0.35404943 | N10: 28 | O10: 98 | P10: 80 | Q10: 81 | R10: =Q10*0.93 -> 75.33 | S10: 72 | T10: =Q10*1.25 -> 101.25 | U10: =Q10*1.5 -> 121.5 | V10: =Q10*2 -> 162 | W10: =H10-(H10*0.07) -> 74.520913 | X10: 85 | Y10: =(X10-H10)/H10 -> 0.060776053 | Z10: =F10/F$20 -> 0.078365007 | AB10: 46126 | AC10: 99
A11: RKT | B11: Long | C11: Rocket Cos | D11: =1733.9964+1138.3726 -> 2872.369 | E11: 23.24 | F11: =E11*D11 -> 66753.856 | G11: =36288.78+24176.77 -> 60465.55 | H11: =G11/D11 -> 21.05076 | I11: =F11-G11 -> 6288.3056 | J11: =E11-H11 -> 2.1892402 | K11: 46027 | L11: =DAYS360(K11,$C$1) -> 11 | M11: =(I11/G11) -> 0.10399815 | N11: 55 | O11: 94 | P11: 15 | Q11: 20.6 | R11: =Q11*0.93 -> 19.158 | S11: 17.76 | T11: =Q11*1.25 -> 25.75 | U11: =Q11*1.5 -> 30.9 | V11: =Q11*2 -> 41.2 | W11: =H11-(H11*0.07) -> 19.577207 | X11: 20.5 | Y11: =(X11-H11)/H11 -> -0.026163419 | Z11: =F11/F$20 -> 0.1066822 | AB11: 46072 | AC11: 81
A12: APH | B12: Long | C12: Amphenol | D12: 424.7267 | E12: 154.39 | F12: =E12*D12 -> 65573.555 | G12: 61848.7 | H12: =G12/D12 -> 145.62 | I12: =F12-G12 -> 3724.8552 | J12: =E12-H12 -> 8.7700048 | K12: 46034 | L12: =DAYS360(K12,$C$1) -> 4 | M12: =(I12/G12) -> 0.060225279 | N12: 11 | O12: 94 | P12: 99 | Q12: 143.3 | R12: =Q12*0.93 -> 133.269 | S12: 130.62 | T12: =Q12*1.25 -> 179.125 | U12: =Q12*1.5 -> 214.95 | V12: =Q12*2 -> 286.6 | W12: =H12-(H12*0.07) -> 135.4266 | X12: 135 | Y12: =(X12-H12)/H12 -> -0.072929512 | Z12: =F12/F$20 -> 0.10479591 | AB12: 46050 | AC12: 99
A13: SEI | B13: Long | C13: Solaris Energy | D13: =911.4227+399.4035 -> 1310.8262 | E13: 56.87 | F13: =E13*D13 -> 74546.686 | G13: =49515.3+22851.93 -> 72367.23 | H13: =G13/D13 -> 55.207342 | I13: =F13-G13 -> 2179.456 | J13: =E13-H13 -> 1.6626582 | K13: 46035 | L13: =DAYS360(K13,$C$1) -> 3 | M13: =(I13/G13) -> 0.030116615 | N13: 38 | O13: 94 | P13: 98 | Q13: 55.83 | R13: =Q13*0.93 -> 51.9219 | S13: 49.72 | T13: =Q13*1.25 -> 69.7875 | U13: =Q13*1.5 -> 83.745 | V13: =Q13*2 -> 111.66 | W13: =H13-(H13*0.07) -> 51.342828 | X13: 50 | Y13: =(X13-H13)/H13 -> -0.094323356 | Z13: =F13/F$20 -> 0.11913625 | AB13: 46077 | AC13: 99
F14: =E14*D14 -> 0 | H14: =G14/D14 -> #DIV/0! | I14: =F14-G14 -> 0 | J14: =E14-H14 -> #DIV/0! | L14: =DAYS360(K14,$C$1) -> 45376 | M14: =(I14/G14) -> #DIV/0! | R14: =Q14*0.93 -> 0 | T14: =Q14*1.25 -> 0 | U14: =Q14*1.5 -> 0 | V14: =Q14*2 -> 0 | W14: =H14-(H14*0.07) -> #DIV/0! | Y14: =(X14-H14)/H14 -> #DIV/0! | Z14: =F14/F$20 -> 0
F15: =E15*D15 -> 0 | H15: =G15/D15 -> #DIV/0! | I15: =F15-G15 -> 0 | J15: =E15-H15 -> #DIV/0! | L15: =DAYS360(K15,$C$1) -> 45376 | M15: =(I15/G15) -> #DIV/0! | R15: =Q15*0.93 -> 0 | T15: =Q15*1.25 -> 0 | U15: =Q15*1.5 -> 0 | V15: =Q15*2 -> 0 | W15: =H15-(H15*0.07) -> #DIV/0! | Y15: =(X15-H15)/H15 -> #DIV/0! | Z15: =F15/F$20 -> 0
F16: =E16*D16 -> 0 | H16: =G16/D16 -> #DIV/0! | I16: =F16-G16 -> 0 | J16: =E16-H16 -> #DIV/0! | L16: =DAYS360(K16,$C$1) -> 45376 | M16: =(I16/G16) -> #DIV/0! | R16: =Q16*0.93 -> 0 | T16: =Q16*1.25 -> 0 | U16: =Q16*1.5 -> 0 | V16: =Q16*2 -> 0 | W16: =H16-(H16*0.07) -> #DIV/0! | Y16: =(X16-H16)/H16 -> #DIV/0! | Z16: =F16/F$20 -> 0
F17: =E17*D17 -> 0 | H17: =G17/D17 -> #DIV/0! | I17: =F17-G17 -> 0 | J17: =E17-H17 -> #DIV/0! | L17: =DAYS360(K17,$C$1) -> 45376 | M17: =(I17/G17) -> #DIV/0! | R17: =Q17*0.93 -> 0 | T17: =Q17*1.25 -> 0 | U17: =Q17*1.5 -> 0 | V17: =Q17*2 -> 0 | W17: =H17-(H17*0.07) -> #DIV/0! | Y17: =(X17-H17)/H17 -> #DIV/0! | Z17: =F17/F$20 -> 0
A18: Sub-Total | F18: =SUM(F6:F17) -> 455936.29 | G18: =SUM(G6:G17) -> 422074.11 | I18: =SUM(I6:I17) -> 33862.173
D19: Cash, other | F19: 169790 | G19: =F19/F20 -> 0.27134868
D20: Total | F20: =SUM(F18:F19) -> 625726.29 | K20: Control acct (Doug's IRA) | M20: Today
H21: Last week's close | I21: ='01-09-26'!F20 -> 620191.77 | K21: 45657 | L21: 208334 | M21: 216906
H22: Week's change | I22: =(F20-I21)/I21 -> 0.0089238755 | K22: ytd chg % | L22: =(M21-L21)/L21 -> 0.041145468
M24: days
A25: 2026 Closed Trades - Managed Acct | D25: Qty | E25: Cost/sh | F25: $ cost | G25: $Proc | H25: Proc/sh | I25: Profit/loss | J25: % | K25: Date purch | L25: Date sold | M25: held
A26: URBN | B26: Long | C26: Urban Outfitters | D26: 747.3506 | E26: =F26/D26 -> 82.18365 | F26: 61420 | G26: 53510.285 | H26: =G26/D26 -> 71.599977 | I26: =G26-F26 -> -7909.7146 | J26: =I26/F26 -> -0.12878077 | K26: 46009 | L26: 46034 | M26: =DAYS360(K26,L26) -> 24
A27: APP | B27: Long | C27: Applovin | D27: 90.3434 | E27: =F27/D27 -> 678.26493 | F27: 61276.76 | G27: 54541.21 | H27: =G27/D27 -> 603.70996 | I27: =G27-F27 -> -6735.55 | J27: =I27/F27 -> -0.10992014 | K27: 45995 | L27: 46037 | M27: =DAYS360(K27,L27) -> 41
A28: AAPL | B28: Long | C28: Apple | D28: 288.5853 | E28: =F28/D28 -> 271.34092 | F28: 78305 | G28: 73933.25 | H28: =G28/D28 -> 256.19202 | I28: =G28-F28 -> -4371.75 | J28: =I28/F28 -> -0.055829768 | K28: 45971 | L28: 46038 | M28: =DAYS360(K28,L28) -> 66
E29: =F29/D29 -> #DIV/0! | H29: =G29/D29 -> #DIV/0! | I29: =G29-F29 -> 0 | J29: =I29/F29 -> #DIV/0! | M29: =DAYS360(K29,L29) -> 0
E30: =F30/D30 -> #DIV/0! | H30: =G30/D30 -> #DIV/0! | I30: =G30-F30 -> 0 | J30: =I30/F30 -> #DIV/0! | M30: =DAYS360(K30,L30) -> 0
E31: =F31/D31 -> #DIV/0! | H31: =G31/D31 -> #DIV/0! | I31: =G31-F31 -> 0 | J31: =I31/F31 -> #DIV/0! | M31: =DAYS360(K31,L31) -> 0
E32: =F32/D32 -> #DIV/0! | H32: =G32/D32 -> #DIV/0! | I32: =G32-F32 -> 0 | J32: =I32/F32 -> #DIV/0! | M32: =DAYS360(K32,L32) -> 0
H36: Total gains | I36: =SUM(I26:I33) -> -19017.015 | J36: Avg
H37: # of losses | I37: 3 | J37: -0.0982
H38: # of wins
I39: =SUM(I37:I38) -> 3
H40: W/L ratio | I40: =I38/I39 -> 0 | J40: =J38/J37*-1 -> 0

Sheet 01-23-26
C1: 46045
C3: MANAGED ACCT | X3: Current | AC3: IBD
H4: Cost | J4: P/L | N4: Group | P4: EPS | R4: pivot | S4: last | W4: cost | X4: Stop | Y4: Stop | Z4: % | AB4: EPS | AC4: Comp
A5: Symbol | B5: Position | C5: Name | D5: Qty | E5: Current | F5: Value | G5: Cost | H5: per share | I5: P/L $ | J5: per sh | K5: Date purch | L5: days held | M5: % incr | N5: Rank | O5: RS | P5: RS | Q5: pivot | R5: -0.07 | S5: low | T5: 0.25 | U5: 0.5 | V5: 1 | W5: -0.07 | X5: Loss | Y5: Loss% | Z5: of port | AB5: Due | AC5: Rank
A7: GEV | B7: Long | C7: GE Vernova | D7: =97.1506+30.2251 -> 127.3757 | E7: 657.78 | F7: =E7*D7 -> 83785.188 | G7: =61467.93+20488.3849 -> 81956.315 | H7: =G7/D7 -> 643.4219 | I7: =F7-G7 -> 1828.873 | J7: =E7-H7 -> 14.3581 | K7: 46000 | L7: =DAYS360(K7,$C$1) -> 44 | M7: =(I7/G7) -> 0.022315218 | N7: 71 | O7: 87 | P7: 40 | Q7: 664.69 | R7: =Q7*0.93 -> 618.1617 | S7: 555.84 | T7: =Q7*1.25 -> 830.8625 | U7: =Q7*1.5 -> 997.035 | V7: =Q7*2 -> 1329.38 | W7: =H7-(H7*0.07) -> 598.38237 | X7: 630 | Y7: =(X7-H7)/H7 -> -0.020860185 | Z7: =F7/F$20 -> 0.13677749 | AB7: 46050 | AC7: 82
A8: TSLA | B8: Long | C8: Tesla | D8: 129.2645 | E8: 449.06 | F8: =E8*D8 -> 58047.516 | G8: 61897.92 | H8: =G8/D8 -> 478.84702 | I8: =F8-G8 -> -3850.4036 | J8: =E8-H8 -> -29.787015 | K8: 46006 | L8: =DAYS360(K8,$C$1) -> 38 | M8: =(I8/G8) -> -0.062205703 | N8: 46 | O8: 83 | P8: 46 | Q8: 458.87 | R8: =Q8*0.93 -> 426.7491 | S8: 435.25 | T8: =Q8*1.25 -> 573.5875 | U8: =Q8*1.5 -> 688.305 | V8: =Q8*2 -> 917.74 | W8: =H8-(H8*0.07) -> 445.32772 | X8: 445 | Y8: =(X8-H8)/H8 -> -0.070684403 | Z8: =F8/F$20 -> 0.094761301 | AB8: 46050 | AC8: 69
A9: UFO | B9: Long | C9: Procure Space ETF | D9: =774.8271+421.3989 -> 1196.226 | E9: 46.95 | F9: =E9*D9 -> 56162.811 | G9: =30380.12+16944.65 -> 47324.77 | H9: =G9/D9 -> 39.56173 | I9: =F9-G9 -> 8838.0407 | J9: =E9-H9 -> 7.38827 | K9: 46021 | L9: =DAYS360(K9,$C$1) -> 23 | M9: =(I9/G9) -> 0.18675296 | N9: - | O9: 93 | P9: - | Q9: 40.68 | R9: =Q9*0.93 -> 37.8324 | S9: 35.32 | T9: =Q9*1.25 -> 50.85 | U9: =Q9*1.5 -> 61.02 | V9: =Q9*2 -> 81.36 | W9: =H9-(H9*0.07) -> 36.792409 | X9: 39 | Y9: =(X9-H9)/H9 -> -0.014198822 | Z9: =F9/F$20 -> 0.091684561 | AB9: - | AC9: -
A10: KRMN | B10: Long | C10: Karman Hldgs | D10: 451.9359 | E10: 108.22 | F10: =E10*D10 -> 48908.503 | G10: 36213.63 | H10: =G10/D10 -> 80.130014 | I10: =F10-G10 -> 12694.873 | J10: =E10-H10 -> 28.089986 | K10: 46027 | L10: =DAYS360(K10,$C$1) -> 18 | M10: =(I10/G10) -> 0.35055511 | N10: 14 | O10: 97 | P10: 80 | Q10: 81 | R10: =Q10*0.93 -> 75.33 | S10: 72 | T10: =Q10*1.25 -> 101.25 | U10: =Q10*1.5 -> 121.5 | V10: =Q10*2 -> 162 | W10: =H10-(H10*0.07) -> 74.520913 | X10: 95 | Y10: =(X10-H10)/H10 -> 0.18557324 | Z10: =F10/F$20 -> 0.079842062 | AB10: 46126 | AC10: 99
A11: RKT | B11: Long | C11: Rocket Cos | D11: =1733.9964+1138.3726 -> 2872.369 | E11: 21.07 | F11: =E11*D11 -> 60520.815 | G11: =36288.78+24176.77 -> 60465.55 | H11: =G11/D11 -> 21.05076 | I11: =F11-G11 -> 55.26483 | J11: =E11-H11 -> 0.019240157 | K11: 46027 | L11: =DAYS360(K11,$C$1) -> 18 | M11: =(I11/G11) -> 0.00091398871 | N11: 55 | O11: 91 | P11: 15 | Q11: 20.6 | R11: =Q11*0.93 -> 19.158 | S11: 17.76 | T11: =Q11*1.25 -> 25.75 | U11: =Q11*1.5 -> 30.9 | V11: =Q11*2 -> 41.2 | W11: =H11-(H11*0.07) -> 19.577207 | X11: 20.5 | Y11: =(X11-H11)/H11 -> -0.026163419 | Z11: =F11/F$20 -> 0.098798907 | AB11: 46072 | AC11: 74
A12: APH | B12: Long | C12: Amphenol | D12: 424.7267 | E12: 150.99 | F12: =E12*D12 -> 64129.484 | G12: 61848.7 | H12: =G12/D12 -> 145.62 | I12: =F12-G12 -> 2280.7844 | J12: =E12-H12 -> 5.3700048 | K12: 46034 | L12: =DAYS360(K12,$C$1) -> 11 | M12: =(I12/G12) -> 0.036876837 | N12: 15 | O12: 92 | P12: 99 | Q12: 143.3 | R12: =Q12*0.93 -> 133.269 | S12: 130.62 | T12: =Q12*1.25 -> 179.125 | U12: =Q12*1.5 -> 214.95 | V12: =Q12*2 -> 286.6 | W12: =H12-(H12*0.07) -> 135.4266 | X12: 135 | Y12: =(X12-H12)/H12 -> -0.072929512 | Z12: =F12/F$20 -> 0.10468998 | AB12: 46050 | AC12: 99
A13: SEI | B13: Long | C13: Solaris Energy | D13: =911.4227+399.4035 -> 1310.8262 | E13: 53.7 | F13: =E13*D13 -> 70391.367 | G13: =49515.3+22851.93 -> 72367.23 | H13: =G13/D13 -> 55.207342 | I13: =F13-G13 -> -1975.8631 | J13: =E13-H13 -> -1.5073418 | K13: 46035 | L13: =DAYS360(K13,$C$1) -> 10 | M13: =(I13/G13) -> -0.027303284 | N13: 30 | O13: 93 | P13: 98 | Q13: 55.83 | R13: =Q13*0.93 -> 51.9219 | S13: 49.72 | T13: =Q13*1.25 -> 69.7875 | U13: =Q13*1.5 -> 83.745 | V13: =Q13*2 -> 111.66 | W13: =H13-(H13*0.07) -> 51.342828 | X13: 50 | Y13: =(X13-H13)/H13 -> -0.094323356 | Z13: =F13/F$20 -> 0.11491237 | AB13: 46077 | AC13: 99
A14: APLD | B14: Long | C14: Applied Digital | D14: =842.9076+471.2592 -> 1314.1668 | E14: 37.69 | F14: =E14*D14 -> 49530.947 | G14: =30923.76+17760.7 -> 48684.46 | H14: =G14/D14 -> 37.045876 | I14: =F14-G14 -> 846.48669 | J14: =E14-H14 -> 0.64412424 | K14: 46043 | L14: =DAYS360(K14,$C$1) -> 2 | M14: =(I14/G14) -> 0.017387205 | N14: 63 | O14: 99 | P14: 33 | Q14: 39.51 | R14: =Q14*0.93 -> 36.7443 | S14: 33.62 | T14: =Q14*1.25 -> 49.3875 | U14: =Q14*1.5 -> 59.265 | V14: =Q14*2 -> 79.02 | W14: =H14-(H14*0.07) -> 34.452664 | X14: 34 | Y14: =(X14-H14)/H14 -> -0.082219024 | Z14: =F14/F$20 -> 0.080858188 | AB14: 46150 | AC14: 85
F15: =E15*D15 -> 0 | H15: =G15/D15 -> #DIV/0! | I15: =F15-G15 -> 0 | J15: =E15-H15 -> #DIV/0! | L15: =DAYS360(K15,$C$1) -> 45383 | M15: =(I15/G15) -> #DIV/0! | R15: =Q15*0.93 -> 0 | T15: =Q15*1.25 -> 0 | U15: =Q15*1.5 -> 0 | V15: =Q15*2 -> 0 | W15: =H15-(H15*0.07) -> #DIV/0! | Y15: =(X15-H15)/H15 -> #DIV/0! | Z15: =F15/F$20 -> 0
F16: =E16*D16 -> 0 | H16: =G16/D16 -> #DIV/0! | I16: =F16-G16 -> 0 | J16: =E16-H16 -> #DIV/0! | L16: =DAYS360(K16,$C$1) -> 45383 | M16: =(I16/G16) -> #DIV/0! | R16: =Q16*0.93 -> 0 | T16: =Q16*1.25 -> 0 | U16: =Q16*1.5 -> 0 | V16: =Q16*2 -> 0 | W16: =H16-(H16*0.07) -> #DIV/0! | Y16: =(X16-H16)/H16 -> #DIV/0! | Z16: =F16/F$20 -> 0
F17: =E17*D17 -> 0 | H17: =G17/D17 -> #DIV/0! | I17: =F17-G17 -> 0 | J17: =E17-H17 -> #DIV/0! | L17: =DAYS360(K17,$C$1) -> 45383 | M17: =(I17/G17) -> #DIV/0! | R17: =Q17*0.93 -> 0 | T17: =Q17*1.25 -> 0 | U17: =Q17*1.5 -> 0 | V17: =Q17*2 -> 0 | W17: =H17-(H17*0.07) -> #DIV/0! | Y17: =(X17-H17)/H17 -> #DIV/0! | Z17: =F17/F$20 -> 0
A18: Sub-Total | F18: =SUM(F6:F17) -> 491476.63 | G18: =SUM(G6:G17) -> 470758.57 | I18: =SUM(I6:I17) -> 20718.056
D19: Cash, other | F19: 121089 | G19: =F19/F20 -> 0.19767515
D20: Total | F20: =SUM(F18:F19) -> 612565.63 | K20: Control acct (Doug's IRA) | M20: Today
H21: Last week's close | I21: ='01-16-26'!F20 -> 625726.29 | K21: 45657 | L21: 208334 | M21: 211511
H22: Week's change | I22: =(F20-I21)/I21 -> -0.02103261 | K22: ytd chg % | L22: =(M21-L21)/L21 -> 0.015249551
M24: days
A25: 2026 Closed Trades - Managed Acct | D25: Qty | E25: Cost/sh | F25: $ cost | G25: $Proc | H25: Proc/sh | I25: Profit/loss | J25: % | K25: Date purch | L25: Date sold | M25: held
A26: URBN | B26: Long | C26: Urban Outfitters | D26: 747.3506 | E26: =F26/D26 -> 82.18365 | F26: 61420 | G26: 53510.285 | H26: =G26/D26 -> 71.599977 | I26: =G26-F26 -> -7909.7146 | J26: =I26/F26 -> -0.12878077 | K26: 46009 | L26: 46034 | M26: =DAYS360(K26,L26) -> 24
A27: APP | B27: Long | C27: Applovin | D27: 90.3434 | E27: =F27/D27 -> 678.26493 | F27: 61276.76 | G27: 54541.21 | H27: =G27/D27 -> 603.70996 | I27: =G27-F27 -> -6735.55 | J27: =I27/F27 -> -0.10992014 | K27: 45995 | L27: 46037 | M27: =DAYS360(K27,L27) -> 41
A28: AAPL | B28: Long | C28: Apple | D28: 288.5853 | E28: =F28/D28 -> 271.34092 | F28: 78305 | G28: 73933.25 | H28: =G28/D28 -> 256.19202 | I28: =G28-F28 -> -4371.75 | J28: =I28/F28 -> -0.055829768 | K28: 45971 | L28: 46038 | M28: =DAYS360(K28,L28) -> 66
E29: =F29/D29 -> #DIV/0! | H29: =G29/D29 -> #DIV/0! | I29: =G29-F29 -> 0 | J29: =I29/F29 -> #DIV/0! | M29: =DAYS360(K29,L29) -> 0
E30: =F30/D30 -> #DIV/0! | H30: =G30/D30 -> #DIV/0! | I30: =G30-F30 -> 0 | J30: =I30/F30 -> #DIV/0! | M30: =DAYS360(K30,L30) -> 0
E31: =F31/D31 -> #DIV/0! | H31: =G31/D31 -> #DIV/0! | I31: =G31-F31 -> 0 | J31: =I31/F31 -> #DIV/0! | M31: =DAYS360(K31,L31) -> 0
E32: =F32/D32 -> #DIV/0! | H32: =G32/D32 -> #DIV/0! | I32: =G32-F32 -> 0 | J32: =I32/F32 -> #DIV/0! | M32: =DAYS360(K32,L32) -> 0
H36: Total gains | I36: =SUM(I26:I33) -> -19017.015 | J36: Avg
H37: # of losses | I37: 3 | J37: -0.0982
H38: # of wins
I39: =SUM(I37:I38) -> 3
H40: W/L ratio | I40: =I38/I39 -> 0 | J40: =J38/J37*-1 -> 0

Sheet 01-30-26
C1: 46052
C3: MANAGED ACCT | X3: Current | AC3: IBD
H4: Cost | J4: P/L | N4: Group | P4: EPS | R4: pivot | S4: last | W4: cost | X4: Stop | Y4: Stop | Z4: % | AB4: EPS | AC4: Comp
A5: Symbol | B5: Position | C5: Name | D5: Qty | E5: Current | F5: Value | G5: Cost | H5: per share | I5: P/L $ | J5: per sh | K5: Date purch | L5: days held | M5: % incr | N5: Rank | O5: RS | P5: RS | Q5: pivot | R5: -0.07 | S5: low | T5: 0.25 | U5: 0.5 | V5: 1 | W5: -0.07 | X5: Loss | Y5: Loss% | Z5: of port | AB5: Due | AC5: Rank
A7: GEV | B7: Long | C7: GE Vernova | D7: =97.1506+30.2251 -> 127.3757 | E7: 726.37 | F7: =E7*D7 -> 92521.887 | G7: =61467.93+20488.3849 -> 81956.315 | H7: =G7/D7 -> 643.4219 | I7: =F7-G7 -> 10565.572 | J7: =E7-H7 -> 82.9481 | K7: 46000 | L7: =DAYS360(K7,$C$1) -> 51 | M7: =(I7/G7) -> 0.12891712 | N7: 50 | O7: 92 | P7: 78 | Q7: 664.69 | R7: =Q7*0.93 -> 618.1617 | S7: 555.84 | T7: =Q7*1.25 -> 830.8625 | U7: =Q7*1.5 -> 997.035 | V7: =Q7*2 -> 1329.38 | W7: =H7-(H7*0.07) -> 598.38237 | X7: 630 | Y7: =(X7-H7)/H7 -> -0.020860185 | Z7: =F7/F$20 -> 0.15537916 | AB7: 46134 | AC7: 93
A8: UFO | B8: Long | C8: Procure Space ETF | D8: =774.8271+421.3989 -> 1196.226 | E8: 45.44 | F8: =E8*D8 -> 54356.509 | G8: =30380.12+16944.65 -> 47324.77 | H8: =G8/D8 -> 39.56173 | I8: =F8-G8 -> 7031.7394 | J8: =E8-H8 -> 5.87827 | K8: 46021 | L8: =DAYS360(K8,$C$1) -> 30 | M8: =(I8/G8) -> 0.14858476 | N8: - | O8: 93 | P8: - | Q8: 40.68 | R8: =Q8*0.93 -> 37.8324 | S8: 35.32 | T8: =Q8*1.25 -> 50.85 | U8: =Q8*1.5 -> 61.02 | V8: =Q8*2 -> 81.36 | W8: =H8-(H8*0.07) -> 36.792409 | X8: 39 | Y8: =(X8-H8)/H8 -> -0.014198822 | Z8: =F8/F$20 -> 0.09128509 | AB8: - | AC8: -
A9: KRMN | B9: Long | C9: Karman Hldgs | D9: 451.9359 | E9: 103.8 | F9: =E9*D9 -> 46910.946 | G9: 36213.63 | H9: =G9/D9 -> 80.130014 | I9: =F9-G9 -> 10697.316 | J9: =E9-H9 -> 23.669986 | K9: 46027 | L9: =DAYS360(K9,$C$1) -> 25 | M9: =(I9/G9) -> 0.29539476 | N9: 18 | O9: 97 | P9: 80 | Q9: 81 | R9: =Q9*0.93 -> 75.33 | S9: 72 | T9: =Q9*1.25 -> 101.25 | U9: =Q9*1.5 -> 121.5 | V9: =Q9*2 -> 162 | W9: =H9-(H9*0.07) -> 74.520913 | X9: 95 | Y9: =(X9-H9)/H9 -> 0.18557324 | Z9: =F9/F$20 -> 0.07878118 | AB9: 46126 | AC9: 99
A10: RKT | B10: Long | C10: Rocket Cos | D10: =1733.9964+1138.3726 -> 2872.369 | E10: 17.93 | F10: =E10*D10 -> 51501.576 | G10: =36288.78+24176.77 -> 60465.55 | H10: =G10/D10 -> 21.05076 | I10: =F10-G10 -> -8963.9738 | J10: =E10-H10 -> -3.1207598 | K10: 46027 | L10: =DAYS360(K10,$C$1) -> 25 | M10: =(I10/G10) -> -0.14824927 | N10: 128 | O10: 83 | P10: 15 | Q10: 20.6 | R10: =Q10*0.93 -> 19.158 | S10: 17.76 | T10: =Q10*1.25 -> 25.75 | U10: =Q10*1.5 -> 30.9 | V10: =Q10*2 -> 41.2 | W10: =H10-(H10*0.07) -> 19.577207 | X10: 20.5 | Y10: =(X10-H10)/H10 -> -0.026163419 | Z10: =F10/F$20 -> 0.08649058 | AB10: 46072 | AC10: 58
A11: APH | B11: Long | C11: Amphenol | D11: 424.7267 | E11: 144.08 | F11: =E11*D11 -> 61194.623 | G11: 61848.7 | H11: =G11/D11 -> 145.62 | I11: =F11-G11 -> -654.07706 | J11: =E11-H11 -> -1.5399952 | K11: 46034 | L11: =DAYS360(K11,$C$1) -> 18 | M11: =(I11/G11) -> -0.010575438 | N11: 12 | O11: 91 | P11: 99 | Q11: 143.3 | R11: =Q11*0.93 -> 133.269 | S11: 130.62 | T11: =Q11*1.25 -> 179.125 | U11: =Q11*1.5 -> 214.95 | V11: =Q11*2 -> 286.6 | W11: =H11-(H11*0.07) -> 135.4266 | X11: 135 | Y11: =(X11-H11)/H11 -> -0.072929512 | Z11: =F11/F$20 -> 0.10276886 | AB11: 46141 | AC11: 99
A12: SEI | B12: Long | C12: Solaris Energy | D12: =911.4227+399.4035 -> 1310.8262 | E12: 55.19 | F12: =E12*D12 -> 72344.498 | G12: =49515.3+22851.93 -> 72367.23 | H12: =G12/D12 -> 55.207342 | I12: =F12-G12 -> -22.732022 | J12: =E12-H12 -> -0.017341751 | K12: 46035 | L12: =DAYS360(K12,$C$1) -> 17 | M12: =(I12/G12) -> -0.00031412038 | N12: 17 | O12: 94 | P12: 98 | Q12: 55.83 | R12: =Q12*0.93 -> 51.9219 | S12: 49.72 | T12: =Q12*1.25 -> 69.7875 | U12: =Q12*1.5 -> 83.745 | V12: =Q12*2 -> 111.66 | W12: =H12-(H12*0.07) -> 51.342828 | X12: 50 | Y12: =(X12-H12)/H12 -> -0.094323356 | Z12: =F12/F$20 -> 0.12149371 | AB12: 46077 | AC12: 99
A13: APLD | B13: Long | C13: Applied Digital | D13: =842.9076+471.2592+487.9805 -> 1802.1473 | E13: 33.88 | F13: =E13*D13 -> 61056.751 | G13: =30923.76+17760.7+20459.97 -> 69144.43 | H13: =G13/D13 -> 38.367802 | I13: =F13-G13 -> -8087.6795 | J13: =E13-H13 -> -4.4878016 | K13: 46043 | L13: =DAYS360(K13,$C$1) -> 9 | M13: =(I13/G13) -> -0.11696791 | N13: 65 | O13: 99 | P13: 33 | Q13: 39.51 | R13: =Q13*0.93 -> 36.7443 | S13: 33.62 | T13: =Q13*1.25 -> 49.3875 | U13: =Q13*1.5 -> 59.265 | V13: =Q13*2 -> 79.02 | W13: =H13-(H13*0.07) -> 35.682055 | X13: 34 | Y13: =(X13-H13)/H13 -> -0.11384029 | Z13: =F13/F$20 -> 0.10253732 | AB13: 46150 | AC13: 83
F14: =E14*D14 -> 0 | H14: =G14/D14 -> #DIV/0! | I14: =F14-G14 -> 0 | J14: =E14-H14 -> #DIV/0! | L14: =DAYS360(K14,$C$1) -> 45390 | M14: =(I14/G14) -> #DIV/0! | R14: =Q14*0.93 -> 0 | T14: =Q14*1.25 -> 0 | U14: =Q14*1.5 -> 0 | V14: =Q14*2 -> 0 | W14: =H14-(H14*0.07) -> #DIV/0! | Y14: =(X14-H14)/H14 -> #DIV/0! | Z14: =F14/F$20 -> 0
F15: =E15*D15 -> 0 | H15: =G15/D15 -> #DIV/0! | I15: =F15-G15 -> 0 | J15: =E15-H15 -> #DIV/0! | L15: =DAYS360(K15,$C$1) -> 45390 | M15: =(I15/G15) -> #DIV/0! | R15: =Q15*0.93 -> 0 | T15: =Q15*1.25 -> 0 | U15: =Q15*1.5 -> 0 | V15: =Q15*2 -> 0 | W15: =H15-(H15*0.07) -> #DIV/0! | Y15: =(X15-H15)/H15 -> #DIV/0! | Z15: =F15/F$20 -> 0
F16: =E16*D16 -> 0 | H16: =G16/D16 -> #DIV/0! | I16: =F16-G16 -> 0 | J16: =E16-H16 -> #DIV/0! | L16: =DAYS360(K16,$C$1) -> 45390 | M16: =(I16/G16) -> #DIV/0! | R16: =Q16*0.93 -> 0 | T16: =Q16*1.25 -> 0 | U16: =Q16*1.5 -> 0 | V16: =Q16*2 -> 0 | W16: =H16-(H16*0.07) -> #DIV/0! | Y16: =(X16-H16)/H16 -> #DIV/0! | Z16: =F16/F$20 -> 0
F17: =E17*D17 -> 0 | H17: =G17/D17 -> #DIV/0! | I17: =F17-G17 -> 0 | J17: =E17-H17 -> #DIV/0! | L17: =DAYS360(K17,$C$1) -> 45390 | M17: =(I17/G17) -> #DIV/0! | R17: =Q17*0.93 -> 0 | T17: =Q17*1.25 -> 0 | U17: =Q17*1.5 -> 0 | V17: =Q17*2 -> 0 | W17: =H17-(H17*0.07) -> #DIV/0! | Y17: =(X17-H17)/H17 -> #DIV/0! | Z17: =F17/F$20 -> 0
A18: Sub-Total | F18: =SUM(F6:F17) -> 439886.79 | G18: =SUM(G6:G17) -> 429320.62 | I18: =SUM(I6:I17) -> 10566.166
D19: Cash, other | F19: 155572 | G19: =F19/F20 -> 0.26126409
D20: Total | F20: =SUM(F18:F19) -> 595458.79 | K20: Control acct (Doug's IRA) | M20: Today
H21: Last week's close | I21: ='01-23-26'!F20 -> 612565.63 | K21: 45657 | L21: 208334 | M21: 206121
H22: Week's change | I22: =(F20-I21)/I21 -> -0.027926543 | K22: ytd chg % | L22: =(M21-L21)/L21 -> -0.010622366
M24: days
A25: 2026 Closed Trades - Managed Acct | D25: Qty | E25: Cost/sh | F25: $ cost | G25: $Proc | H25: Proc/sh | I25: Profit/loss | J25: % | K25: Date purch | L25: Date sold | M25: held
A26: URBN | B26: Long | C26: Urban Outfitters | D26: 747.3506 | E26: =F26/D26 -> 82.18365 | F26: 61420 | G26: 53510.285 | H26: =G26/D26 -> 71.599977 | I26: =G26-F26 -> -7909.7146 | J26: =I26/F26 -> -0.12878077 | K26: 46009 | L26: 46034 | M26: =DAYS360(K26,L26) -> 24
A27: APP | B27: Long | C27: Applovin | D27: 90.3434 | E27: =F27/D27 -> 678.26493 | F27: 61276.76 | G27: 54541.21 | H27: =G27/D27 -> 603.70996 | I27: =G27-F27 -> -6735.55 | J27: =I27/F27 -> -0.10992014 | K27: 45995 | L27: 46037 | M27: =DAYS360(K27,L27) -> 41
A28: AAPL | B28: Long | C28: Apple | D28: 288.5853 | E28: =F28/D28 -> 271.34092 | F28: 78305 | G28: 73933.25 | H28: =G28/D28 -> 256.19202 | I28: =G28-F28 -> -4371.75 | J28: =I28/F28 -> -0.055829768 | K28: 45971 | L28: 46038 | M28: =DAYS360(K28,L28) -> 66
A29: TSLA | B29: Long | C29: Tesla | D29: 129.2645 | E29: =F29/D29 -> 478.84702 | F29: 61897.92 | G29: 54753.85 | H29: =G29/D29 -> 423.57995 | I29: =G29-F29 -> -7144.07 | J29: =I29/F29 -> -0.11541696 | K29: 46006 | L29: 46051 | M29: =DAYS360(K29,L29) -> 44
E30: =F30/D30 -> #DIV/0! | H30: =G30/D30 -> #DIV/0! | I30: =G30-F30 -> 0 | J30: =I30/F30 -> #DIV/0! | M30: =DAYS360(K30,L30) -> 0
E31: =F31/D31 -> #DIV/0! | H31: =G31/D31 -> #DIV/0! | I31: =G31-F31 -> 0 | J31: =I31/F31 -> #DIV/0! | M31: =DAYS360(K31,L31) -> 0
E32: =F32/D32 -> #DIV/0! | H32: =G32/D32 -> #DIV/0! | I32: =G32-F32 -> 0 | J32: =I32/F32 -> #DIV/0! | M32: =DAYS360(K32,L32) -> 0
H36: Total gains | I36: =SUM(I26:I33) -> -26161.085 | J36: Avg
H37: # of losses | I37: 4 | J37: -0.1025
H38: # of wins
I39: =SUM(I37:I38) -> 4
H40: W/L ratio | I40: =I38/I39 -> 0 | J40: =J38/J37*-1 -> 0

Sheet 02-06-26
C1: 46059
C3: MANAGED ACCT | X3: Current | AC3: IBD
H4: Cost | J4: P/L | N4: Group | P4: EPS | R4: pivot | S4: last | W4: cost | X4: Stop | Y4: Stop | Z4: % | AB4: EPS | AC4: Comp
A5: Symbol | B5: Position | C5: Name | D5: Qty | E5: Current | F5: Value | G5: Cost | H5: per share | I5: P/L $ | J5: per sh | K5: Date purch | L5: days held | M5: % incr | N5: Rank | O5: RS | P5: RS | Q5: pivot | R5: -0.07 | S5: low | T5: 0.25 | U5: 0.5 | V5: 1 | W5: -0.07 | X5: Loss | Y5: Loss% | Z5: of port | AB5: Due | AC5: Rank
A7: GEV | B7: Long | C7: GE Vernova | D7: =97.1506+30.2251 -> 127.3757 | E7: 778.27 | F7: =E7*D7 -> 99132.686 | G7: =61467.93+20488.3849 -> 81956.315 | H7: =G7/D7 -> 643.4219 | I7: =F7-G7 -> 17176.371 | J7: =E7-H7 -> 134.8481 | K7: 46000 | L7: =DAYS360(K7,$C$1) -> 57 | M7: =(I7/G7) -> 0.20957959 | N7: 74 | O7: 93 | P7: 78 | Q7: 664.69 | R7: =Q7*0.93 -> 618.1617 | S7: 555.84 | T7: =Q7*1.25 -> 830.8625 | U7: =Q7*1.5 -> 997.035 | V7: =Q7*2 -> 1329.38 | W7: =H7-(H7*0.07) -> 598.38237 | X7: 695 | Y7: =(X7-H7)/H7 -> 0.080162177 | Z7: =F7/F$20 -> 0.16660905 | AB7: 46134 | AC7: 91
A8: UFO | B8: Long | C8: Procure Space ETF | D8: =774.8271+421.3989 -> 1196.226 | E8: 43.97 | F8: =E8*D8 -> 52598.057 | G8: =30380.12+16944.65 -> 47324.77 | H8: =G8/D8 -> 39.56173 | I8: =F8-G8 -> 5273.2872 | J8: =E8-H8 -> 4.40827 | K8: 46021 | L8: =DAYS360(K8,$C$1) -> 36 | M8: =(I8/G8) -> 0.11142764 | N8: - | O8: 93 | P8: - | Q8: 40.68 | R8: =Q8*0.93 -> 37.8324 | S8: 35.32 | T8: =Q8*1.25 -> 50.85 | U8: =Q8*1.5 -> 61.02 | V8: =Q8*2 -> 81.36 | W8: =H8-(H8*0.07) -> 36.792409 | X8: 39 | Y8: =(X8-H8)/H8 -> -0.014198822 | Z8: =F8/F$20 -> 0.08839983 | AB8: - | AC8: -
A9: APLD | B9: Long | C9: Applied Digital | D9: =842.9076+471.2592+487.9805 -> 1802.1473 | E9: 34.95 | F9: =E9*D9 -> 62985.048 | G9: =30923.76+17760.7+20459.97 -> 69144.43 | H9: =G9/D9 -> 38.367802 | I9: =F9-G9 -> -6159.3819 | J9: =E9-H9 -> -3.4178016 | K9: 46043 | L9: =DAYS360(K9,$C$1) -> 15 | M9: =(I9/G9) -> -0.089079943 | N9: 129 | O9: 98 | P9: 33 | Q9: 39.51 | R9: =Q9*0.93 -> 36.7443 | S9: 33.62 | T9: =Q9*1.25 -> 49.3875 | U9: =Q9*1.5 -> 59.265 | V9: =Q9*2 -> 79.02 | W9: =H9-(H9*0.07) -> 35.682055 | X9: 34 | Y9: =(X9-H9)/H9 -> -0.11384029 | Z9: =F9/F$20 -> 0.10585691 | AB9: 46150 | AC9: 71
F10: =E10*D10 -> 0 | H10: =G10/D10 -> #DIV/0! | I10: =F10-G10 -> 0 | J10: =E10-H10 -> #DIV/0! | M10: =(I10/G10) -> #DIV/0! | R10: =Q10*0.93 -> 0 | T10: =Q10*1.25 -> 0 | U10: =Q10*1.5 -> 0 | V10: =Q10*2 -> 0 | W10: =H10-(H10*0.07) -> #DIV/0! | Y10: =(X10-H10)/H10 -> #DIV/0! | Z10: =F10/F$20 -> 0
F11: =E11*D11 -> 0 | H11: =G11/D11 -> #DIV/0! | I11: =F11-G11 -> 0 | J11: =E11-H11 -> #DIV/0! | M11: =(I11/G11) -> #DIV/0! | R11: =Q11*0.93 -> 0 | T11: =Q11*1.25 -> 0 | U11: =Q11*1.5 -> 0 | V11: =Q11*2 -> 0 | W11: =H11-(H11*0.07) -> #DIV/0! | Y11: =(X11-H11)/H11 -> #DIV/0! | Z11: =F11/F$20 -> 0
F12: =E12*D12 -> 0 | H12: =G12/D12 -> #DIV/0! | I12: =F12-G12 -> 0 | J12: =E12-H12 -> #DIV/0! | M12: =(I12/G12) -> #DIV/0! | R12: =Q12*0.93 -> 0 | T12: =Q12*1.25 -> 0 | U12: =Q12*1.5 -> 0 | V12: =Q12*2 -> 0 | W12: =H12-(H12*0.07) -> #DIV/0! | Y12: =(X12-H12)/H12 -> #DIV/0! | Z12: =F12/F$20 -> 0
F13: =E13*D13 -> 0 | H13: =G13/D13 -> #DIV/0! | I13: =F13-G13 -> 0 | J13: =E13-H13 -> #DIV/0! | M13: =(I13/G13) -> #DIV/0! | R13: =Q13*0.93 -> 0 | T13: =Q13*1.25 -> 0 | U13: =Q13*1.5 -> 0 | V13: =Q13*2 -> 0 | W13: =H13-(H13*0.07) -> #DIV/0! | Y13: =(X13-H13)/H13 -> #DIV/0! | Z13: =F13/F$20 -> 0
F14: =E14*D14 -> 0 | H14: =G14/D14 -> #DIV/0! | I14: =F14-G14 -> 0 | J14: =E14-H14 -> #DIV/0! | L14: =DAYS360(K14,$C$1) -> 45396 | M14: =(I14/G14) -> #DIV/0! | R14: =Q14*0.93 -> 0 | T14: =Q14*1.25 -> 0 | U14: =Q14*1.5 -> 0 | V14: =Q14*2 -> 0 | W14: =H14-(H14*0.07) -> #DIV/0! | Y14: =(X14-H14)/H14 -> #DIV/0! | Z14: =F14/F$20 -> 0
F15: =E15*D15 -> 0 | H15: =G15/D15 -> #DIV/0! | I15: =F15-G15 -> 0 | J15: =E15-H15 -> #DIV/0! | L15: =DAYS360(K15,$C$1) -> 45396 | M15: =(I15/G15) -> #DIV/0! | R15: =Q15*0.93 -> 0 | T15: =Q15*1.25 -> 0 | U15: =Q15*1.5 -> 0 | V15: =Q15*2 -> 0 | W15: =H15-(H15*0.07) -> #DIV/0! | Y15: =(X15-H15)/H15 -> #DIV/0! | Z15: =F15/F$20 -> 0
F16: =E16*D16 -> 0 | H16: =G16/D16 -> #DIV/0! | I16: =F16-G16 -> 0 | J16: =E16-H16 -> #DIV/0! | L16: =DAYS360(K16,$C$1) -> 45396 | M16: =(I16/G16) -> #DIV/0! | R16: =Q16*0.93 -> 0 | T16: =Q16*1.25 -> 0 | U16: =Q16*1.5 -> 0 | V16: =Q16*2 -> 0 | W16: =H16-(H16*0.07) -> #DIV/0! | Y16: =(X16-H16)/H16 -> #DIV/0! | Z16: =F16/F$20 -> 0
F17: =E17*D17 -> 0 | H17: =G17/D17 -> #DIV/0! | I17: =F17-G17 -> 0 | J17: =E17-H17 -> #DIV/0! | L17: =DAYS360(K17,$C$1) -> 45396 | M17: =(I17/G17) -> #DIV/0! | R17: =Q17*0.93 -> 0 | T17: =Q17*1.25 -> 0 | U17: =Q17*1.5 -> 0 | V17: =Q17*2 -> 0 | W17: =H17-(H17*0.07) -> #DIV/0! | Y17: =(X17-H17)/H17 -> #DIV/0! | Z17: =F17/F$20 -> 0
A18: Sub-Total | F18: =SUM(F6:F17) -> 214715.79 | G18: =SUM(G6:G17) -> 198425.51 | I18: =SUM(I6:I17) -> 16290.276
D19: Cash, other | F19: 380286 | G19: =F19/F20 -> 0.63913421
D20: Total | F20: =SUM(F18:F19) -> 595001.79 | K20: Control acct (Doug's IRA) | M20: Today
H21: Last week's close | I21: ='01-30-26'!F20 -> 595458.79 | K21: 45657 | L21: 208334 | M21: 205572
H22: Week's change | I22: =(F20-I21)/I21 -> -0.00076747424 | K22: ytd chg % | L22: =(M21-L21)/L21 -> -0.013257558
M24: days
A25: 2026 Closed Trades - Managed Acct | D25: Qty | E25: Cost/sh | F25: $ cost | G25: $Proc | H25: Proc/sh | I25: Profit/loss | J25: % | K25: Date purch | L25: Date sold | M25: held
A26: URBN | B26: Long | C26: Urban Outfitters | D26: 747.3506 | E26: =F26/D26 -> 82.18365 | F26: 61420 | G26: 53510.285 | H26: =G26/D26 -> 71.599977 | I26: =G26-F26 -> -7909.7146 | J26: =I26/F26 -> -0.12878077 | K26: 46009 | L26: 46034 | M26: =DAYS360(K26,L26) -> 24
A27: APP | B27: Long | C27: Applovin | D27: 90.3434 | E27: =F27/D27 -> 678.26493 | F27: 61276.76 | G27: 54541.21 | H27: =G27/D27 -> 603.70996 | I27: =G27-F27 -> -6735.55 | J27: =I27/F27 -> -0.10992014 | K27: 45995 | L27: 46037 | M27: =DAYS360(K27,L27) -> 41
A28: AAPL | B28: Long | C28: Apple | D28: 288.5853 | E28: =F28/D28 -> 271.34092 | F28: 78305 | G28: 73933.25 | H28: =G28/D28 -> 256.19202 | I28: =G28-F28 -> -4371.75 | J28: =I28/F28 -> -0.055829768 | K28: 45971 | L28: 46038 | M28: =DAYS360(K28,L28) -> 66
A29: TSLA | B29: Long | C29: Tesla | D29: 129.2645 | E29: =F29/D29 -> 478.84702 | F29: 61897.92 | G29: 54753.85 | H29: =G29/D29 -> 423.57995 | I29: =G29-F29 -> -7144.07 | J29: =I29/F29 -> -0.11541696 | K29: 46006 | L29: 46051 | M29: =DAYS360(K29,L29) -> 44
A30: APH | B30: Long | C30: Amphenol | D30: 424.7267 | E30: =F30/D30 -> 145.62 | F30: 61848.7 | G30: 58111.071 | H30: =G30/D30 -> 136.81991 | I30: =G30-F30 -> -3737.6292 | J30: =I30/F30 -> -0.060431815 | K30: 46034 | L30: 46057 | M30: =DAYS360(K30,L30) -> 22
A31: SEI | B31: Long | C31: Solaris Energy | D31: =911.4227+399.4035 -> 1310.8262 | E31: =F31/D31 -> 55.207342 | F31: 72367.23 | G31: 67265.89 | H31: =G31/D31 -> 51.315644 | I31: =G31-F31 -> -5101.34 | J31: =I31/F31 -> -0.070492404 | K31: 46035 | L31: 46057 | M31: =DAYS360(K31,L31) -> 21
A32: KRMN | B32: Long | C32: Karman Hldgs | D32: 451.9359 | E32: =F32/D32 -> 80.130014 | F32: 36213.63 | G32: 43431.477 | H32: =G32/D32 -> 96.100967 | I32: =G32-F32 -> 7217.847 | J32: =I32/F32 -> 0.19931299 | K32: 46027 | L32: 46057 | M32: =DAYS360(K32,L32) -> 29
A33: RKT | B33: Long | C33: Rocket Cos | D33: =1733.9964+1138.3726 -> 2872.369 | E33: =F33/D33 -> 21.05076 | F33: 60465.55 | G33: 55822.99 | H33: =G33/D33 -> 19.434477 | I33: =G33-F33 -> -4642.5604 | J33: =I33/F33 -> -0.076780256 | K33: 46027 | L33: 46057 | M33: =DAYS360(K33,L33) -> 29
H36: Total gains | I36: =SUM(I26:I33) -> -32424.767 | J36: Avg
H37: # of losses | I37: 7 | J37: -0.0882
H38: # of wins | I38: 1 | J38: 0.1993
I39: =SUM(I37:I38) -> 8
H40: W/L ratio | I40: =I38/I39 -> 0.125 | J40: =J38/J37*-1 -> 2.2596372

Sheet 02-13-26
C1: 46066
C3: MANAGED ACCT | X3: Current | AC3: IBD
H4: Cost | J4: P/L | N4: Group | P4: EPS | R4: pivot | S4: last | W4: cost | X4: Stop | Y4: Stop | Z4: % | AB4: EPS | AC4: Comp
A5: Symbol | B5: Position | C5: Name | D5: Qty | E5: Current | F5: Value | G5: Cost | H5: per share | I5: P/L $ | J5: per sh | K5: Date purch | L5: days held | M5: % incr | N5: Rank | O5: RS | P5: RS | Q5: pivot | R5: -0.07 | S5: low | T5: 0.25 | U5: 0.5 | V5: 1 | W5: -0.07 | X5: Loss | Y5: Loss% | Z5: of port | AB5: Due | AC5: Rank
A7: GEV | B7: Long | C7: GE Vernova | D7: =97.1506+30.2251 -> 127.3757 | E7: 802.13 | F7: =E7*D7 -> 102171.87 | G7: =61467.93+20488.3849 -> 81956.315 | H7: =G7/D7 -> 643.4219 | I7: =F7-G7 -> 20215.555 | J7: =E7-H7 -> 158.7081 | K7: 46000 | L7: =DAYS360(K7,$C$1) -> 64 | M7: =(I7/G7) -> 0.24666257 | N7: 44 | O7: 95 | P7: 78 | Q7: 664.69 | R7: =Q7*0.93 -> 618.1617 | S7: 555.84 | T7: =Q7*1.25 -> 830.8625 | U7: =Q7*1.5 -> 997.035 | V7: =Q7*2 -> 1329.38 | W7: =H7-(H7*0.07) -> 598.38237 | X7: 695 | Y7: =(X7-H7)/H7 -> 0.080162177 | Z7: =F7/F$20 -> 0.17068917 | AB7: 46134 | AC7: 94
A8: UFO | B8: Long | C8: Procure Space ETF | D8: =774.8271+421.3989 -> 1196.226 | E8: 43.54 | F8: =E8*D8 -> 52083.68 | G8: =30380.12+16944.65 -> 47324.77 | H8: =G8/D8 -> 39.56173 | I8: =F8-G8 -> 4758.91 | J8: =E8-H8 -> 3.97827 | K8: 46021 | L8: =DAYS360(K8,$C$1) -> 43 | M8: =(I8/G8) -> 0.10055855 | N8: - | O8: 92 | P8: - | Q8: 40.68 | R8: =Q8*0.93 -> 37.8324 | S8: 35.32 | T8: =Q8*1.25 -> 50.85 | U8: =Q8*1.5 -> 61.02 | V8: =Q8*2 -> 81.36 | W8: =H8-(H8*0.07) -> 36.792409 | X8: 39 | Y8: =(X8-H8)/H8 -> -0.014198822 | Z8: =F8/F$20 -> 0.087011425 | AB8: - | AC8: -
A9: APLD | B9: Long | C9: Applied Digital | D9: =842.9076+471.2592+487.9805 -> 1802.1473 | E9: 35.28 | F9: =E9*D9 -> 63579.757 | G9: =30923.76+17760.7+20459.97 -> 69144.43 | H9: =G9/D9 -> 38.367802 | I9: =F9-G9 -> -5564.6733 | J9: =E9-H9 -> -3.0878016 | K9: 46043 | L9: =DAYS360(K9,$C$1) -> 22 | M9: =(I9/G9) -> -0.080478981 | N9: 114 | O9: 99 | P9: 33 | Q9: 39.51 | R9: =Q9*0.93 -> 36.7443 | S9: 33.62 | T9: =Q9*1.25 -> 49.3875 | U9: =Q9*1.5 -> 59.265 | V9: =Q9*2 -> 79.02 | W9: =H9-(H9*0.07) -> 35.682055 | X9: 34 | Y9: =(X9-H9)/H9 -> -0.11384029 | Z9: =F9/F$20 -> 0.10621687 | AB9: 46150 | AC9: 81
A10: WLDN | B10: Long | C10: Wildan | D10: 410.2141 | E10: 117.33 | F10: =E10*D10 -> 48130.42 | G10: 48654.55 | H10: =G10/D10 -> 118.6077 | I10: =F10-G10 -> -524.12965 | J10: =E10-H10 -> -1.2776978 | K10: 46062 | L10: =DAYS360(K10,$C$1) -> 4 | M10: =(I10/G10) -> -0.010772469 | N10: 26 | O10: 96 | P10: 97 | Q10: 115.93 | R10: =Q10*0.93 -> 107.8149 | S10: 105.75 | T10: =Q10*1.25 -> 144.9125 | U10: =Q10*1.5 -> 173.895 | V10: =Q10*2 -> 231.86 | W10: =H10-(H10*0.07) -> 110.30516 | X10: 110 | Y10: =(X10-H10)/H10 -> -0.072572843 | Z10: =F10/F$20 -> 0.080407077 | AB10: 46079 | AC10: 98
A11: Q | B11: Long | C11: Qnity Electronics | D11: 220.4374 | E11: 111.69 | F11: =E11*D11 -> 24620.653 | G11: 24221.635 | H11: =G11/D11 -> 109.87988 | I11: =F11-G11 -> 399.01791 | J11: =E11-H11 -> 1.8101189 | K11: 46063 | L11: =DAYS360(K11,$C$1) -> 3 | M11: =(I11/G11) -> 0.016473615 | N11: 4 | O11: 78 | P11: 75 | Q11: 105.4 | R11: =Q11*0.93 -> 98.022 | S11: 92.67 | T11: =Q11*1.25 -> 131.75 | U11: =Q11*1.5 -> 158.1 | V11: =Q11*2 -> 210.8 | W11: =H11-(H11*0.07) -> 102.18829 | X11: 102 | Y11: =(X11-H11)/H11 -> -0.071713593 | Z11: =F11/F$20 -> 0.041131466 | AB11: 46079 | AC11: 91
F12: =E12*D12 -> 0 | H12: =G12/D12 -> #DIV/0! | I12: =F12-G12 -> 0 | J12: =E12-H12 -> #DIV/0! | L12: =DAYS360(K12,$C$1) -> 45403 | M12: =(I12/G12) -> #DIV/0! | R12: =Q12*0.93 -> 0 | T12: =Q12*1.25 -> 0 | U12: =Q12*1.5 -> 0 | V12: =Q12*2 -> 0 | W12: =H12-(H12*0.07) -> #DIV/0! | Y12: =(X12-H12)/H12 -> #DIV/0! | Z12: =F12/F$20 -> 0
