Workbook

Sheet 01-03-25
C1: 45660
C3: MANAGED ACCT | X3: Current | AC3: IBD
H4: Cost | J4: P/L | N4: Group | P4: EPS | R4: pivot | S4: last | W4: cost | X4: Stop | Y4: Stop | Z4: % | AB4: EPS | AC4: Comp
A5: Symbol | B5: Position | C5: Name | D5: Qty | E5: Current | F5: Value | G5: Cost | H5: per share | I5: P/L $ | J5: per sh | K5: Date purch | L5: days held | M5: % incr | N5: Rank | O5: RS | P5: RS | Q5: pivot | R5: -0.07 | S5: low | T5: 0.25 | U5: 0.5 | V5: 1 | W5: -0.07 | X5: Loss | Y5: Loss% | Z5: of port | AB5: Due | AC5: Rank
A7: ONON | B7: Long | C7: On Holding | D7: 1263.7796 | E7: 56.62 | F7: =E7*D7 -> 71555.201 | G7: 56489.42 | H7: =G7/D7 -> 44.698791 | I7: =F7-G7 -> 15065.781 | J7: =E7-H7 -> 11.921209 | K7: 45527 | L7: =DAYS360(K7,$C$1) -> 130 | M7: =(I7/G7) -> 0.26670093 | N7: 120 | O7: 94 | P7: 89 | Q7: 43.2 | R7: =Q7*0.93 -> 40.176 | S7: 49.51 | T7: =Q7*1.25 -> 54 | U7: =Q7*1.5 -> 64.8 | V7: =Q7*2 -> 86.4 | W7: =H7-(H7*0.07) -> 41.569875 | X7: 51 | Y7: =(X7-H7)/H7 -> 0.14097046 | Z7: =F7/F$19 -> 0.095345346 | AB7: 45729 | AC7: 96
A8: TILE | B8: Long | C8: Interface | D8: 3020.3486 | E8: 24.24 | F8: =E8*D8 -> 73213.25 | G8: 56486.59 | H8: =G8/D8 -> 18.70201 | I8: =F8-G8 -> 16726.66 | J8: =E8-H8 -> 5.5379899 | K8: 45527 | L8: =DAYS360(K8,$C$1) -> 130 | M8: =(I8/G8) -> 0.29611736 | N8: 108 | O8: 94 | P8: 86 | Q8: 17.86 | R8: =Q8*0.93 -> 16.6098 | S8: 23.7 | T8: =Q8*1.25 -> 22.325 | U8: =Q8*1.5 -> 26.79 | V8: =Q8*2 -> 35.72 | W8: =H8-(H8*0.07) -> 17.392869 | X8: 22 | Y8: =(X8-H8)/H8 -> 0.17634414 | Z8: =F8/F$19 -> 0.097554651 | AB8: 45720 | AC8: 89
A9: MSTR | B9: Long | C9: Microstrategy | D9: =341.2204-83.2121 -> 258.0083 | E9: 339.66 | F9: =E9*D9 -> 87635.099 | G9: =71012.62-17317.27 -> 53695.35 | H9: =G9/D9 -> 208.11482 | I9: =F9-G9 -> 33939.749 | J9: =E9-H9 -> 131.54518 | K9: 45580 | L9: =DAYS360(K9,$C$1) -> 78 | M9: =(I9/G9) -> 0.63207986 | N9: 13 | O9: 98 | P9: 5 | Q9: 183.7 | R9: =Q9*0.93 -> 170.841 | S9: 285.01 | T9: =Q9*1.25 -> 229.625 | U9: =Q9*1.5 -> 275.55 | V9: =Q9*2 -> 367.4 | W9: =H9-(H9*0.07) -> 193.54678 | X9: 335 | Y9: =(X9-H9)/H9 -> 0.60968837 | Z9: =F9/F$19 -> 0.11677137 | AB9: 45692 | AC9: 61
A10: IBIT | B10: Long | C10: iShares Bitcoin | D10: 939.2424 | E10: 55.96 | F10: =E10*D10 -> 52560.005 | G10: 36992.18 | H10: =G10/D10 -> 39.385126 | I10: =F10-G10 -> 15567.825 | J10: =E10-H10 -> 16.574874 | K10: 45593 | L10: =DAYS360(K10,$C$1) -> 65 | M10: =(I10/G10) -> 0.42084096 | O10: 96 | P10: - | Q10: 39.37 | R10: =Q10*0.93 -> 36.6141 | S10: 51.54 | T10: =Q10*1.25 -> 49.2125 | U10: =Q10*1.5 -> 59.055 | V10: =Q10*2 -> 78.74 | W10: =H10-(H10*0.07) -> 36.628167 | X10: 50 | Y10: =(X10-H10)/H10 -> 0.2695148 | Z10: =F10/F$19 -> 0.070034767
A11: AXGN | B11: Long | C11: Axogen | D11: 2234.6065 | E11: 16.11 | F11: =E11*D11 -> 35999.511 | G11: 37971.83 | H11: =G11/D11 -> 16.992625 | I11: =F11-G11 -> -1972.3193 | J11: =E11-H11 -> -0.88262488 | K11: 45652 | L11: =DAYS360(K11,$C$1) -> 7 | M11: =(I11/G11) -> -0.051941644 | N11: 82 | O11: 96 | P11: 81 | Q11: 15.9 | R11: =Q11*0.93 -> 14.787 | S11: 13.85 | T11: =Q11*1.25 -> 19.875 | U11: =Q11*1.5 -> 23.85 | V11: =Q11*2 -> 31.8 | W11: =H11-(H11*0.07) -> 15.803141 | X11: 15.65 | Y11: =(X11-H11)/H11 -> -0.079012212 | Z11: =F11/F$19 -> 0.047968362 | AB11: 45720 | AC11: 93
A12: SQ | B12: Long | C12: Block | D12: 653.8238 | E12: 92.16 | F12: =E12*D12 -> 60256.401 | G12: 58922.08 | H12: =G12/D12 -> 90.119203 | I12: =F12-G12 -> 1334.3214 | J12: =E12-H12 -> 2.0407966 | K12: 45660 | L12: =DAYS360(K12,$C$1) -> 0 | M12: =(I12/G12) -> 0.022645525 | N12: 38 | O12: 89 | P12: 99 | Q12: 87.52 | R12: =Q12*0.93 -> 81.3936 | S12: 84.82 | T12: =Q12*1.25 -> 109.4 | U12: =Q12*1.5 -> 131.28 | V12: =Q12*2 -> 175.04 | W12: =H12-(H12*0.07) -> 83.810859 | X12: 84 | Y12: =(X12-H12)/H12 -> -0.067901215 | Z12: =F12/F$19 -> 0.080290005 | AB12: 45708 | AC12: 97
F13: =E13*D13 -> 0 | H13: =G13/D13 -> #DIV/0! | I13: =F13-G13 -> 0 | J13: =E13-H13 -> #DIV/0! | L13: =DAYS360(K13,$C$1) -> 45003 | M13: =(I13/G13) -> #DIV/0! | R13: =Q13*0.93 -> 0 | T13: =Q13*1.25 -> 0 | U13: =Q13*1.5 -> 0 | V13: =Q13*2 -> 0 | W13: =H13-(H13*0.07) -> #DIV/0! | Y13: =(X13-H13)/H13 -> #DIV/0! | Z13: =F13/F$19 -> 0
F14: =E14*D14 -> 0 | H14: =G14/D14 -> #DIV/0! | I14: =F14-G14 -> 0 | J14: =E14-H14 -> #DIV/0! | L14: =DAYS360(K14,$C$1) -> 45003 | M14: =(I14/G14) -> #DIV/0! | R14: =Q14*0.93 -> 0 | T14: =Q14*1.25 -> 0 | U14: =Q14*1.5 -> 0 | V14: =Q14*2 -> 0 | W14: =H14-(H14*0.07) -> #DIV/0! | Y14: =(X14-H14)/H14 -> #DIV/0! | Z14: =F14/F$19 -> 0
F15: =E15*D15 -> 0 | H15: =G15/D15 -> #DIV/0! | I15: =F15-G15 -> 0 | J15: =E15-H15 -> #DIV/0! | L15: =DAYS360(K15,$C$1) -> 45003 | M15: =(I15/G15) -> #DIV/0! | R15: =Q15*0.93 -> 0 | T15: =Q15*1.25 -> 0 | U15: =Q15*1.5 -> 0 | V15: =Q15*2 -> 0 | W15: =H15-(H15*0.07) -> #DIV/0! | Y15: =(X15-H15)/H15 -> #DIV/0! | Z15: =F15/F$19 -> 0
F16: =E16*D16 -> 0 | H16: =G16/D16 -> #DIV/0! | I16: =F16-G16 -> 0 | J16: =E16-H16 -> #DIV/0! | L16: =DAYS360(K16,$C$1) -> 45003 | M16: =(I16/G16) -> #DIV/0! | R16: =Q16*0.93 -> 0 | T16: =Q16*1.25 -> 0 | U16: =Q16*1.5 -> 0 | V16: =Q16*2 -> 0 | W16: =H16-(H16*0.07) -> #DIV/0! | Y16: =(X16-H16)/H16 -> #DIV/0! | Z16: =F16/F$19 -> 0
A17: Sub-Total | F17: =SUM(F6:F16) -> 381219.47 | G17: =SUM(G6:G16) -> 300557.45 | I17: =SUM(I6:I16) -> 80662.017
D18: Cash, other | F18: 369265 | G18: =F18/F19 -> 0.4920355
D19: Total | F19: =SUM(F17:F18) -> 750484.47 | K19: Control acct (Doug's IRA) | M19: Today
H20: Last week's close | I20: ='[1]12-27-24'!F19 -> 751129.2 | K20: 45657 | L20: 170762 | M20: 174651
H21: Week's change | I21: =(F19-I20)/I20 -> -0.00085834714 | K21: chg % | L21: =(M20-L20)/L20 -> 0.022774388
M23: days
A24: 2025 Closed Trades - Managed Acct | D24: Qty | E24: Cost/sh | F24: $ cost | G24: $Proc | H24: Proc/sh | I24: Profit/loss | J24: % | K24: Date purch | L24: Date sold | M24: held | P24: Comments
A25: APH | B25: Long | C25: Amphenol | D25: 935.0369 | E25: =F25/D25 -> 72.335006 | F25: 67635.9 | G25: 64699.88 | H25: =G25/D25 -> 69.195002 | I25: =G25-F25 -> -2936.02 | J25: =I25/F25 -> -0.043409195 | K25: 45609 | L25: 45659 | M25: =DAYS360(K25,L25) -> 49
I35: =SUM(I25:I34) -> -2936.02 | J35: Avg
H36: # of losses | I36: 1 | J36: -0.0434
H37: # of wins | I37: 0 | J37: 0

Sheet 01-10-25
C1: 45667
C3: MANAGED ACCT | X3: Current | AC3: IBD
H4: Cost | J4: P/L | N4: Group | P4: EPS | R4: pivot | S4: last | W4: cost | X4: Stop | Y4: Stop | Z4: % | AB4: EPS | AC4: Comp
A5: Symbol | B5: Position | C5: Name | D5: Qty | E5: Current | F5: Value | G5: Cost | H5: per share | I5: P/L $ | J5: per sh | K5: Date purch | L5: days held | M5: % incr | N5: Rank | O5: RS | P5: RS | Q5: pivot | R5: -0.07 | S5: low | T5: 0.25 | U5: 0.5 | V5: 1 | W5: -0.07 | X5: Loss | Y5: Loss% | Z5: of port | AB5: Due | AC5: Rank
A7: ONON | B7: Long | C7: On Holding | D7: 1263.7796 | E7: 56.63 | F7: =E7*D7 -> 71567.839 | G7: 56489.42 | H7: =G7/D7 -> 44.698791 | I7: =F7-G7 -> 15078.419 | J7: =E7-H7 -> 11.931209 | K7: 45527 | L7: =DAYS360(K7,$C$1) -> 137 | M7: =(I7/G7) -> 0.26692465 | N7: 95 | O7: 94 | P7: 89 | Q7: 43.2 | R7: =Q7*0.93 -> 40.176 | S7: 49.51 | T7: =Q7*1.25 -> 54 | U7: =Q7*1.5 -> 64.8 | V7: =Q7*2 -> 86.4 | W7: =H7-(H7*0.07) -> 41.569875 | X7: 51 | Y7: =(X7-H7)/H7 -> 0.14097046 | Z7: =F7/F$19 -> 0.097506787 | AB7: 45729 | AC7: 98
A8: TILE | B8: Long | C8: Interface | D8: 3020.3486 | E8: 22.8 | F8: =E8*D8 -> 68863.948 | G8: 56486.59 | H8: =G8/D8 -> 18.70201 | I8: =F8-G8 -> 12377.358 | J8: =E8-H8 -> 4.0979899 | K8: 45527 | L8: =DAYS360(K8,$C$1) -> 137 | M8: =(I8/G8) -> 0.21912029 | N8: 122 | O8: 93 | P8: 86 | Q8: 17.86 | R8: =Q8*0.93 -> 16.6098 | S8: 23.7 | T8: =Q8*1.25 -> 22.325 | U8: =Q8*1.5 -> 26.79 | V8: =Q8*2 -> 35.72 | W8: =H8-(H8*0.07) -> 17.392869 | X8: 22 | Y8: =(X8-H8)/H8 -> 0.17634414 | Z8: =F8/F$19 -> 0.093822902 | AB8: 45720 | AC8: 88
A9: MSTR | B9: Long | C9: Microstrategy | D9: =341.2204-83.2121 -> 258.0083 | E9: 327.91 | F9: =E9*D9 -> 84603.502 | G9: =71012.62-17317.27 -> 53695.35 | H9: =G9/D9 -> 208.11482 | I9: =F9-G9 -> 30908.152 | J9: =E9-H9 -> 119.79518 | K9: 45580 | L9: =DAYS360(K9,$C$1) -> 85 | M9: =(I9/G9) -> 0.57562064 | N9: 19 | O9: 99 | P9: 5 | Q9: 183.7 | R9: =Q9*0.93 -> 170.841 | S9: 285.01 | T9: =Q9*1.25 -> 229.625 | U9: =Q9*1.5 -> 275.55 | V9: =Q9*2 -> 367.4 | W9: =H9-(H9*0.07) -> 193.54678 | X9: 335 | Y9: =(X9-H9)/H9 -> 0.60968837 | Z9: =F9/F$19 -> 0.11526708 | AB9: 45692 | AC9: 65
A10: IBIT | B10: Long | C10: iShares Bitcoin | D10: 939.2424 | E10: 53.84 | F10: =E10*D10 -> 50568.811 | G10: 36992.18 | H10: =G10/D10 -> 39.385126 | I10: =F10-G10 -> 13576.631 | J10: =E10-H10 -> 14.454874 | K10: 45593 | L10: =DAYS360(K10,$C$1) -> 72 | M10: =(I10/G10) -> 0.36701354 | O10: 96 | P10: - | Q10: 39.37 | R10: =Q10*0.93 -> 36.6141 | S10: 51.54 | T10: =Q10*1.25 -> 49.2125 | U10: =Q10*1.5 -> 59.055 | V10: =Q10*2 -> 78.74 | W10: =H10-(H10*0.07) -> 36.628167 | X10: 50 | Y10: =(X10-H10)/H10 -> 0.2695148 | Z10: =F10/F$19 -> 0.0688969
A11: AXGN | B11: Long | C11: Axogen | D11: 2234.6065 | E11: 18.05 | F11: =E11*D11 -> 40334.647 | G11: 37971.83 | H11: =G11/D11 -> 16.992625 | I11: =F11-G11 -> 2362.8173 | J11: =E11-H11 -> 1.0573751 | K11: 45652 | L11: =DAYS360(K11,$C$1) -> 14 | M11: =(I11/G11) -> 0.062225532 | N11: 55 | O11: 97 | P11: 81 | Q11: 15.9 | R11: =Q11*0.93 -> 14.787 | S11: 13.85 | T11: =Q11*1.25 -> 19.875 | U11: =Q11*1.5 -> 23.85 | V11: =Q11*2 -> 31.8 | W11: =H11-(H11*0.07) -> 15.803141 | X11: 15.65 | Y11: =(X11-H11)/H11 -> -0.079012212 | Z11: =F11/F$19 -> 0.054953481 | AB11: 45720 | AC11: 94
A12: OKLO | B12: Long | C12: Oklo | D12: 1255.3625 | E12: 25.24 | F12: =E12*D12 -> 31685.349 | G12: 37884.65 | H12: =G12/D12 -> 30.178255 | I12: =F12-G12 -> -6199.3005 | J12: =E12-H12 -> -4.9382553 | K12: 45663 | L12: =DAYS360(K12,$C$1) -> 4 | M12: =(I12/G12) -> -0.16363621 | N12: 9 | O12: 98 | P12: 7 | Q12: 24.99 | R12: =Q12*0.93 -> 23.2407 | S12: 20.3 | T12: =Q12*1.25 -> 31.2375 | U12: =Q12*1.5 -> 37.485 | V12: =Q12*2 -> 49.98 | W12: =H12-(H12*0.07) -> 28.065777 | X12: 23 | Y12: =(X12-H12)/H12 -> -0.23786184 | Z12: =F12/F$19 -> 0.043169343 | AB12: 45713 | AC12: 69
A13: GEV | B13: Long | C13: GE Vernova | D13: 201.9693 | E13: 367.1 | F13: =E13*D13 -> 74142.93 | G13: 74438.86 | H13: =G13/D13 -> 368.56522 | I13: =F13-G13 -> -295.92997 | J13: =E13-H13 -> -1.4652225 | K13: 45664 | L13: =DAYS360(K13,$C$1) -> 3 | M13: =(I13/G13) -> -0.0039754769 | N13: 9 | O13: 98 | P13: 61 | Q13: 354.69 | R13: =Q13*0.93 -> 329.8617 | S13: 348.2 | T13: =Q13*1.25 -> 443.3625 | U13: =Q13*1.5 -> 532.035 | V13: =Q13*2 -> 709.38 | W13: =H13-(H13*0.07) -> 342.76566 | X13: 345 | Y13: =(X13-H13)/H13 -> -0.063937727 | Z13: =F13/F$19 -> 0.10101519 | AB13: 45679 | AC13: 92
F14: =E14*D14 -> 0 | H14: =G14/D14 -> #DIV/0! | I14: =F14-G14 -> 0 | J14: =E14-H14 -> #DIV/0! | L14: =DAYS360(K14,$C$1) -> 45010 | M14: =(I14/G14) -> #DIV/0! | R14: =Q14*0.93 -> 0 | T14: =Q14*1.25 -> 0 | U14: =Q14*1.5 -> 0 | V14: =Q14*2 -> 0 | W14: =H14-(H14*0.07) -> #DIV/0! | Y14: =(X14-H14)/H14 -> #DIV/0! | Z14: =F14/F$19 -> 0
F15: =E15*D15 -> 0 | H15: =G15/D15 -> #DIV/0! | I15: =F15-G15 -> 0 | J15: =E15-H15 -> #DIV/0! | L15: =DAYS360(K15,$C$1) -> 45010 | M15: =(I15/G15) -> #DIV/0! | R15: =Q15*0.93 -> 0 | T15: =Q15*1.25 -> 0 | U15: =Q15*1.5 -> 0 | V15: =Q15*2 -> 0 | W15: =H15-(H15*0.07) -> #DIV/0! | Y15: =(X15-H15)/H15 -> #DIV/0! | Z15: =F15/F$19 -> 0
F16: =E16*D16 -> 0 | H16: =G16/D16 -> #DIV/0! | I16: =F16-G16 -> 0 | J16: =E16-H16 -> #DIV/0! | L16: =DAYS360(K16,$C$1) -> 45010 | M16: =(I16/G16) -> #DIV/0! | R16: =Q16*0.93 -> 0 | T16: =Q16*1.25 -> 0 | U16: =Q16*1.5 -> 0 | V16: =Q16*2 -> 0 | W16: =H16-(H16*0.07) -> #DIV/0! | Y16: =(X16-H16)/H16 -> #DIV/0! | Z16: =F16/F$19 -> 0
A17: Sub-Total | F17: =SUM(F6:F16) -> 421767.03 | G17: =SUM(G6:G16) -> 353958.88 | I17: =SUM(I6:I16) -> 67808.146
D18: Cash, other | F18: 312211 | G18: =F18/F19 -> 0.42536832
D19: Total | F19: =SUM(F17:F18) -> 733978.03 | K19: Control acct (Doug's IRA) | M19: Today
H20: Last week's close | I20: ='01-03-25'!F19 -> 750484.47 | K20: 45657 | L20: 170762 | M20: 170621
H21: Week's change | I21: =(F19-I20)/I20 -> -0.02199438 | K21: chg % | L21: =(M20-L20)/L20 -> -0.00082571064
M23: days
A24: 2025 Closed Trades - Managed Acct | D24: Qty | E24: Cost/sh | F24: $ cost | G24: $Proc | H24: Proc/sh | I24: Profit/loss | J24: % | K24: Date purch | L24: Date sold | M24: held | P24: Comments
A25: APH | B25: Long | C25: Amphenol | D25: 935.0369 | E25: =F25/D25 -> 72.335006 | F25: 67635.9 | G25: 64699.88 | H25: =G25/D25 -> 69.195002 | I25: =G25-F25 -> -2936.02 | J25: =I25/F25 -> -0.043409195 | K25: 45609 | L25: 45659 | M25: =DAYS360(K25,L25) -> 49
A26: SQ | B26: Long | C26: Block | D26: 653.8238 | E26: =F26/D26 -> 90.119203 | F26: 58922.08 | G26: 54094.08 | H26: =G26/D26 -> 82.734951 | I26: =G26-F26 -> -4828 | J26: =I26/F26 -> -0.081938723 | K26: 45660 | L26: 45667 | M26: =DAYS360(K26,L26) -> 7
I35: =SUM(I25:I34) -> -7764.02 | J35: Avg
H36: # of losses | I36: 2 | J36: -0.0627
H37: # of wins | I37: 0 | J37: 0

Sheet 01-17-25
C1: 45674
C3: MANAGED ACCT | X3: Current | AC3: IBD
H4: Cost | J4: P/L | N4: Group | P4: EPS | R4: pivot | S4: last | W4: cost | X4: Stop | Y4: Stop | Z4: % | AB4: EPS | AC4: Comp
A5: Symbol | B5: Position | C5: Name | D5: Qty | E5: Current | F5: Value | G5: Cost | H5: per share | I5: P/L $ | J5: per sh | K5: Date purch | L5: days held | M5: % incr | N5: Rank | O5: RS | P5: RS | Q5: pivot | R5: -0.07 | S5: low | T5: 0.25 | U5: 0.5 | V5: 1 | W5: -0.07 | X5: Loss | Y5: Loss% | Z5: of port | AB5: Due | AC5: Rank
A7: ONON | B7: Long | C7: On Holding | D7: 1263.7796 | E7: 57.98 | F7: =E7*D7 -> 73273.941 | G7: 56489.42 | H7: =G7/D7 -> 44.698791 | I7: =F7-G7 -> 16784.521 | J7: =E7-H7 -> 13.281209 | K7: 45527 | L7: =DAYS360(K7,$C$1) -> 144 | M7: =(I7/G7) -> 0.29712681 | N7: 92 | O7: 94 | P7: 89 | Q7: 43.2 | R7: =Q7*0.93 -> 40.176 | S7: 53.08 | T7: =Q7*1.25 -> 54 | U7: =Q7*1.5 -> 64.8 | V7: =Q7*2 -> 86.4 | W7: =H7-(H7*0.07) -> 41.569875 | X7: 51 | Y7: =(X7-H7)/H7 -> 0.14097046 | Z7: =F7/F$19 -> 0.09484278 | AB7: 45729 | AC7: 97
A8: TILE | B8: Long | C8: Interface | D8: 3020.3486 | E8: 24.01 | F8: =E8*D8 -> 72518.57 | G8: 56486.59 | H8: =G8/D8 -> 18.70201 | I8: =F8-G8 -> 16031.98 | J8: =E8-H8 -> 5.3079899 | K8: 45527 | L8: =DAYS360(K8,$C$1) -> 144 | M8: =(I8/G8) -> 0.28381922 | N8: 117 | O8: 93 | P8: 86 | Q8: 17.86 | R8: =Q8*0.93 -> 16.6098 | S8: 22.11 | T8: =Q8*1.25 -> 22.325 | U8: =Q8*1.5 -> 26.79 | V8: =Q8*2 -> 35.72 | W8: =H8-(H8*0.07) -> 17.392869 | X8: 22 | Y8: =(X8-H8)/H8 -> 0.17634414 | Z8: =F8/F$19 -> 0.093865059 | AB8: 45720 | AC8: 87
A9: MSTR | B9: Long | C9: Microstrategy | D9: =341.2204-83.2121 -> 258.0083 | E9: 396.5 | F9: =E9*D9 -> 102300.29 | G9: =71012.62-17317.27 -> 53695.35 | H9: =G9/D9 -> 208.11482 | I9: =F9-G9 -> 48604.941 | J9: =E9-H9 -> 188.38518 | K9: 45580 | L9: =DAYS360(K9,$C$1) -> 92 | M9: =(I9/G9) -> 0.90519833 | N9: 21 | O9: 99 | P9: 4 | Q9: 183.7 | R9: =Q9*0.93 -> 170.841 | S9: 285.01 | T9: =Q9*1.25 -> 229.625 | U9: =Q9*1.5 -> 275.55 | V9: =Q9*2 -> 367.4 | W9: =H9-(H9*0.07) -> 193.54678 | X9: 335 | Y9: =(X9-H9)/H9 -> 0.60968837 | Z9: =F9/F$19 -> 0.1324133 | AB9: 45692 | AC9: 67
A10: IBIT | B10: Long | C10: iShares Bitcoin | D10: 939.2424 | E10: 59.62 | F10: =E10*D10 -> 55997.632 | G10: 36992.18 | H10: =G10/D10 -> 39.385126 | I10: =F10-G10 -> 19005.452 | J10: =E10-H10 -> 20.234874 | K10: 45593 | L10: =DAYS360(K10,$C$1) -> 79 | M10: =(I10/G10) -> 0.51376945 | O10: 96 | P10: - | Q10: 39.37 | R10: =Q10*0.93 -> 36.6141 | S10: 51.54 | T10: =Q10*1.25 -> 49.2125 | U10: =Q10*1.5 -> 59.055 | V10: =Q10*2 -> 78.74 | W10: =H10-(H10*0.07) -> 36.628167 | X10: 50 | Y10: =(X10-H10)/H10 -> 0.2695148 | Z10: =F10/F$19 -> 0.072481035
A11: AXGN | B11: Long | C11: Axogen | D11: 2234.6065 | E11: 18.09 | F11: =E11*D11 -> 40424.032 | G11: 37971.83 | H11: =G11/D11 -> 16.992625 | I11: =F11-G11 -> 2452.2016 | J11: =E11-H11 -> 1.0973751 | K11: 45652 | L11: =DAYS360(K11,$C$1) -> 21 | M11: =(I11/G11) -> 0.064579494 | N11: 49 | O11: 97 | P11: 81 | Q11: 15.9 | R11: =Q11*0.93 -> 14.787 | S11: 14 | T11: =Q11*1.25 -> 19.875 | U11: =Q11*1.5 -> 23.85 | V11: =Q11*2 -> 31.8 | W11: =H11-(H11*0.07) -> 15.803141 | X11: 15.65 | Y11: =(X11-H11)/H11 -> -0.079012212 | Z11: =F11/F$19 -> 0.052323206 | AB11: 45720 | AC11: 94
A12: OKLO | B12: Long | C12: Oklo | D12: 1255.3625 | E12: 26.05 | F12: =E12*D12 -> 32702.193 | G12: 37884.65 | H12: =G12/D12 -> 30.178255 | I12: =F12-G12 -> -5182.4569 | J12: =E12-H12 -> -4.1282553 | K12: 45663 | L12: =DAYS360(K12,$C$1) -> 11 | M12: =(I12/G12) -> -0.13679569 | N12: 3 | O12: 98 | P12: 6 | Q12: 24.99 | R12: =Q12*0.93 -> 23.2407 | S12: 21.5 | T12: =Q12*1.25 -> 31.2375 | U12: =Q12*1.5 -> 37.485 | V12: =Q12*2 -> 49.98 | W12: =H12-(H12*0.07) -> 28.065777 | X12: 23 | Y12: =(X12-H12)/H12 -> -0.23786184 | Z12: =F12/F$19 -> 0.042328376 | AB12: 45713 | AC12: 69
A13: GEV | B13: Long | C13: GE Vernova | D13: 201.9693 | E13: 401.41 | F13: =E13*D13 -> 81072.497 | G13: 74438.86 | H13: =G13/D13 -> 368.56522 | I13: =F13-G13 -> 6633.6367 | J13: =E13-H13 -> 32.844777 | K13: 45664 | L13: =DAYS360(K13,$C$1) -> 10 | M13: =(I13/G13) -> 0.089115238 | N13: 3 | O13: 98 | P13: 61 | Q13: 354.69 | R13: =Q13*0.93 -> 329.8617 | S13: 348.2 | T13: =Q13*1.25 -> 443.3625 | U13: =Q13*1.5 -> 532.035 | V13: =Q13*2 -> 709.38 | W13: =H13-(H13*0.07) -> 342.76566 | X13: 345 | Y13: =(X13-H13)/H13 -> -0.063937727 | Z13: =F13/F$19 -> 0.10493691 | AB13: 45679 | AC13: 91
A14: AGX | B14: Long | C14: Argan | D14: 347.7531 | E14: 177.89 | F14: =E14*D14 -> 61861.799 | G14: 59492.79 | H14: =G14/D14 -> 171.07767 | I14: =F14-G14 -> 2369.009 | J14: =E14-H14 -> 6.8123302 | K14: 45671 | L14: =DAYS360(K14,$C$1) -> 3 | M14: =(I14/G14) -> 0.039820102 | N14: 9 | O14: 98 | P14: 98 | Q14: 165.33 | R14: =Q14*0.93 -> 153.7569 | S14: 141.02 | T14: =Q14*1.25 -> 206.6625 | U14: =Q14*1.5 -> 247.995 | V14: =Q14*2 -> 330.66 | W14: =H14-(H14*0.07) -> 159.10223 | X14: 159 | Y14: =(X14-H14)/H14 -> -0.070597582 | Z14: =F14/F$19 -> 0.080071372 | AB14: 45756 | AC14: 99
A15: PSTG | B15: Long | C15: Pure Storage | D15: 675.2982 | E15: 66.3 | F15: =E15*D15 -> 44772.271 | G15: 45046.15 | H15: =G15/D15 -> 66.705568 | I15: =F15-G15 -> -273.87934 | J15: =E15-H15 -> -0.405568 | K15: 45673 | L15: =DAYS360(K15,$C$1) -> 1 | M15: =(I15/G15) -> -0.0060799722 | N15: 126 | O15: 88 | P15: 90 | Q15: 67.95 | R15: =Q15*0.93 -> 63.1935 | S15: 60.62 | T15: =Q15*1.25 -> 84.9375 | U15: =Q15*1.5 -> 101.925 | V15: =Q15*2 -> 135.9 | W15: =H15-(H15*0.07) -> 62.036178 | X15: 62 | Y15: =(X15-H15)/H15 -> -0.070542357 | Z15: =F15/F$19 -> 0.057951389 | AB15: 45714 | AC15: 90
F16: =E16*D16 -> 0 | H16: =G16/D16 -> #DIV/0! | I16: =F16-G16 -> 0 | J16: =E16-H16 -> #DIV/0! | L16: =DAYS360(K16,$C$1) -> 45017 | M16: =(I16/G16) -> #DIV/0! | R16: =Q16*0.93 -> 0 | T16: =Q16*1.25 -> 0 | U16: =Q16*1.5 -> 0 | V16: =Q16*2 -> 0 | W16: =H16-(H16*0.07) -> #DIV/0! | Y16: =(X16-H16)/H16 -> #DIV/0! | Z16: =F16/F$19 -> 0
A17: Sub-Total | F17: =SUM(F6:F16) -> 564923.22 | G17: =SUM(G6:G16) -> 458497.82 | I17: =SUM(I6:I16) -> 106425.4
D18: Cash, other | F18: 207660 | G18: =F18/F19 -> 0.26878658
D19: Total | F19: =SUM(F17:F18) -> 772583.22 | K19: Control acct (Doug's IRA) | M19: Today
H20: Last week's close | I20: ='01-10-25'!F19 -> 733978.03 | K20: 45657 | L20: 170762 | M20: 180122
H21: Week's change | I21: =(F19-I20)/I20 -> 0.052597213 | K21: chg % | L21: =(M20-L20)/L20 -> 0.054813132
M23: days
A24: 2025 Closed Trades - Managed Acct | D24: Qty | E24: Cost/sh | F24: $ cost | G24: $Proc | H24: Proc/sh | I24: Profit/loss | J24: % | K24: Date purch | L24: Date sold | M24: held | P24: Comments
A25: APH | B25: Long | C25: Amphenol | D25: 935.0369 | E25: =F25/D25 -> 72.335006 | F25: 67635.9 | G25: 64699.88 | H25: =G25/D25 -> 69.195002 | I25: =G25-F25 -> -2936.02 | J25: =I25/F25 -> -0.043409195 | K25: 45609 | L25: 45659 | M25: =DAYS360(K25,L25) -> 49
A26: SQ | B26: Long | C26: Block | D26: 653.8238 | E26: =F26/D26 -> 90.119203 | F26: 58922.08 | G26: 54094.08 | H26: =G26/D26 -> 82.734951 | I26: =G26-F26 -> -4828 | J26: =I26/F26 -> -0.081938723 | K26: 45660 | L26: 45667 | M26: =DAYS360(K26,L26) -> 7
I35: =SUM(I25:I34) -> -7764.02 | J35: Avg
H36: # of losses | I36: 2 | J36: -0.0627
H37: # of wins | I37: 0 | J37: 0

Sheet 01-24-25
C1: 45681
C3: MANAGED ACCT | X3: Current | AC3: IBD
H4: Cost | J4: P/L | N4: Group | P4: EPS | R4: pivot | S4: last | W4: cost | X4: Stop | Y4: Stop | Z4: % | AB4: EPS | AC4: Comp
A5: Symbol | B5: Position | C5: Name | D5: Qty | E5: Current | F5: Value | G5: Cost | H5: per share | I5: P/L $ | J5: per sh | K5: Date purch | L5: days held | M5: % incr | N5: Rank | O5: RS | P5: RS | Q5: pivot | R5: -0.07 | S5: low | T5: 0.25 | U5: 0.5 | V5: 1 | W5: -0.07 | X5: Loss | Y5: Loss% | Z5: of port | AB5: Due | AC5: Rank
A7: ONON | B7: Long | C7: On Holding | D7: 1263.7796 | E7: 60.15 | F7: =E7*D7 -> 76016.343 | G7: 56489.42 | H7: =G7/D7 -> 44.698791 | I7: =F7-G7 -> 19526.923 | J7: =E7-H7 -> 15.451209 | K7: 45527 | L7: =DAYS360(K7,$C$1) -> 151 | M7: =(I7/G7) -> 0.34567399 | N7: 58 | O7: 95 | P7: 89 | Q7: 43.2 | R7: =Q7*0.93 -> 40.176 | S7: 53.08 | T7: =Q7*1.25 -> 54 | U7: =Q7*1.5 -> 64.8 | V7: =Q7*2 -> 86.4 | W7: =H7-(H7*0.07) -> 41.569875 | X7: 51 | Y7: =(X7-H7)/H7 -> 0.14097046 | Z7: =F7/F$19 -> 0.09598834 | AB7: 45729 | AC7: 99
A8: TILE | B8: Long | C8: Interface | D8: 3020.3486 | E8: 24.47 | F8: =E8*D8 -> 73907.93 | G8: 56486.59 | H8: =G8/D8 -> 18.70201 | I8: =F8-G8 -> 17421.34 | J8: =E8-H8 -> 5.7679899 | K8: 45527 | L8: =DAYS360(K8,$C$1) -> 151 | M8: =(I8/G8) -> 0.30841551 | N8: 103 | O8: 93 | P8: 86 | Q8: 17.86 | R8: =Q8*0.93 -> 16.6098 | S8: 22.11 | T8: =Q8*1.25 -> 22.325 | U8: =Q8*1.5 -> 26.79 | V8: =Q8*2 -> 35.72 | W8: =H8-(H8*0.07) -> 17.392869 | X8: 22 | Y8: =(X8-H8)/H8 -> 0.17634414 | Z8: =F8/F$19 -> 0.093325978 | AB8: 45720 | AC8: 88
A9: MSTR | B9: Long | C9: Microstrategy | D9: =341.2204-83.2121 -> 258.0083 | E9: 353.67 | F9: =E9*D9 -> 91249.795 | G9: =71012.62-17317.27 -> 53695.35 | H9: =G9/D9 -> 208.11482 | I9: =F9-G9 -> 37554.445 | J9: =E9-H9 -> 145.55518 | K9: 45580 | L9: =DAYS360(K9,$C$1) -> 99 | M9: =(I9/G9) -> 0.69939847 | N9: 20 | O9: 99 | P9: 4 | Q9: 183.7 | R9: =Q9*0.93 -> 170.841 | S9: 285.01 | T9: =Q9*1.25 -> 229.625 | U9: =Q9*1.5 -> 275.55 | V9: =Q9*2 -> 367.4 | W9: =H9-(H9*0.07) -> 193.54678 | X9: 335 | Y9: =(X9-H9)/H9 -> 0.60968837 | Z9: =F9/F$19 -> 0.11522412 | AB9: 45693 | AC9: 65
A10: IBIT | B10: Long | C10: iShares Bitcoin | D10: =939.2424+388.9544 -> 1328.1968 | E10: 59.7 | F10: =E10*D10 -> 79293.349 | G10: =36992.18+23418.77 -> 60410.95 | H10: =G10/D10 -> 45.483433 | I10: =F10-G10 -> 18882.399 | J10: =E10-H10 -> 14.216567 | K10: 45593 | L10: =DAYS360(K10,$C$1) -> 86 | M10: =(I10/G10) -> 0.31256583 | O10: 96 | P10: - | Q10: 61.08 | R10: =Q10*0.93 -> 56.8044 | S10: 51.54 | T10: =Q10*1.25 -> 76.35 | U10: =Q10*1.5 -> 91.62 | V10: =Q10*2 -> 122.16 | W10: =H10-(H10*0.07) -> 42.299593 | X10: 53 | Y10: =(X10-H10)/H10 -> 0.16525945 | Z10: =F10/F$19 -> 0.10012632
A11: AXGN | B11: Long | C11: Axogen | D11: 2234.6065 | E11: 18.14 | F11: =E11*D11 -> 40535.762 | G11: 37971.83 | H11: =G11/D11 -> 16.992625 | I11: =F11-G11 -> 2563.9319 | J11: =E11-H11 -> 1.1473751 | K11: 45652 | L11: =DAYS360(K11,$C$1) -> 28 | M11: =(I11/G11) -> 0.067521947 | N11: 45 | O11: 97 | P11: 81 | Q11: 15.9 | R11: =Q11*0.93 -> 14.787 | S11: 14 | T11: =Q11*1.25 -> 19.875 | U11: =Q11*1.5 -> 23.85 | V11: =Q11*2 -> 31.8 | W11: =H11-(H11*0.07) -> 15.803141 | X11: 15.65 | Y11: =(X11-H11)/H11 -> -0.079012212 | Z11: =F11/F$19 -> 0.051185842 | AB11: 45720 | AC11: 93
A12: OKLO | B12: Long | C12: Oklo | D12: 1255.3625 | E12: 41.82 | F12: =E12*D12 -> 52499.26 | G12: 37884.65 | H12: =G12/D12 -> 30.178255 | I12: =F12-G12 -> 14614.61 | J12: =E12-H12 -> 11.641745 | K12: 45663 | L12: =DAYS360(K12,$C$1) -> 18 | M12: =(I12/G12) -> 0.385766 | N12: 2 | O12: 99 | P12: 6 | Q12: 24.99 | R12: =Q12*0.93 -> 23.2407 | S12: 21.5 | T12: =Q12*1.25 -> 31.2375 | U12: =Q12*1.5 -> 37.485 | V12: =Q12*2 -> 49.98 | W12: =H12-(H12*0.07) -> 28.065777 | X12: 32 | Y12: =(X12-H12)/H12 -> 0.060366138 | Z12: =F12/F$19 -> 0.066292545 | AB12: 45713 | AC12: 76
A13: GEV | B13: Long | C13: GE Vernova | D13: 201.9693 | E13: 420.49 | F13: =E13*D13 -> 84926.071 | G13: 74438.86 | H13: =G13/D13 -> 368.56522 | I13: =F13-G13 -> 10487.211 | J13: =E13-H13 -> 51.924777 | K13: 45664 | L13: =DAYS360(K13,$C$1) -> 17 | M13: =(I13/G13) -> 0.14088355 | N13: 2 | O13: 98 | P13: 67 | Q13: 354.69 | R13: =Q13*0.93 -> 329.8617 | S13: 348.2 | T13: =Q13*1.25 -> 443.3625 | U13: =Q13*1.5 -> 532.035 | V13: =Q13*2 -> 709.38 | W13: =H13-(H13*0.07) -> 342.76566 | X13: 375 | Y13: =(X13-H13)/H13 -> 0.017458993 | Z13: =F13/F$19 -> 0.10723895 | AB13: 45771 | AC13: 94
A14: AGX | B14: Long | C14: Argan | D14: =347.7531+131.6951 -> 479.4482 | E14: 168.54 | F14: =E14*D14 -> 80806.2 | G14: =59492.79+21969.78 -> 81462.57 | H14: =G14/D14 -> 169.90901 | I14: =F14-G14 -> -656.37037 | J14: =E14-H14 -> -1.3690121 | K14: 45671 | L14: =DAYS360(K14,$C$1) -> 10 | M14: =(I14/G14) -> -0.0080573246 | N14: 11 | O14: 98 | P14: 98 | Q14: 165.33 | R14: =Q14*0.93 -> 153.7569 | S14: 141.02 | T14: =Q14*1.25 -> 206.6625 | U14: =Q14*1.5 -> 247.995 | V14: =Q14*2 -> 330.66 | W14: =H14-(H14*0.07) -> 158.01538 | X14: 159 | Y14: =(X14-H14)/H14 -> -0.064205023 | Z14: =F14/F$19 -> 0.10203665 | AB14: 45756 | AC14: 99
A15: PSTG | B15: Long | C15: Pure Storage | D15: =675.2982+456.8207 -> 1132.1189 | E15: 72.15 | F15: =E15*D15 -> 81682.379 | G15: =45046.15+31240.53 -> 76286.68 | H15: =G15/D15 -> 67.383982 | I15: =F15-G15 -> 5395.6986 | J15: =E15-H15 -> 4.7660176 | K15: 45673 | L15: =DAYS360(K15,$C$1) -> 8 | M15: =(I15/G15) -> 0.070729237 | N15: 95 | O15: 91 | P15: 90 | Q15: 67.95 | R15: =Q15*0.93 -> 63.1935 | S15: 60.62 | T15: =Q15*1.25 -> 84.9375 | U15: =Q15*1.5 -> 101.925 | V15: =Q15*2 -> 135.9 | W15: =H15-(H15*0.07) -> 62.667104 | X15: 64 | Y15: =(X15-H15)/H15 -> -0.050219388 | Z15: =F15/F$19 -> 0.10314303 | AB15: 45714 | AC15: 92
F16: =E16*D16 -> 0 | H16: =G16/D16 -> #DIV/0! | I16: =F16-G16 -> 0 | J16: =E16-H16 -> #DIV/0! | L16: =DAYS360(K16,$C$1) -> 45024 | M16: =(I16/G16) -> #DIV/0! | R16: =Q16*0.93 -> 0 | T16: =Q16*1.25 -> 0 | U16: =Q16*1.5 -> 0 | V16: =Q16*2 -> 0 | W16: =H16-(H16*0.07) -> #DIV/0! | Y16: =(X16-H16)/H16 -> #DIV/0! | Z16: =F16/F$19 -> 0
A17: Sub-Total | F17: =SUM(F6:F16) -> 660917.09 | G17: =SUM(G6:G16) -> 535126.9 | I17: =SUM(I6:I16) -> 125790.19
D18: Cash, other | F18: 131016 | G18: =F18/F19 -> 0.16543822
D19: Total | F19: =SUM(F17:F18) -> 791933.09 | K19: Control acct (Doug's IRA) | M19: Today
H20: Last week's close | I20: ='01-17-25'!F19 -> 772583.22 | K20: 45657 | L20: 170762 | M20: 184611
H21: Week's change | I21: =(F19-I20)/I20 -> 0.025045669 | K21: chg % | L21: =(M20-L20)/L20 -> 0.081101182
M23: days
A24: 2025 Closed Trades - Managed Acct | D24: Qty | E24: Cost/sh | F24: $ cost | G24: $Proc | H24: Proc/sh | I24: Profit/loss | J24: % | K24: Date purch | L24: Date sold | M24: held | P24: Comments
A25: APH | B25: Long | C25: Amphenol | D25: 935.0369 | E25: =F25/D25 -> 72.335006 | F25: 67635.9 | G25: 64699.88 | H25: =G25/D25 -> 69.195002 | I25: =G25-F25 -> -2936.02 | J25: =I25/F25 -> -0.043409195 | K25: 45609 | L25: 45659 | M25: =DAYS360(K25,L25) -> 49
A26: SQ | B26: Long | C26: Block | D26: 653.8238 | E26: =F26/D26 -> 90.119203 | F26: 58922.08 | G26: 54094.08 | H26: =G26/D26 -> 82.734951 | I26: =G26-F26 -> -4828 | J26: =I26/F26 -> -0.081938723 | K26: 45660 | L26: 45667 | M26: =DAYS360(K26,L26) -> 7
I35: =SUM(I25:I34) -> -7764.02 | J35: Avg
H36: # of losses | I36: 2 | J36: -0.0627
H37: # of wins | I37: 0 | J37: 0

Sheet 01-31-25
C1: 45688
C3: MANAGED ACCT | X3: Current | AC3: IBD
H4: Cost | J4: P/L | N4: Group | P4: EPS | R4: pivot | S4: last | W4: cost | X4: Stop | Y4: Stop | Z4: % | AB4: EPS | AC4: Comp
A5: Symbol | B5: Position | C5: Name | D5: Qty | E5: Current | F5: Value | G5: Cost | H5: per share | I5: P/L $ | J5: per sh | K5: Date purch | L5: days held | M5: % incr | N5: Rank | O5: RS | P5: RS | Q5: pivot | R5: -0.07 | S5: low | T5: 0.25 | U5: 0.5 | V5: 1 | W5: -0.07 | X5: Loss | Y5: Loss% | Z5: of port | AB5: Due | AC5: Rank
A7: TILE | B7: Long | C7: Interface | D7: 3020.3486 | E7: 24.76 | F7: =E7*D7 -> 74783.831 | G7: 56486.59 | H7: =G7/D7 -> 18.70201 | I7: =F7-G7 -> 18297.241 | J7: =E7-H7 -> 6.0579899 | K7: 45527 | L7: =DAYS360(K7,$C$1) -> 158 | M7: =(I7/G7) -> 0.32392186 | N7: 84 | O7: 94 | P7: 85 | Q7: 17.86 | R7: =Q7*0.93 -> 16.6098 | S7: 22.11 | T7: =Q7*1.25 -> 22.325 | U7: =Q7*1.5 -> 26.79 | V7: =Q7*2 -> 35.72 | W7: =H7-(H7*0.07) -> 17.392869 | X7: 22 | Y7: =(X7-H7)/H7 -> 0.17634414 | Z7: =F7/F$19 -> 0.099120339 | AB7: 45720 | AC7: 89
A8: MSTR | B8: Long | C8: Microstrategy | D8: =341.2204-83.2121 -> 258.0083 | E8: 334.79 | F8: =E8*D8 -> 86378.599 | G8: =71012.62-17317.27 -> 53695.35 | H8: =G8/D8 -> 208.11482 | I8: =F8-G8 -> 32683.249 | J8: =E8-H8 -> 126.67518 | K8: 45580 | L8: =DAYS360(K8,$C$1) -> 106 | M8: =(I8/G8) -> 0.60867931 | N8: 26 | O8: 99 | P8: 5 | Q8: 183.7 | R8: =Q8*0.93 -> 170.841 | S8: 285.01 | T8: =Q8*1.25 -> 229.625 | U8: =Q8*1.5 -> 275.55 | V8: =Q8*2 -> 367.4 | W8: =H8-(H8*0.07) -> 193.54678 | X8: 335 | Y8: =(X8-H8)/H8 -> 0.60968837 | Z8: =F8/F$19 -> 0.11448833 | AB8: 45693 | AC8: 59
A9: IBIT | B9: Long | C9: iShares Bitcoin | D9: =939.2424+388.9544 -> 1328.1968 | E9: 57.71 | F9: =E9*D9 -> 76650.237 | G9: =36992.18+23418.77 -> 60410.95 | H9: =G9/D9 -> 45.483433 | I9: =F9-G9 -> 16239.287 | J9: =E9-H9 -> 12.226567 | K9: 45593 | L9: =DAYS360(K9,$C$1) -> 93 | M9: =(I9/G9) -> 0.26881364 | O9: 96 | P9: - | Q9: 61.08 | R9: =Q9*0.93 -> 56.8044 | S9: 51.54 | T9: =Q9*1.25 -> 76.35 | U9: =Q9*1.5 -> 91.62 | V9: =Q9*2 -> 122.16 | W9: =H9-(H9*0.07) -> 42.299593 | X9: 53 | Y9: =(X9-H9)/H9 -> 0.16525945 | Z9: =F9/F$19 -> 0.10159412
A10: AXGN | B10: Long | C10: Axogen | D10: 2234.6065 | E10: 18.21 | F10: =E10*D10 -> 40692.184 | G10: 37971.83 | H10: =G10/D10 -> 16.992625 | I10: =F10-G10 -> 2720.3544 | J10: =E10-H10 -> 1.2173751 | K10: 45652 | L10: =DAYS360(K10,$C$1) -> 35 | M10: =(I10/G10) -> 0.071641382 | N10: 44 | O10: 97 | P10: 81 | Q10: 15.9 | R10: =Q10*0.93 -> 14.787 | S10: 14 | T10: =Q10*1.25 -> 19.875 | U10: =Q10*1.5 -> 23.85 | V10: =Q10*2 -> 31.8 | W10: =H10-(H10*0.07) -> 15.803141 | X10: 15.65 | Y10: =(X10-H10)/H10 -> -0.079012212 | Z10: =F10/F$19 -> 0.053934427 | AB10: 45720 | AC10: 93
A11: OKLO | B11: Long | C11: Oklo | D11: 1255.3625 | E11: 41.61 | F11: =E11*D11 -> 52235.634 | G11: 37884.65 | H11: =G11/D11 -> 30.178255 | I11: =F11-G11 -> 14350.984 | J11: =E11-H11 -> 11.431745 | K11: 45663 | L11: =DAYS360(K11,$C$1) -> 25 | M11: =(I11/G11) -> 0.37880734 | N11: 2 | O11: 99 | P11: 7 | Q11: 24.99 | R11: =Q11*0.93 -> 23.2407 | S11: 29.06 | T11: =Q11*1.25 -> 31.2375 | U11: =Q11*1.5 -> 37.485 | V11: =Q11*2 -> 49.98 | W11: =H11-(H11*0.07) -> 28.065777 | X11: 32 | Y11: =(X11-H11)/H11 -> 0.060366138 | Z11: =F11/F$19 -> 0.0692344 | AB11: 45713 | AC11: 75
A12: GEV | B12: Long | C12: GE Vernova | D12: 201.9693 | E12: 372.88 | F12: =E12*D12 -> 75310.313 | G12: 74438.86 | H12: =G12/D12 -> 368.56522 | I12: =F12-G12 -> 871.45258 | J12: =E12-H12 -> 4.3147775 | K12: 45664 | L12: =DAYS360(K12,$C$1) -> 24 | M12: =(I12/G12) -> 0.011706958 | N12: 2 | O12: 97 | P12: 66 | Q12: 354.69 | R12: =Q12*0.93 -> 329.8617 | S12: 348.2 | T12: =Q12*1.25 -> 443.3625 | U12: =Q12*1.5 -> 532.035 | V12: =Q12*2 -> 709.38 | W12: =H12-(H12*0.07) -> 342.76566 | X12: 375 | Y12: =(X12-H12)/H12 -> 0.017458993 | Z12: =F12/F$19 -> 0.09981815 | AB12: 45771 | AC12: 93
A13: PSTG | B13: Long | C13: Pure Storage | D13: =675.2982+456.8207 -> 1132.1189 | E13: 67.79 | F13: =E13*D13 -> 76746.34 | G13: =45046.15+31240.53 -> 76286.68 | H13: =G13/D13 -> 67.383982 | I13: =F13-G13 -> 459.66023 | J13: =E13-H13 -> 0.40601763 | K13: 45673 | L13: =DAYS360(K13,$C$1) -> 15 | M13: =(I13/G13) -> 0.0060254324 | N13: 88 | O13: 91 | P13: 90 | Q13: 67.95 | R13: =Q13*0.93 -> 63.1935 | S13: 60.62 | T13: =Q13*1.25 -> 84.9375 | U13: =Q13*1.5 -> 101.925 | V13: =Q13*2 -> 135.9 | W13: =H13-(H13*0.07) -> 62.667104 | X13: 64 | Y13: =(X13-H13)/H13 -> -0.050219388 | Z13: =F13/F$19 -> 0.1017215 | AB13: 45714 | AC13: 90
F14: =E14*D14 -> 0 | H14: =G14/D14 -> #DIV/0! | I14: =F14-G14 -> 0 | J14: =E14-H14 -> #DIV/0! | L14: =DAYS360(K14,$C$1) -> 45031 | M14: =(I14/G14) -> #DIV/0! | R14: =Q14*0.93 -> 0 | T14: =Q14*1.25 -> 0 | U14: =Q14*1.5 -> 0 | V14: =Q14*2 -> 0 | W14: =H14-(H14*0.07) -> #DIV/0! | Y14: =(X14-H14)/H14 -> #DIV/0! | Z14: =F14/F$19 -> 0
F15: =E15*D15 -> 0 | H15: =G15/D15 -> #DIV/0! | I15: =F15-G15 -> 0 | J15: =E15-H15 -> #DIV/0! | L15: =DAYS360(K15,$C$1) -> 45031 | M15: =(I15/G15) -> #DIV/0! | R15: =Q15*0.93 -> 0 | T15: =Q15*1.25 -> 0 | U15: =Q15*1.5 -> 0 | V15: =Q15*2 -> 0 | W15: =H15-(H15*0.07) -> #DIV/0! | Y15: =(X15-H15)/H15 -> #DIV/0! | Z15: =F15/F$19 -> 0
F16: =E16*D16 -> 0 | H16: =G16/D16 -> #DIV/0! | I16: =F16-G16 -> 0 | J16: =E16-H16 -> #DIV/0! | L16: =DAYS360(K16,$C$1) -> 45031 | M16: =(I16/G16) -> #DIV/0! | R16: =Q16*0.93 -> 0 | T16: =Q16*1.25 -> 0 | U16: =Q16*1.5 -> 0 | V16: =Q16*2 -> 0 | W16: =H16-(H16*0.07) -> #DIV/0! | Y16: =(X16-H16)/H16 -> #DIV/0! | Z16: =F16/F$19 -> 0
A17: Sub-Total | F17: =SUM(F6:F16) -> 482797.14 | G17: =SUM(G6:G16) -> 397174.91 | I17: =SUM(I6:I16) -> 85622.228
D18: Cash, other | F18: 271678 | G18: =F18/F19 -> 0.36008874
D19: Total | F19: =SUM(F17:F18) -> 754475.14 | K19: Control acct (Doug's IRA) | M19: Today
H20: Last week's close | I20: ='01-24-25'!F19 -> 791933.09 | K20: 45657 | L20: 170762 | M20: 175345
H21: Week's change | I21: =(F19-I20)/I20 -> -0.047299388 | K21: chg % | L21: =(M20-L20)/L20 -> 0.026838524
M23: days
A24: 2025 Closed Trades - Managed Acct | D24: Qty | E24: Cost/sh | F24: $ cost | G24: $Proc | H24: Proc/sh | I24: Profit/loss | J24: % | K24: Date purch | L24: Date sold | M24: held | P24: Comments
A25: APH | B25: Long | C25: Amphenol | D25: 935.0369 | E25: =F25/D25 -> 72.335006 | F25: 67635.9 | G25: 64699.88 | H25: =G25/D25 -> 69.195002 | I25: =G25-F25 -> -2936.02 | J25: =I25/F25 -> -0.043409195 | K25: 45609 | L25: 45659 | M25: =DAYS360(K25,L25) -> 49
A26: SQ | B26: Long | C26: Block | D26: 653.8238 | E26: =F26/D26 -> 90.119203 | F26: 58922.08 | G26: 54094.08 | H26: =G26/D26 -> 82.734951 | I26: =G26-F26 -> -4828 | J26: =I26/F26 -> -0.081938723 | K26: 45660 | L26: 45667 | M26: =DAYS360(K26,L26) -> 7
A27: ONON | B27: Long | C27: On Holding | D27: 1263.7796 | E27: =F27/D27 -> 44.698791 | F27: 56489.42 | G27: 75501.87 | H27: =G27/D27 -> 59.742909 | I27: =G27-F27 -> 19012.45 | J27: =I27/F27 -> 0.33656656 | K27: 45527 | L27: 45688 | M27: =DAYS360(K27,L27) -> 158
A28: AGX | B28: Long | C28: Argan | D28: =347.7531+131.6951 -> 479.4482 | E28: =F28/D28 -> 169.90901 | F28: =59492.79+21969.78 -> 81462.57 | G28: 65047.58 | H28: =G28/D28 -> 135.67176 | I28: =G28-F28 -> -16414.99 | J28: =I28/F28 -> -0.20150346 | K28: 45671 | L28: 45688 | M28: =DAYS360(K28,L28) -> 17
I35: =SUM(I25:I34) -> -5166.56 | J35: Avg
H36: # of losses | I36: 3 | J36: -0.1089
H37: # of wins | I37: 1 | J37: 0.3366

Sheet 02-07-25
C1: 45695
C3: MANAGED ACCT | X3: Current | AC3: IBD
H4: Cost | J4: P/L | N4: Group | P4: EPS | R4: pivot | S4: last | W4: cost | X4: Stop | Y4: Stop | Z4: % | AB4: EPS | AC4: Comp
A5: Symbol | B5: Position | C5: Name | D5: Qty | E5: Current | F5: Value | G5: Cost | H5: per share | I5: P/L $ | J5: per sh | K5: Date purch | L5: days held | M5: % incr | N5: Rank | O5: RS | P5: RS | Q5: pivot | R5: -0.07 | S5: low | T5: 0.25 | U5: 0.5 | V5: 1 | W5: -0.07 | X5: Loss | Y5: Loss% | Z5: of port | AB5: Due | AC5: Rank
A7: MSTR | B7: Long | C7: Microstrategy | D7: =341.2204-83.2121 -> 258.0083 | E7: 327.56 | F7: =E7*D7 -> 84513.199 | G7: =71012.62-17317.27 -> 53695.35 | H7: =G7/D7 -> 208.11482 | I7: =F7-G7 -> 30817.849 | J7: =E7-H7 -> 119.44518 | K7: 45580 | L7: =DAYS360(K7,$C$1) -> 112 | M7: =(I7/G7) -> 0.57393887 | N7: 27 | O7: 98 | P7: 4 | Q7: 183.7 | R7: =Q7*0.93 -> 170.841 | S7: 285.01 | T7: =Q7*1.25 -> 229.625 | U7: =Q7*1.5 -> 275.55 | V7: =Q7*2 -> 367.4 | W7: =H7-(H7*0.07) -> 193.54678 | X7: 335 | Y7: =(X7-H7)/H7 -> 0.60968837 | Z7: =F7/F$19 -> 0.11029424 | AB7: 45783 | AC7: 55
A8: IBIT | B8: Long | C8: iShares Bitcoin | D8: =939.2424+388.9544 -> 1328.1968 | E8: 54.47 | F8: =E8*D8 -> 72346.88 | G8: =36992.18+23418.77 -> 60410.95 | H8: =G8/D8 -> 45.483433 | I8: =F8-G8 -> 11935.93 | J8: =E8-H8 -> 8.9865671 | K8: 45593 | L8: =DAYS360(K8,$C$1) -> 99 | M8: =(I8/G8) -> 0.19757891 | O8: 94 | P8: - | Q8: 61.08 | R8: =Q8*0.93 -> 56.8044 | S8: 51.54 | T8: =Q8*1.25 -> 76.35 | U8: =Q8*1.5 -> 91.62 | V8: =Q8*2 -> 122.16 | W8: =H8-(H8*0.07) -> 42.299593 | X8: 53 | Y8: =(X8-H8)/H8 -> 0.16525945 | Z8: =F8/F$19 -> 0.094416544
A9: AXGN | B9: Long | C9: Axogen | D9: 2234.6065 | E9: 17.96 | F9: =E9*D9 -> 40133.533 | G9: 37971.83 | H9: =G9/D9 -> 16.992625 | I9: =F9-G9 -> 2161.7027 | J9: =E9-H9 -> 0.96737512 | K9: 45652 | L9: =DAYS360(K9,$C$1) -> 41 | M9: =(I9/G9) -> 0.056929117 | N9: 51 | O9: 97 | P9: 80 | Q9: 15.9 | R9: =Q9*0.93 -> 14.787 | S9: 14 | T9: =Q9*1.25 -> 19.875 | U9: =Q9*1.5 -> 23.85 | V9: =Q9*2 -> 31.8 | W9: =H9-(H9*0.07) -> 15.803141 | X9: 15.65 | Y9: =(X9-H9)/H9 -> -0.079012212 | Z9: =F9/F$19 -> 0.052376405 | AB9: 45720 | AC9: 93
A10: OKLO | B10: Long | C10: Oklo | D10: 1255.3625 | E10: 55.49 | F10: =E10*D10 -> 69660.065 | G10: 37884.65 | H10: =G10/D10 -> 30.178255 | I10: =F10-G10 -> 31775.415 | J10: =E10-H10 -> 25.311745 | K10: 45663 | L10: =DAYS360(K10,$C$1) -> 31 | M10: =(I10/G10) -> 0.83874116 | N10: 3 | O10: 99 | P10: 7 | Q10: 24.99 | R10: =Q10*0.93 -> 23.2407 | S10: 29.06 | T10: =Q10*1.25 -> 31.2375 | U10: =Q10*1.5 -> 37.485 | V10: =Q10*2 -> 49.98 | W10: =H10-(H10*0.07) -> 28.065777 | X10: 39 | Y10: =(X10-H10)/H10 -> 0.29232123 | Z10: =F10/F$19 -> 0.090910107 | AB10: 45713 | AC10: 79
A11: GEV | B11: Long | C11: GE Vernova | D11: 201.9693 | E11: 377.97 | F11: =E11*D11 -> 76338.336 | G11: 74438.86 | H11: =G11/D11 -> 368.56522 | I11: =F11-G11 -> 1899.4763 | J11: =E11-H11 -> 9.4047775 | K11: 45664 | L11: =DAYS360(K11,$C$1) -> 30 | M11: =(I11/G11) -> 0.025517268 | N11: 3 | O11: 97 | P11: 67 | Q11: 354.69 | R11: =Q11*0.93 -> 329.8617 | S11: 348.2 | T11: =Q11*1.25 -> 443.3625 | U11: =Q11*1.5 -> 532.035 | V11: =Q11*2 -> 709.38 | W11: =H11-(H11*0.07) -> 342.76566 | X11: 375 | Y11: =(X11-H11)/H11 -> 0.017458993 | Z11: =F11/F$19 -> 0.099625608 | AB11: 45771 | AC11: 93
A12: PSTG | B12: Long | C12: Pure Storage | D12: =675.2982+456.8207 -> 1132.1189 | E12: 69.07 | F12: =E12*D12 -> 78195.452 | G12: =45046.15+31240.53 -> 76286.68 | H12: =G12/D12 -> 67.383982 | I12: =F12-G12 -> 1908.7724 | J12: =E12-H12 -> 1.6860176 | K12: 45673 | L12: =DAYS360(K12,$C$1) -> 21 | M12: =(I12/G12) -> 0.025021045 | N12: 110 | O12: 90 | P12: 90 | Q12: 67.95 | R12: =Q12*0.93 -> 63.1935 | S12: 60.62 | T12: =Q12*1.25 -> 84.9375 | U12: =Q12*1.5 -> 101.925 | V12: =Q12*2 -> 135.9 | W12: =H12-(H12*0.07) -> 62.667104 | X12: 64 | Y12: =(X12-H12)/H12 -> -0.050219388 | Z12: =F12/F$19 -> 0.10204924 | AB12: 45714 | AC12: 89
A13: MTRX | B13: Long | C13: Matrix Service | D13: 1628.6374 | E13: 14.18 | F13: =E13*D13 -> 23094.078 | G13: 22621.18 | H13: =G13/D13 -> 13.889636 | I13: =F13-G13 -> 472.89833 | J13: =E13-H13 -> 0.29036441 | K13: 45692 | L13: =DAYS360(K13,$C$1) -> 3 | M13: =(I13/G13) -> 0.020905113 | N13: 73 | O13: 87 | P13: 10 | Q13: 13.58 | R13: =Q13*0.93 -> 12.6294 | S13: 13 | T13: =Q13*1.25 -> 16.975 | U13: =Q13*1.5 -> 20.37 | V13: =Q13*2 -> 27.16 | W13: =H13-(H13*0.07) -> 12.917361 | X13: 13 | Y13: =(X13-H13)/H13 -> -0.064050319 | Z13: =F13/F$19 -> 0.030139006 | AB13: 45784 | AC13: 56
A14: FTNT | B14: Long | C14: Fortinet | D14: 440.0298 | E14: 107.66 | F14: =E14*D14 -> 47373.608 | G14: 46412.71 | H14: =G14/D14 -> 105.47629 | I14: =F14-G14 -> 960.89827 | J14: =E14-H14 -> 2.1837118 | K14: 45695 | L14: =DAYS360(K14,$C$1) -> 0 | M14: =(I14/G14) -> 0.020703343 | N14: 31 | O14: 93 | P14: 99 | Q14: 101 | R14: =Q14*0.93 -> 93.93 | S14: 94.1 | T14: =Q14*1.25 -> 126.25 | U14: =Q14*1.5 -> 151.5 | V14: =Q14*2 -> 202 | W14: =H14-(H14*0.07) -> 98.092948 | X14: 99 | Y14: =(X14-H14)/H14 -> -0.061400418 | Z14: =F14/F$19 -> 0.06182509 | AB14: 45778 | AC14: 99
F15: =E15*D15 -> 0 | H15: =G15/D15 -> #DIV/0! | I15: =F15-G15 -> 0 | J15: =E15-H15 -> #DIV/0! | L15: =DAYS360(K15,$C$1) -> 45037 | M15: =(I15/G15) -> #DIV/0! | R15: =Q15*0.93 -> 0 | T15: =Q15*1.25 -> 0 | U15: =Q15*1.5 -> 0 | V15: =Q15*2 -> 0 | W15: =H15-(H15*0.07) -> #DIV/0! | Y15: =(X15-H15)/H15 -> #DIV/0! | Z15: =F15/F$19 -> 0
F16: =E16*D16 -> 0 | H16: =G16/D16 -> #DIV/0! | I16: =F16-G16 -> 0 | J16: =E16-H16 -> #DIV/0! | L16: =DAYS360(K16,$C$1) -> 45037 | M16: =(I16/G16) -> #DIV/0! | R16: =Q16*0.93 -> 0 | T16: =Q16*1.25 -> 0 | U16: =Q16*1.5 -> 0 | V16: =Q16*2 -> 0 | W16: =H16-(H16*0.07) -> #DIV/0! | Y16: =(X16-H16)/H16 -> #DIV/0! | Z16: =F16/F$19 -> 0
A17: Sub-Total | F17: =SUM(F6:F16) -> 491655.15 | G17: =SUM(G6:G16) -> 409722.21 | I17: =SUM(I6:I16) -> 81932.942
D18: Cash, other | F18: 274597 | G18: =F18/F19 -> 0.35836376
D19: Total | F19: =SUM(F17:F18) -> 766252.15 | K19: Control acct (Doug's IRA) | M19: Today
H20: Last week's close | I20: ='01-31-25'!F19 -> 754475.14 | K20: 45657 | L20: 170762 | M20: 178244
H21: Week's change | I21: =(F19-I20)/I20 -> 0.015609545 | K21: chg % | L21: =(M20-L20)/L20 -> 0.043815369
M23: days
A24: 2025 Closed Trades - Managed Acct | D24: Qty | E24: Cost/sh | F24: $ cost | G24: $Proc | H24: Proc/sh | I24: Profit/loss | J24: % | K24: Date purch | L24: Date sold | M24: held | P24: Comments
A25: APH | B25: Long | C25: Amphenol | D25: 935.0369 | E25: =F25/D25 -> 72.335006 | F25: 67635.9 | G25: 64699.88 | H25: =G25/D25 -> 69.195002 | I25: =G25-F25 -> -2936.02 | J25: =I25/F25 -> -0.043409195 | K25: 45609 | L25: 45659 | M25: =DAYS360(K25,L25) -> 49
A26: SQ | B26: Long | C26: Block | D26: 653.8238 | E26: =F26/D26 -> 90.119203 | F26: 58922.08 | G26: 54094.08 | H26: =G26/D26 -> 82.734951 | I26: =G26-F26 -> -4828 | J26: =I26/F26 -> -0.081938723 | K26: 45660 | L26: 45667 | M26: =DAYS360(K26,L26) -> 7
A27: ONON | B27: Long | C27: On Holding | D27: 1263.7796 | E27: =F27/D27 -> 44.698791 | F27: 56489.42 | G27: 75501.87 | H27: =G27/D27 -> 59.742909 | I27: =G27-F27 -> 19012.45 | J27: =I27/F27 -> 0.33656656 | K27: 45527 | L27: 45688 | M27: =DAYS360(K27,L27) -> 158
A28: AGX | B28: Long | C28: Argan | D28: =347.7531+131.6951 -> 479.4482 | E28: =F28/D28 -> 169.90901 | F28: =59492.79+21969.78 -> 81462.57 | G28: 65047.58 | H28: =G28/D28 -> 135.67176 | I28: =G28-F28 -> -16414.99 | J28: =I28/F28 -> -0.20150346 | K28: 45671 | L28: 45688 | M28: =DAYS360(K28,L28) -> 17
A29: TILE | B29: Long | C29: Interface | D29: 3020.3486 | E29: =F29/D29 -> 18.70201 | F29: 56486.59 | G29: 71124.88 | H29: =G29/D29 -> 23.548567 | I29: =G29-F29 -> 14638.29 | J29: =I29/F29 -> 0.25914629 | K29: 45527 | L29: 45691 | M29: =DAYS360(K29,L29) -> 160
I35: =SUM(I25:I34) -> 9471.73 | J35: Avg
H36: # of losses | I36: 3 | J36: -0.1089
H37: # of wins | I37: 2 | J37: 0.2979

Sheet 02-14-25
C1: 45702
C3: MANAGED ACCT | X3: Current | AC3: IBD
H4: Cost | J4: P/L | N4: Group | P4: EPS | R4: pivot | S4: last | W4: cost | X4: Stop | Y4: Stop | Z4: % | AB4: EPS | AC4: Comp
A5: Symbol | B5: Position | C5: Name | D5: Qty | E5: Current | F5: Value | G5: Cost | H5: per share | I5: P/L $ | J5: per sh | K5: Date purch | L5: days held | M5: % incr | N5: Rank | O5: RS | P5: RS | Q5: pivot | R5: -0.07 | S5: low | T5: 0.25 | U5: 0.5 | V5: 1 | W5: -0.07 | X5: Loss | Y5: Loss% | Z5: of port | AB5: Due | AC5: Rank
A7: MSTR | B7: Long | C7: Microstrategy | D7: =341.2204-83.2121 -> 258.0083 | E7: 339.51 | F7: =E7*D7 -> 87596.398 | G7: =71012.62-17317.27 -> 53695.35 | H7: =G7/D7 -> 208.11482 | I7: =F7-G7 -> 33901.048 | J7: =E7-H7 -> 131.39518 | K7: 45580 | L7: =DAYS360(K7,$C$1) -> 119 | M7: =(I7/G7) -> 0.6313591 | N7: 26 | O7: 98 | P7: 5 | Q7: 183.7 | R7: =Q7*0.93 -> 170.841 | S7: 285.01 | T7: =Q7*1.25 -> 229.625 | U7: =Q7*1.5 -> 275.55 | V7: =Q7*2 -> 367.4 | W7: =H7-(H7*0.07) -> 193.54678 | X7: 335 | Y7: =(X7-H7)/H7 -> 0.60968837 | Z7: =F7/F$19 -> 0.1143349 | AB7: 45783 | AC7: 55
A8: IBIT | B8: Long | C8: iShares Bitcoin | D8: =939.2424+388.9544 -> 1328.1968 | E8: 55.33 | F8: =E8*D8 -> 73489.129 | G8: =36992.18+23418.77 -> 60410.95 | H8: =G8/D8 -> 45.483433 | I8: =F8-G8 -> 13078.179 | J8: =E8-H8 -> 9.8465671 | K8: 45593 | L8: =DAYS360(K8,$C$1) -> 106 | M8: =(I8/G8) -> 0.21648689 | O8: 93 | P8: - | Q8: 61.08 | R8: =Q8*0.93 -> 56.8044 | S8: 51.54 | T8: =Q8*1.25 -> 76.35 | U8: =Q8*1.5 -> 91.62 | V8: =Q8*2 -> 122.16 | W8: =H8-(H8*0.07) -> 42.299593 | X8: 53 | Y8: =(X8-H8)/H8 -> 0.16525945 | Z8: =F8/F$19 -> 0.095921439
A9: AXGN | B9: Long | C9: Axogen | D9: 2234.6065 | E9: 18.13 | F9: =E9*D9 -> 40513.416 | G9: 37971.83 | H9: =G9/D9 -> 16.992625 | I9: =F9-G9 -> 2541.5858 | J9: =E9-H9 -> 1.1373751 | K9: 45652 | L9: =DAYS360(K9,$C$1) -> 48 | M9: =(I9/G9) -> 0.066933457 | N9: 62 | O9: 97 | P9: 81 | Q9: 15.9 | R9: =Q9*0.93 -> 14.787 | S9: 14 | T9: =Q9*1.25 -> 19.875 | U9: =Q9*1.5 -> 23.85 | V9: =Q9*2 -> 31.8 | W9: =H9-(H9*0.07) -> 15.803141 | X9: 15.65 | Y9: =(X9-H9)/H9 -> -0.079012212 | Z9: =F9/F$19 -> 0.05288 | AB9: 45713 | AC9: 94
A10: OKLO | B10: Long | C10: Oklo | D10: 1255.3625 | E10: 52.62 | F10: =E10*D10 -> 66057.175 | G10: 37884.65 | H10: =G10/D10 -> 30.178255 | I10: =F10-G10 -> 28172.525 | J10: =E10-H10 -> 22.441745 | K10: 45663 | L10: =DAYS360(K10,$C$1) -> 38 | M10: =(I10/G10) -> 0.74363957 | N10: 1 | O10: 99 | P10: 7 | Q10: 24.99 | R10: =Q10*0.93 -> 23.2407 | S10: 29.06 | T10: =Q10*1.25 -> 31.2375 | U10: =Q10*1.5 -> 37.485 | V10: =Q10*2 -> 49.98 | W10: =H10-(H10*0.07) -> 28.065777 | X10: 39 | Y10: =(X10-H10)/H10 -> 0.29232123 | Z10: =F10/F$19 -> 0.086220906 | AB10: 45713 | AC10: 78
A11: GEV | B11: Long | C11: GE Vernova | D11: 201.9693 | E11: 367.59 | F11: =E11*D11 -> 74241.895 | G11: 74438.86 | H11: =G11/D11 -> 368.56522 | I11: =F11-G11 -> -196.96501 | J11: =E11-H11 -> -0.97522254 | K11: 45664 | L11: =DAYS360(K11,$C$1) -> 37 | M11: =(I11/G11) -> -0.0026459972 | N11: 1 | O11: 97 | P11: 67 | Q11: 354.69 | R11: =Q11*0.93 -> 329.8617 | S11: 348.2 | T11: =Q11*1.25 -> 443.3625 | U11: =Q11*1.5 -> 532.035 | V11: =Q11*2 -> 709.38 | W11: =H11-(H11*0.07) -> 342.76566 | X11: 375 | Y11: =(X11-H11)/H11 -> 0.017458993 | Z11: =F11/F$19 -> 0.096903985 | AB11: 45771 | AC11: 93
A12: PSTG | B12: Long | C12: Pure Storage | D12: =675.2982+456.8207 -> 1132.1189 | E12: 67.8 | F12: =E12*D12 -> 76757.661 | G12: =45046.15+31240.53 -> 76286.68 | H12: =G12/D12 -> 67.383982 | I12: =F12-G12 -> 470.98142 | J12: =E12-H12 -> 0.41601763 | K12: 45673 | L12: =DAYS360(K12,$C$1) -> 28 | M12: =(I12/G12) -> 0.0061738356 | N12: 120 | O12: 90 | P12: 90 | Q12: 67.95 | R12: =Q12*0.93 -> 63.1935 | S12: 60.62 | T12: =Q12*1.25 -> 84.9375 | U12: =Q12*1.5 -> 101.925 | V12: =Q12*2 -> 135.9 | W12: =H12-(H12*0.07) -> 62.667104 | X12: 64 | Y12: =(X12-H12)/H12 -> -0.050219388 | Z12: =F12/F$19 -> 0.10018768 | AB12: 45714 | AC12: 87
A13: MTRX | B13: Long | C13: Matrix Service | D13: 1628.6374 | E13: 15.2 | F13: =E13*D13 -> 24755.288 | G13: 22621.18 | H13: =G13/D13 -> 13.889636 | I13: =F13-G13 -> 2134.1085 | J13: =E13-H13 -> 1.3103644 | K13: 45692 | L13: =DAYS360(K13,$C$1) -> 10 | M13: =(I13/G13) -> 0.094341165 | N13: 53 | O13: 90 | P13: 10 | Q13: 13.58 | R13: =Q13*0.93 -> 12.6294 | S13: 13 | T13: =Q13*1.25 -> 16.975 | U13: =Q13*1.5 -> 20.37 | V13: =Q13*2 -> 27.16 | W13: =H13-(H13*0.07) -> 12.917361 | X13: 13 | Y13: =(X13-H13)/H13 -> -0.064050319 | Z13: =F13/F$19 -> 0.032311757 | AB13: 45784 | AC13: 63
A14: FTNT | B14: Long | C14: Fortinet | D14: 440.0298 | E14: 111.64 | F14: =E14*D14 -> 49124.927 | G14: 46412.71 | H14: =G14/D14 -> 105.47629 | I14: =F14-G14 -> 2712.2169 | J14: =E14-H14 -> 6.1637118 | K14: 45695 | L14: =DAYS360(K14,$C$1) -> 7 | M14: =(I14/G14) -> 0.058436943 | N14: 22 | O14: 93 | P14: 99 | Q14: 101 | R14: =Q14*0.93 -> 93.93 | S14: 94.1 | T14: =Q14*1.25 -> 126.25 | U14: =Q14*1.5 -> 151.5 | V14: =Q14*2 -> 202 | W14: =H14-(H14*0.07) -> 98.092948 | X14: 99 | Y14: =(X14-H14)/H14 -> -0.061400418 | Z14: =F14/F$19 -> 0.064120146 | AB14: 45778 | AC14: 99
A15: DKS | B15: Long | C15: Dicks | D15: 252.7011 | E15: 238.36 | F15: =E15*D15 -> 60233.834 | G15: 61221.72 | H15: =G15/D15 -> 242.26931 | I15: =F15-G15 -> -987.8858 | J15: =E15-H15 -> -3.9093055 | K15: 45699 | L15: =DAYS360(K15,$C$1) -> 3 | M15: =(I15/G15) -> -0.016136198 | N15: 137 | O15: 85 | P15: 88 | Q15: 235.16 | R15: =Q15*0.93 -> 218.6988 | S15: 228.77 | T15: =Q15*1.25 -> 293.95 | U15: =Q15*1.5 -> 352.74 | V15: =Q15*2 -> 470.32 | W15: =H15-(H15*0.07) -> 225.31045 | X15: 228.5 | Y15: =(X15-H15)/H15 -> -0.056834709 | Z15: =F15/F$19 -> 0.07862001 | AB15: 45727 | AC15: 82
F16: =E16*D16 -> 0 | H16: =G16/D16 -> #DIV/0! | I16: =F16-G16 -> 0 | J16: =E16-H16 -> #DIV/0! | L16: =DAYS360(K16,$C$1) -> 45044 | M16: =(I16/G16) -> #DIV/0! | R16: =Q16*0.93 -> 0 | T16: =Q16*1.25 -> 0 | U16: =Q16*1.5 -> 0 | V16: =Q16*2 -> 0 | W16: =H16-(H16*0.07) -> #DIV/0! | Y16: =(X16-H16)/H16 -> #DIV/0! | Z16: =F16/F$19 -> 0
A17: Sub-Total | F17: =SUM(F6:F16) -> 552769.72 | G17: =SUM(G6:G16) -> 470943.93 | I17: =SUM(I6:I16) -> 81825.793
D18: Cash, other | F18: 213369 | G18: =F18/F19 -> 0.27849917
D19: Total | F19: =SUM(F17:F18) -> 766138.72 | K19: Control acct (Doug's IRA) | M19: Today
H20: Last week's close | I20: ='02-07-25'!F19 -> 766252.15 | K20: 45657 | L20: 170762 | M20: 178205
H21: Week's change | I21: =(F19-I20)/I20 -> -0.0001480299 | K21: chg % | L21: =(M20-L20)/L20 -> 0.043586981
M23: days
A24: 2025 Closed Trades - Managed Acct | D24: Qty | E24: Cost/sh | F24: $ cost | G24: $Proc | H24: Proc/sh | I24: Profit/loss | J24: % | K24: Date purch | L24: Date sold | M24: held | P24: Comments
A25: APH | B25: Long | C25: Amphenol | D25: 935.0369 | E25: =F25/D25 -> 72.335006 | F25: 67635.9 | G25: 64699.88 | H25: =G25/D25 -> 69.195002 | I25: =G25-F25 -> -2936.02 | J25: =I25/F25 -> -0.043409195 | K25: 45609 | L25: 45659 | M25: =DAYS360(K25,L25) -> 49
A26: SQ | B26: Long | C26: Block | D26: 653.8238 | E26: =F26/D26 -> 90.119203 | F26: 58922.08 | G26: 54094.08 | H26: =G26/D26 -> 82.734951 | I26: =G26-F26 -> -4828 | J26: =I26/F26 -> -0.081938723 | K26: 45660 | L26: 45667 | M26: =DAYS360(K26,L26) -> 7
A27: ONON | B27: Long | C27: On Holding | D27: 1263.7796 | E27: =F27/D27 -> 44.698791 | F27: 56489.42 | G27: 75501.87 | H27: =G27/D27 -> 59.742909 | I27: =G27-F27 -> 19012.45 | J27: =I27/F27 -> 0.33656656 | K27: 45527 | L27: 45688 | M27: =DAYS360(K27,L27) -> 158
A28: AGX | B28: Long | C28: Argan | D28: =347.7531+131.6951 -> 479.4482 | E28: =F28/D28 -> 169.90901 | F28: =59492.79+21969.78 -> 81462.57 | G28: 65047.58 | H28: =G28/D28 -> 135.67176 | I28: =G28-F28 -> -16414.99 | J28: =I28/F28 -> -0.20150346 | K28: 45671 | L28: 45688 | M28: =DAYS360(K28,L28) -> 17
A29: TILE | B29: Long | C29: Interface | D29: 3020.3486 | E29: =F29/D29 -> 18.70201 | F29: 56486.59 | G29: 71124.88 | H29: =G29/D29 -> 23.548567 | I29: =G29-F29 -> 14638.29 | J29: =I29/F29 -> 0.25914629 | K29: 45527 | L29: 45691 | M29: =DAYS360(K29,L29) -> 160
I35: =SUM(I25:I34) -> 9471.73 | J35: Avg
H36: # of losses | I36: 3 | J36: -0.1089
H37: # of wins | I37: 2 | J37: 0.2979

Sheet 02-21-25
C1: 45709
C3: MANAGED ACCT | X3: Current | AC3: IBD
H4: Cost | J4: P/L | N4: Group | P4: EPS | R4: pivot | S4: last | W4: cost | X4: Stop | Y4: Stop | Z4: % | AB4: EPS | AC4: Comp
A5: Symbol | B5: Position | C5: Name | D5: Qty | E5: Current | F5: Value | G5: Cost | H5: per share | I5: P/L $ | J5: per sh | K5: Date purch | L5: days held | M5: % incr | N5: Rank | O5: RS | P5: RS | Q5: pivot | R5: -0.07 | S5: low | T5: 0.25 | U5: 0.5 | V5: 1 | W5: -0.07 | X5: Loss | Y5: Loss% | Z5: of port | AB5: Due | AC5: Rank
A7: MSTR | B7: Long | C7: Microstrategy | D7: =341.2204-83.2121 -> 258.0083 | E7: 299.69 | F7: =E7*D7 -> 77322.507 | G7: =71012.62-17317.27 -> 53695.35 | H7: =G7/D7 -> 208.11482 | I7: =F7-G7 -> 23627.157 | J7: =E7-H7 -> 91.575184 | K7: 45580 | L7: =DAYS360(K7,$C$1) -> 126 | M7: =(I7/G7) -> 0.44002241 | N7: 27 | O7: 98 | P7: 5 | Q7: 183.7 | R7: =Q7*0.93 -> 170.841 | S7: 285.01 | T7: =Q7*1.25 -> 229.625 | U7: =Q7*1.5 -> 275.55 | V7: =Q7*2 -> 367.4 | W7: =H7-(H7*0.07) -> 193.54678 | X7: 335 | Y7: =(X7-H7)/H7 -> 0.60968837 | Z7: =F7/F$20 -> 0.11083135 | AB7: 45783 | AC7: 53
A8: IBIT | B8: Long | C8: iShares Bitcoin | D8: =939.2424+388.9544 -> 1328.1968 | E8: 53.91 | F8: =E8*D8 -> 71603.089 | G8: =36992.18+23418.77 -> 60410.95 | H8: =G8/D8 -> 45.483433 | I8: =F8-G8 -> 11192.139 | J8: =E8-H8 -> 8.4265671 | K8: 45593 | L8: =DAYS360(K8,$C$1) -> 113 | M8: =(I8/G8) -> 0.18526674 | O8: 93 | P8: - | Q8: 61.08 | R8: =Q8*0.93 -> 56.8044 | S8: 51.54 | T8: =Q8*1.25 -> 76.35 | U8: =Q8*1.5 -> 91.62 | V8: =Q8*2 -> 122.16 | W8: =H8-(H8*0.07) -> 42.299593 | X8: 53 | Y8: =(X8-H8)/H8 -> 0.16525945 | Z8: =F8/F$20 -> 0.10263334
A9: AXGN | B9: Long | C9: Axogen | D9: 2234.6065 | E9: 18 | F9: =E9*D9 -> 40222.917 | G9: 37971.83 | H9: =G9/D9 -> 16.992625 | I9: =F9-G9 -> 2251.087 | J9: =E9-H9 -> 1.0073751 | K9: 45652 | L9: =DAYS360(K9,$C$1) -> 55 | M9: =(I9/G9) -> 0.059283079 | N9: 54 | O9: 97 | P9: 81 | Q9: 15.9 | R9: =Q9*0.93 -> 14.787 | S9: 14 | T9: =Q9*1.25 -> 19.875 | U9: =Q9*1.5 -> 23.85 | V9: =Q9*2 -> 31.8 | W9: =H9-(H9*0.07) -> 15.803141 | X9: 15.65 | Y9: =(X9-H9)/H9 -> -0.079012212 | Z9: =F9/F$20 -> 0.05765411 | AB9: 45713 | AC9: 94
A10: PSTG | B10: Long | C10: Pure Storage | D10: =675.2982+456.8207 -> 1132.1189 | E10: 65.07 | F10: =E10*D10 -> 73666.977 | G10: =45046.15+31240.53 -> 76286.68 | H10: =G10/D10 -> 67.383982 | I10: =F10-G10 -> -2619.7032 | J10: =E10-H10 -> -2.3139824 | K10: 45673 | L10: =DAYS360(K10,$C$1) -> 35 | M10: =(I10/G10) -> -0.034340244 | N10: 116 | O10: 90 | P10: 90 | Q10: 67.95 | R10: =Q10*0.93 -> 63.1935 | S10: 60.62 | T10: =Q10*1.25 -> 84.9375 | U10: =Q10*1.5 -> 101.925 | V10: =Q10*2 -> 135.9 | W10: =H10-(H10*0.07) -> 62.667104 | X10: 64 | Y10: =(X10-H10)/H10 -> -0.050219388 | Z10: =F10/F$20 -> 0.10559164 | AB10: 45714 | AC10: 88
A11: MTRX | B11: Long | C11: Matrix Service | D11: 1628.6374 | E11: 13.08 | F11: =E11*D11 -> 21302.577 | G11: 22621.18 | H11: =G11/D11 -> 13.889636 | I11: =F11-G11 -> -1318.6028 | J11: =E11-H11 -> -0.80963559 | K11: 45692 | L11: =DAYS360(K11,$C$1) -> 17 | M11: =(I11/G11) -> -0.058290629 | N11: 61 | O11: 86 | P11: 10 | Q11: 13.58 | R11: =Q11*0.93 -> 12.6294 | S11: 13 | T11: =Q11*1.25 -> 16.975 | U11: =Q11*1.5 -> 20.37 | V11: =Q11*2 -> 27.16 | W11: =H11-(H11*0.07) -> 12.917361 | X11: 13 | Y11: =(X11-H11)/H11 -> -0.064050319 | Z11: =F11/F$20 -> 0.030534362 | AB11: 45784 | AC11: 60
A12: FTNT | B12: Long | C12: Fortinet | D12: 440.0298 | E12: 110.02 | F12: =E12*D12 -> 48412.079 | G12: 46412.71 | H12: =G12/D12 -> 105.47629 | I12: =F12-G12 -> 1999.3686 | J12: =E12-H12 -> 4.5437118 | K12: 45695 | L12: =DAYS360(K12,$C$1) -> 14 | M12: =(I12/G12) -> 0.04307804 | N12: 28 | O12: 95 | P12: 99 | Q12: 101 | R12: =Q12*0.93 -> 93.93 | S12: 94.1 | T12: =Q12*1.25 -> 126.25 | U12: =Q12*1.5 -> 151.5 | V12: =Q12*2 -> 202 | W12: =H12-(H12*0.07) -> 98.092948 | X12: 99 | Y12: =(X12-H12)/H12 -> -0.061400418 | Z12: =F12/F$20 -> 0.069392165 | AB12: 45778 | AC12: 99
F13: =E13*D13 -> 0 | H13: =G13/D13 -> #DIV/0! | I13: =F13-G13 -> 0 | J13: =E13-H13 -> #DIV/0! | L13: =DAYS360(K13,$C$1) -> 45051 | M13: =(I13/G13) -> #DIV/0! | R13: =Q13*0.93 -> 0 | T13: =Q13*1.25 -> 0 | U13: =Q13*1.5 -> 0 | V13: =Q13*2 -> 0 | W13: =H13-(H13*0.07) -> #DIV/0! | Y13: =(X13-H13)/H13 -> #DIV/0! | Z13: =F13/F$20 -> 0
F14: =E14*D14 -> 0 | H14: =G14/D14 -> #DIV/0! | I14: =F14-G14 -> 0 | J14: =E14-H14 -> #DIV/0! | L14: =DAYS360(K14,$C$1) -> 45051 | M14: =(I14/G14) -> #DIV/0! | R14: =Q14*0.93 -> 0 | T14: =Q14*1.25 -> 0 | U14: =Q14*1.5 -> 0 | V14: =Q14*2 -> 0 | W14: =H14-(H14*0.07) -> #DIV/0! | Y14: =(X14-H14)/H14 -> #DIV/0! | Z14: =F14/F$20 -> 0
F15: =E15*D15 -> 0 | H15: =G15/D15 -> #DIV/0! | I15: =F15-G15 -> 0 | J15: =E15-H15 -> #DIV/0! | L15: =DAYS360(K15,$C$1) -> 45051 | M15: =(I15/G15) -> #DIV/0! | R15: =Q15*0.93 -> 0 | T15: =Q15*1.25 -> 0 | U15: =Q15*1.5 -> 0 | V15: =Q15*2 -> 0 | W15: =H15-(H15*0.07) -> #DIV/0! | Y15: =(X15-H15)/H15 -> #DIV/0! | Z15: =F15/F$20 -> 0
F16: =E16*D16 -> 0 | H16: =G16/D16 -> #DIV/0! | I16: =F16-G16 -> 0 | J16: =E16-H16 -> #DIV/0! | L16: =DAYS360(K16,$C$1) -> 45051 | M16: =(I16/G16) -> #DIV/0! | R16: =Q16*0.93 -> 0 | T16: =Q16*1.25 -> 0 | U16: =Q16*1.5 -> 0 | V16: =Q16*2 -> 0 | W16: =H16-(H16*0.07) -> #DIV/0! | Y16: =(X16-H16)/H16 -> #DIV/0! | Z16: =F16/F$20 -> 0
F17: =E17*D17 -> 0 | H17: =G17/D17 -> #DIV/0! | I17: =F17-G17 -> 0 | J17: =E17-H17 -> #DIV/0! | L17: =DAYS360(K17,$C$1) -> 45051 | M17: =(I17/G17) -> #DIV/0! | R17: =Q17*0.93 -> 0 | T17: =Q17*1.25 -> 0 | U17: =Q17*1.5 -> 0 | V17: =Q17*2 -> 0 | W17: =H17-(H17*0.07) -> #DIV/0! | Y17: =(X17-H17)/H17 -> #DIV/0! | Z17: =F17/F$20 -> 0
A18: Sub-Total | F18: =SUM(F6:F17) -> 332530.15 | G18: =SUM(G6:G17) -> 297398.7 | I18: =SUM(I6:I17) -> 35131.447
D19: Cash, other | F19: 365129 | G19: =F19/F20 -> 0.52336302
D20: Total | F20: =SUM(F18:F19) -> 697659.15 | K20: Control acct (Doug's IRA) | M20: Today
H21: Last week's close | I21: ='02-14-25'!F19 -> 766138.72 | K21: 45657 | L21: 170762 | M21: 162281
H22: Week's change | I22: =(F20-I21)/I21 -> -0.089382738 | K22: chg % | L22: =(M21-L21)/L21 -> -0.049665616
M24: days
A25: 2025 Closed Trades - Managed Acct | D25: Qty | E25: Cost/sh | F25: $ cost | G25: $Proc | H25: Proc/sh | I25: Profit/loss | J25: % | K25: Date purch | L25: Date sold | M25: held | P25: Comments (Close on Feb 21) | S25: chg from sale
A26: APH | B26: Long | C26: Amphenol | D26: 935.0369 | E26: =F26/D26 -> 72.335006 | F26: 67635.9 | G26: 64699.88 | H26: =G26/D26 -> 69.195002 | I26: =G26-F26 -> -2936.02 | J26: =I26/F26 -> -0.043409195 | K26: 45609 | L26: 45659 | M26: =DAYS360(K26,L26) -> 49 | Q26: 67.58 | S26: =(Q26-H26)/H26 -> -0.023339862
A27: SQ | B27: Long | C27: Block | D27: 653.8238 | E27: =F27/D27 -> 90.119203 | F27: 58922.08 | G27: 54094.08 | H27: =G27/D27 -> 82.734951 | I27: =G27-F27 -> -4828 | J27: =I27/F27 -> -0.081938723 | K27: 45660 | L27: 45667 | M27: =DAYS360(K27,L27) -> 7 | Q27: 68.35 | S27: =(Q27-H27)/H27 -> -0.17386788
A28: ONON | B28: Long | C28: On Holding | D28: 1263.7796 | E28: =F28/D28 -> 44.698791 | F28: 56489.42 | G28: 75501.87 | H28: =G28/D28 -> 59.742909 | I28: =G28-F28 -> 19012.45 | J28: =I28/F28 -> 0.33656656 | K28: 45527 | L28: 45688 | M28: =DAYS360(K28,L28) -> 158 | Q28: 48.44 | S28: =(Q28-H28)/H28 -> -0.18919248
A29: AGX | B29: Long | C29: Argan | D29: =347.7531+131.6951 -> 479.4482 | E29: =F29/D29 -> 169.90901 | F29: =59492.79+21969.78 -> 81462.57 | G29: 65047.58 | H29: =G29/D29 -> 135.67176 | I29: =G29-F29 -> -16414.99 | J29: =I29/F29 -> -0.20150346 | K29: 45671 | L29: 45688 | M29: =DAYS360(K29,L29) -> 17 | Q29: 133.63 | S29: =(Q29-H29)/H29 -> -0.015049246
A30: TILE | B30: Long | C30: Interface | D30: 3020.3486 | E30: =F30/D30 -> 18.70201 | F30: 56486.59 | G30: 71124.88 | H30: =G30/D30 -> 23.548567 | I30: =G30-F30 -> 14638.29 | J30: =I30/F30 -> 0.25914629 | K30: 45527 | L30: 45691 | M30: =DAYS360(K30,L30) -> 160 | Q30: 21.48 | S30: =(Q30-H30)/H30 -> -0.087842567
A31: TOST | B31: Long | C31: Toast | D31: 1436.8459 | E31: =F31/D31 -> 42.502492 | F31: =1436.8459*42.5024916 -> 61069.531 | G31: =1436.8459*38.249853 -> 54959.144 | H31: =G31/D31 -> 38.249853 | I31: =G31-F31 -> -6110.3863 | J31: =I31/F31 -> -0.10005622 | K31: 45706 | L31: 45708 | M31: =DAYS360(K31,L31) -> 2 | Q31: 37.7 | S31: =(Q31-H31)/H31 -> -0.014375297
A32: AXON | B32: Long | C32: Axon Enterprises | D32: 130.6907 | E32: =F32/D32 -> 701.32489 | F32: =130.6907*701.324893 -> 91656.641 | G32: =130.6907*531.6399528 -> 69480.398 | H32: =G32/D32 -> 531.63995 | I32: =G32-F32 -> -22176.244 | J32: =I32/F32 -> -0.24194912 | K32: 45706 | L32: 45708 | M32: =DAYS360(K32,L32) -> 2 | Q32: 513.22 | S32: =(Q32-H32)/H32 -> -0.03464742
