Workbook

Sheet 06-30-23
C1: 45107
C3: MANAGED ACCT | X3: Current | AC3: IBD
H4: Cost | J4: P/L | N4: Group | P4: EPS | R4: pivot | S4: last | W4: cost | X4: Stop | Y4: Stop | Z4: % | AB4: EPS | AC4: Comp
A5: Symbol | B5: Position | C5: Name | D5: Qty | E5: Current | F5: Value | G5: Cost | H5: per share | I5: P/L $ | J5: per sh | K5: Date purch | L5: days held | M5: % incr | N5: Rank | O5: RS | P5: RS | Q5: pivot | R5: -0.07 | S5: low | T5: 0.25 | U5: 0.5 | V5: 1 | W5: -0.07 | X5: Loss | Y5: Loss% | Z5: of port | AB5: Due | AC5: Rank
F6: =E6*D6 -> 0 | H6: =G6/D6 -> #DIV/0! | I6: =F6-G6 -> 0 | J6: =E6-H6 -> #DIV/0! | L6: =DAYS360(K6,$C$1) -> 44460 | M6: =(I6/G6) -> #DIV/0! | R6: =Q6*0.93 -> 0 | T6: =Q6*1.25 -> 0 | U6: =Q6*1.5 -> 0 | V6: =Q6*2 -> 0 | W6: =H6-(H6*0.07) -> #DIV/0! | Y6: =(X6-H6)/H6 -> #DIV/0! | Z6: =F6/F$22 -> 0
A7: MCK | B7: Long | C7: McKesson | D7: 123.3931 | E7: 428.17 | F7: =E7*D7 -> 52833.224 | G7: 50990.97 | H7: =G7/D7 -> 413.24004 | I7: =F7-G7 -> 1842.2536 | J7: =E7-H7 -> 14.929957 | K7: 45104 | L7: =DAYS360(K7,$C$1) -> 3 | M7: =(I7/G7) -> 0.036129017 | N7: 56 | O7: 85 | P7: 95 | Q7: 401.53 | R7: =Q7*0.93 -> 373.4229 | S7: 373.28 | T7: =Q7*1.25 -> 501.9125 | U7: =Q7*1.5 -> 602.295 | V7: =Q7*2 -> 803.06 | W7: =H7-(H7*0.07) -> 384.31324 | X7: 399 | Y7: =(X7-H7)/H7 -> -0.034459495 | Z7: =F7/F$22 -> 0.10329671 | AC7: 88 | AD7: Bought after pullback to 10dma
A8: DXCM | B8: Long | C8: DexCom | D8: 278.2008 | E8: 128.8 | F8: =E8*D8 -> 35832.263 | G8: 35723.77 | H8: =G8/D8 -> 128.41002 | I8: =F8-G8 -> 108.49304 | J8: =E8-H8 -> 0.38998105 | K8: 45106 | L8: =DAYS360(K8,$C$1) -> 1 | M8: =(I8/G8) -> 0.0030369986 | N8: 47 | O8: 90 | P8: 98 | Q8: 126.44 | R8: =Q8*0.93 -> 117.5892 | S8: 121.79 | T8: =Q8*1.25 -> 158.05 | U8: =Q8*1.5 -> 189.66 | V8: =Q8*2 -> 252.88 | W8: =H8-(H8*0.07) -> 119.42132 | X8: 120 | Y8: =(X8-H8)/H8 -> -0.06549348 | Z8: =F8/F$22 -> 0.070057333 | AB8: 44596 | AC8: 97 | AD8: Bought after pullback to 50dma and pivot area.
F9: =E9*D9 -> 0 | H9: =G9/D9 -> #DIV/0! | I9: =F9-G9 -> 0 | J9: =E9-H9 -> #DIV/0! | L9: =DAYS360(K9,$C$1) -> 44460 | M9: =(I9/G9) -> #DIV/0! | R9: =Q9*0.93 -> 0 | T9: =Q9*1.25 -> 0 | U9: =Q9*1.5 -> 0 | V9: =Q9*2 -> 0 | W9: =H9-(H9*0.07) -> #DIV/0! | Y9: =(X9-H9)/H9 -> #DIV/0! | Z9: =F9/F$22 -> 0 | AB9: 44596 | AC9: 75
F10: =E10*D10 -> 0 | H10: =G10/D10 -> #DIV/0! | I10: =F10-G10 -> 0 | J10: =E10-H10 -> #DIV/0! | L10: =DAYS360(K10,$C$1) -> 44460 | M10: =(I10/G10) -> #DIV/0! | R10: =Q10*0.93 -> 0 | T10: =Q10*1.25 -> 0 | U10: =Q10*1.5 -> 0 | V10: =Q10*2 -> 0 | W10: =H10-(H10*0.07) -> #DIV/0! | Y10: =(X10-H10)/H10 -> #DIV/0! | Z10: =F10/F$22 -> 0 | AB10: 44589 | AC10: 87
F11: =E11*D11 -> 0 | H11: =G11/D11 -> #DIV/0! | I11: =F11-G11 -> 0 | J11: =E11-H11 -> #DIV/0! | L11: =DAYS360(K11,$C$1) -> 44460 | M11: =(I11/G11) -> #DIV/0! | R11: =Q11*0.93 -> 0 | T11: =Q11*1.25 -> 0 | U11: =Q11*1.5 -> 0 | V11: =Q11*2 -> 0 | W11: =H11-(H11*0.07) -> #DIV/0! | Y11: =(X11-H11)/H11 -> #DIV/0! | Z11: =F11/F$22 -> 0 | AB11: 44581 | AC11: 99
F12: =E12*D12 -> 0 | H12: =G12/D12 -> #DIV/0! | I12: =F12-G12 -> 0 | J12: =E12-H12 -> #DIV/0! | L12: =DAYS360(K12,$C$1) -> 44460 | M12: =(I12/G12) -> #DIV/0! | R12: =Q12*0.93 -> 0 | T12: =Q12*1.25 -> 0 | U12: =Q12*1.5 -> 0 | V12: =Q12*2 -> 0 | W12: =H12-(H12*0.07) -> #DIV/0! | Y12: =(X12-H12)/H12 -> #DIV/0! | Z12: =F12/F$22 -> 0 | AB12: 44568 | AC12: 90
F13: =E13*D13 -> 0 | H13: =G13/D13 -> #DIV/0! | I13: =F13-G13 -> 0 | J13: =E13-H13 -> #DIV/0! | L13: =DAYS360(K13,$C$1) -> 44460 | M13: =(I13/G13) -> #DIV/0! | R13: =Q13*0.93 -> 0 | T13: =Q13*1.25 -> 0 | U13: =Q13*1.5 -> 0 | V13: =Q13*2 -> 0 | W13: =H13-(H13*0.07) -> #DIV/0! | Y13: =(X13-H13)/H13 -> #DIV/0! | Z13: =F13/F$22 -> 0 | AB13: 44601 | AC13: 99
F14: =E14*D14 -> 0 | H14: =G14/D14 -> #DIV/0! | I14: =F14-G14 -> 0 | J14: =E14-H14 -> #DIV/0! | L14: =DAYS360(K14,$C$1) -> 44460 | M14: =(I14/G14) -> #DIV/0! | R14: =Q14*0.93 -> 0 | T14: =Q14*1.25 -> 0 | U14: =Q14*1.5 -> 0 | V14: =Q14*2 -> 0 | W14: =H14-(H14*0.07) -> #DIV/0! | Y14: =(X14-H14)/H14 -> #DIV/0! | Z14: =F14/F$22 -> 0 | AB14: 44610 | AC14: 92
F15: =E15*D15 -> 0 | H15: =G15/D15 -> #DIV/0! | I15: =F15-G15 -> 0 | J15: =E15-H15 -> #DIV/0! | L15: =DAYS360(K15,$C$1) -> 44460 | M15: =(I15/G15) -> #DIV/0! | R15: =Q15*0.93 -> 0 | T15: =Q15*1.25 -> 0 | U15: =Q15*1.5 -> 0 | V15: =Q15*2 -> 0 | W15: =H15-(H15*0.07) -> #DIV/0! | Y15: =(X15-H15)/H15 -> #DIV/0! | Z15: =F15/F$22 -> 0
F16: =E16*D16 -> 0 | H16: =G16/D16 -> #DIV/0! | I16: =F16-G16 -> 0 | J16: =E16-H16 -> #DIV/0! | L16: =DAYS360(K16,$C$1) -> 44460 | M16: =(I16/G16) -> #DIV/0! | R16: =Q16*0.93 -> 0 | T16: =Q16*1.25 -> 0 | U16: =Q16*1.5 -> 0 | V16: =Q16*2 -> 0 | W16: =H16-(H16*0.07) -> #DIV/0! | Y16: =(X16-H16)/H16 -> #DIV/0! | Z16: =F16/F$22 -> 0
A17: BIL | B17: Long | C17: Tbill ETF | D17: 2778.4118 | E17: 91.83 | F17: =E17*D17 -> 255141.56 | G17: 254613.66 | H17: =G17/D17 -> 91.640001 | I17: =F17-G17 -> 527.89559 | J17: =E17-H17 -> 0.18999905 | L17: =DAYS360(K17,$C$1) -> 44460 | M17: =(I17/G17) -> 0.00207332 | R17: =Q17*0.93 -> 0 | T17: =Q17*1.25 -> 0 | U17: =Q17*1.5 -> 0 | V17: =Q17*2 -> 0 | W17: =H17-(H17*0.07) -> 85.225201 | Y17: =(X17-H17)/H17 -> -1 | Z17: =F17/F$22 -> 0.49883919
A18: SQQQ | B18: Long | C18: QQQ Triple short | D18: 511.2918 | E18: 18.82 | F18: =E18*D18 -> 9622.5117 | G18: 24797.66 | H18: =G18/D18 -> 48.500015 | I18: =F18-G18 -> -15175.148 | J18: =E18-H18 -> -29.680015 | L18: =DAYS360(K18,$C$1) -> 44460 | M18: =(I18/G18) -> -0.61195888 | R18: =Q18*0.93 -> 0 | T18: =Q18*1.25 -> 0 | U18: =Q18*1.5 -> 0 | V18: =Q18*2 -> 0 | W18: =H18-(H18*0.07) -> 45.105014 | Y18: =(X18-H18)/H18 -> -1 | Z18: =F18/F$22 -> 0.018813423
F19: =E19*D19 -> 0 | H19: =G19/D19 -> #DIV/0! | I19: =F19-G19 -> 0 | J19: =E19-H19 -> #DIV/0! | L19: =DAYS360(K19,$C$1) -> 44460 | M19: =(I19/G19) -> #DIV/0! | R19: =Q19*0.93 -> 0 | T19: =Q19*1.25 -> 0 | U19: =Q19*1.5 -> 0 | V19: =Q19*2 -> 0 | W19: =H19-(H19*0.07) -> #DIV/0! | Y19: =(X19-H19)/H19 -> #DIV/0! | Z19: =F19/F$22 -> 0
A20: Sub-Total | F20: =SUM(F6:F19) -> 353429.55 | G20: =SUM(G6:G19) -> 366126.06 | I20: =SUM(I6:I19) -> -12696.506
D21: Cash, other | F21: 158041 | G21: =F21/F22 -> 0.30899335
D22: Total | F22: =SUM(F20:F21) -> 511470.55
F23: Yesterday's close >>>> | H23: Last week's close | I23: 509801
F24: Day's change >>> | G24: =(F22-G23)/G23 -> #DIV/0! | H24: Week's change | I24: =(F22-I23-F25)/I23 -> 0.003274913
M26: days
A27: 2023 Closed Trades - Managed Acct | D27: Qty | E27: Cost/sh | F27: $ cost | G27: Proc/sh | H27: $Proc | I27: Profit/loss | J27: % | K27: Date purch | L27: Date sold | M27: held | P27: Comments

Sheet 07-07-23
C1: 45114
C3: MANAGED ACCT | X3: Current | AC3: IBD
H4: Cost | J4: P/L | N4: Group | P4: EPS | R4: pivot | S4: last | W4: cost | X4: Stop | Y4: Stop | Z4: % | AB4: EPS | AC4: Comp
A5: Symbol | B5: Position | C5: Name | D5: Qty | E5: Current | F5: Value | G5: Cost | H5: per share | I5: P/L $ | J5: per sh | K5: Date purch | L5: days held | M5: % incr | N5: Rank | O5: RS | P5: RS | Q5: pivot | R5: -0.07 | S5: low | T5: 0.25 | U5: 0.5 | V5: 1 | W5: -0.07 | X5: Loss | Y5: Loss% | Z5: of port | AB5: Due | AC5: Rank
F6: =E6*D6 -> 0 | H6: =G6/D6 -> #DIV/0! | I6: =F6-G6 -> 0 | J6: =E6-H6 -> #DIV/0! | L6: =DAYS360(K6,$C$1) -> 44467 | M6: =(I6/G6) -> #DIV/0! | R6: =Q6*0.93 -> 0 | T6: =Q6*1.25 -> 0 | U6: =Q6*1.5 -> 0 | V6: =Q6*2 -> 0 | W6: =H6-(H6*0.07) -> #DIV/0! | Y6: =(X6-H6)/H6 -> #DIV/0! | Z6: =F6/F$22 -> 0
A7: MCK | B7: Long | C7: McKesson | D7: 123.3931 | E7: 414.8 | F7: =E7*D7 -> 51183.458 | G7: 50990.97 | H7: =G7/D7 -> 413.24004 | I7: =F7-G7 -> 192.48788 | J7: =E7-H7 -> 1.5599566 | K7: 45104 | L7: =DAYS360(K7,$C$1) -> 10 | M7: =(I7/G7) -> 0.0037749405 | N7: 39 | O7: 83 | P7: 95 | Q7: 401.53 | R7: =Q7*0.93 -> 373.4229 | S7: 373.28 | T7: =Q7*1.25 -> 501.9125 | U7: =Q7*1.5 -> 602.295 | V7: =Q7*2 -> 803.06 | W7: =H7-(H7*0.07) -> 384.31324 | X7: 399 | Y7: =(X7-H7)/H7 -> -0.034459495 | Z7: =F7/F$22 -> 0.10043628 | AB7: 45140 | AC7: 88 | AD7: Bought after pullback to 10dma
A8: DXCM | B8: Long | C8: DexCom | D8: 278.2008 | E8: 126.71 | F8: =E8*D8 -> 35250.823 | G8: 35723.77 | H8: =G8/D8 -> 128.41002 | I8: =F8-G8 -> -472.94663 | J8: =E8-H8 -> -1.700019 | K8: 45106 | L8: =DAYS360(K8,$C$1) -> 8 | M8: =(I8/G8) -> -0.01323899 | N8: 47 | O8: 89 | P8: 98 | Q8: 126.44 | R8: =Q8*0.93 -> 117.5892 | S8: 121.79 | T8: =Q8*1.25 -> 158.05 | U8: =Q8*1.5 -> 189.66 | V8: =Q8*2 -> 252.88 | W8: =H8-(H8*0.07) -> 119.42132 | X8: 122.45 | Y8: =(X8-H8)/H8 -> -0.046413971 | Z8: =F8/F$22 -> 0.069171986 | AB8: 45140 | AC8: 97 | AD8: Bought after pullback to 50dma and pivot area.
A9: HXL | B9: Long | C9: Hexcel | D9: 665.9739 | E9: 76.82 | F9: =E9*D9 -> 51160.115 | G9: 51028 | H9: =G9/D9 -> 76.621621 | I9: =F9-G9 -> 132.115 | J9: =E9-H9 -> 0.19837864 | K9: 45112 | L9: =DAYS360(K9,$C$1) -> 2 | M9: =(I9/G9) -> 0.0025890687 | N9: 44 | O9: 90 | P9: 82 | Q9: 74.44 | R9: =Q9*0.93 -> 69.2292 | S9: 70.88 | T9: =Q9*1.25 -> 93.05 | U9: =Q9*1.5 -> 111.66 | V9: =Q9*2 -> 148.88 | W9: =H9-(H9*0.07) -> 71.258108 | X9: 73.25 | Y9: =(X9-H9)/H9 -> -0.044003524 | Z9: =F9/F$22 -> 0.10039047 | AB9: 45131 | AC9: 97 | AD9: Bought after pivot test. Katie recommends also.
F10: =E10*D10 -> 0 | H10: =G10/D10 -> #DIV/0! | I10: =F10-G10 -> 0 | J10: =E10-H10 -> #DIV/0! | L10: =DAYS360(K10,$C$1) -> 44467 | M10: =(I10/G10) -> #DIV/0! | R10: =Q10*0.93 -> 0 | T10: =Q10*1.25 -> 0 | U10: =Q10*1.5 -> 0 | V10: =Q10*2 -> 0 | W10: =H10-(H10*0.07) -> #DIV/0! | Y10: =(X10-H10)/H10 -> #DIV/0! | Z10: =F10/F$22 -> 0 | AB10: 44589 | AC10: 87
F11: =E11*D11 -> 0 | H11: =G11/D11 -> #DIV/0! | I11: =F11-G11 -> 0 | J11: =E11-H11 -> #DIV/0! | L11: =DAYS360(K11,$C$1) -> 44467 | M11: =(I11/G11) -> #DIV/0! | R11: =Q11*0.93 -> 0 | T11: =Q11*1.25 -> 0 | U11: =Q11*1.5 -> 0 | V11: =Q11*2 -> 0 | W11: =H11-(H11*0.07) -> #DIV/0! | Y11: =(X11-H11)/H11 -> #DIV/0! | Z11: =F11/F$22 -> 0 | AB11: 44581 | AC11: 99
F12: =E12*D12 -> 0 | H12: =G12/D12 -> #DIV/0! | I12: =F12-G12 -> 0 | J12: =E12-H12 -> #DIV/0! | L12: =DAYS360(K12,$C$1) -> 44467 | M12: =(I12/G12) -> #DIV/0! | R12: =Q12*0.93 -> 0 | T12: =Q12*1.25 -> 0 | U12: =Q12*1.5 -> 0 | V12: =Q12*2 -> 0 | W12: =H12-(H12*0.07) -> #DIV/0! | Y12: =(X12-H12)/H12 -> #DIV/0! | Z12: =F12/F$22 -> 0 | AB12: 44568 | AC12: 90
F13: =E13*D13 -> 0 | H13: =G13/D13 -> #DIV/0! | I13: =F13-G13 -> 0 | J13: =E13-H13 -> #DIV/0! | L13: =DAYS360(K13,$C$1) -> 44467 | M13: =(I13/G13) -> #DIV/0! | R13: =Q13*0.93 -> 0 | T13: =Q13*1.25 -> 0 | U13: =Q13*1.5 -> 0 | V13: =Q13*2 -> 0 | W13: =H13-(H13*0.07) -> #DIV/0! | Y13: =(X13-H13)/H13 -> #DIV/0! | Z13: =F13/F$22 -> 0 | AB13: 44601 | AC13: 99
F14: =E14*D14 -> 0 | H14: =G14/D14 -> #DIV/0! | I14: =F14-G14 -> 0 | J14: =E14-H14 -> #DIV/0! | L14: =DAYS360(K14,$C$1) -> 44467 | M14: =(I14/G14) -> #DIV/0! | R14: =Q14*0.93 -> 0 | T14: =Q14*1.25 -> 0 | U14: =Q14*1.5 -> 0 | V14: =Q14*2 -> 0 | W14: =H14-(H14*0.07) -> #DIV/0! | Y14: =(X14-H14)/H14 -> #DIV/0! | Z14: =F14/F$22 -> 0 | AB14: 44610 | AC14: 92
F15: =E15*D15 -> 0 | H15: =G15/D15 -> #DIV/0! | I15: =F15-G15 -> 0 | J15: =E15-H15 -> #DIV/0! | L15: =DAYS360(K15,$C$1) -> 44467 | M15: =(I15/G15) -> #DIV/0! | R15: =Q15*0.93 -> 0 | T15: =Q15*1.25 -> 0 | U15: =Q15*1.5 -> 0 | V15: =Q15*2 -> 0 | W15: =H15-(H15*0.07) -> #DIV/0! | Y15: =(X15-H15)/H15 -> #DIV/0! | Z15: =F15/F$22 -> 0
F16: =E16*D16 -> 0 | H16: =G16/D16 -> #DIV/0! | I16: =F16-G16 -> 0 | J16: =E16-H16 -> #DIV/0! | L16: =DAYS360(K16,$C$1) -> 44467 | M16: =(I16/G16) -> #DIV/0! | R16: =Q16*0.93 -> 0 | T16: =Q16*1.25 -> 0 | U16: =Q16*1.5 -> 0 | V16: =Q16*2 -> 0 | W16: =H16-(H16*0.07) -> #DIV/0! | Y16: =(X16-H16)/H16 -> #DIV/0! | Z16: =F16/F$22 -> 0
A17: BIL | B17: Long | C17: Tbill ETF | D17: 2778.4118 | E17: 91.52 | F17: =E17*D17 -> 254280.25 | G17: 254613.66 | H17: =G17/D17 -> 91.640001 | I17: =F17-G17 -> -333.41206 | J17: =E17-H17 -> -0.12000095 | L17: =DAYS360(K17,$C$1) -> 44467 | M17: =(I17/G17) -> -0.0013094822 | R17: =Q17*0.93 -> 0 | T17: =Q17*1.25 -> 0 | U17: =Q17*1.5 -> 0 | V17: =Q17*2 -> 0 | W17: =H17-(H17*0.07) -> 85.225201 | Y17: =(X17-H17)/H17 -> -1 | Z17: =F17/F$22 -> 0.49896904
A18: SQQQ | B18: Long | C18: QQQ Triple short | D18: 511.2918 | E18: 19.45 | F18: =E18*D18 -> 9944.6255 | G18: 24797.66 | H18: =G18/D18 -> 48.500015 | I18: =F18-G18 -> -14853.034 | J18: =E18-H18 -> -29.050015 | L18: =DAYS360(K18,$C$1) -> 44467 | M18: =(I18/G18) -> -0.5989692 | R18: =Q18*0.93 -> 0 | T18: =Q18*1.25 -> 0 | U18: =Q18*1.5 -> 0 | V18: =Q18*2 -> 0 | W18: =H18-(H18*0.07) -> 45.105014 | Y18: =(X18-H18)/H18 -> -1 | Z18: =F18/F$22 -> 0.01951414
F19: =E19*D19 -> 0 | H19: =G19/D19 -> #DIV/0! | I19: =F19-G19 -> 0 | J19: =E19-H19 -> #DIV/0! | L19: =DAYS360(K19,$C$1) -> 44467 | M19: =(I19/G19) -> #DIV/0! | R19: =Q19*0.93 -> 0 | T19: =Q19*1.25 -> 0 | U19: =Q19*1.5 -> 0 | V19: =Q19*2 -> 0 | W19: =H19-(H19*0.07) -> #DIV/0! | Y19: =(X19-H19)/H19 -> #DIV/0! | Z19: =F19/F$22 -> 0
A20: Sub-Total | F20: =SUM(F6:F19) -> 401819.27 | G20: =SUM(G6:G19) -> 417154.06 | I20: =SUM(I6:I19) -> -15334.79
D21: Cash, other | F21: 107792 | G21: =F21/F22 -> 0.21151809
D22: Total | F22: =SUM(F20:F21) -> 509611.27
F23: Yesterday's close >>>> | H23: Last week's close | I23: 511470.55
F24: Day's change >>> | G24: =(F22-G23)/G23 -> #DIV/0! | H24: Week's change | I24: =(F22-I23-F25)/I23 -> -0.0036351659
M26: days
A27: 2023 Closed Trades - Managed Acct | D27: Qty | E27: Cost/sh | F27: $ cost | G27: Proc/sh | H27: $Proc | I27: Profit/loss | J27: % | K27: Date purch | L27: Date sold | M27: held | P27: Comments

Sheet 07-14-23
C1: 45121
C3: MANAGED ACCT | X3: Current | AC3: IBD
H4: Cost | J4: P/L | N4: Group | P4: EPS | R4: pivot | S4: last | W4: cost | X4: Stop | Y4: Stop | Z4: % | AB4: EPS | AC4: Comp
A5: Symbol | B5: Position | C5: Name | D5: Qty | E5: Current | F5: Value | G5: Cost | H5: per share | I5: P/L $ | J5: per sh | K5: Date purch | L5: days held | M5: % incr | N5: Rank | O5: RS | P5: RS | Q5: pivot | R5: -0.07 | S5: low | T5: 0.25 | U5: 0.5 | V5: 1 | W5: -0.07 | X5: Loss | Y5: Loss% | Z5: of port | AB5: Due | AC5: Rank
F6: =E6*D6 -> 0 | H6: =G6/D6 -> #DIV/0! | I6: =F6-G6 -> 0 | J6: =E6-H6 -> #DIV/0! | L6: =DAYS360(K6,$C$1) -> 44474 | M6: =(I6/G6) -> #DIV/0! | R6: =Q6*0.93 -> 0 | T6: =Q6*1.25 -> 0 | U6: =Q6*1.5 -> 0 | V6: =Q6*2 -> 0 | W6: =H6-(H6*0.07) -> #DIV/0! | Y6: =(X6-H6)/H6 -> #DIV/0! | Z6: =F6/F$22 -> 0
A7: MCK | B7: Long | C7: McKesson | D7: 123.3931 | E7: 409.5 | F7: =E7*D7 -> 50529.474 | G7: 50990.97 | H7: =G7/D7 -> 413.24004 | I7: =F7-G7 -> -461.49555 | J7: =E7-H7 -> -3.7400434 | K7: 45104 | L7: =DAYS360(K7,$C$1) -> 17 | M7: =(I7/G7) -> -0.0090505348 | N7: 39 | O7: 83 | P7: 95 | Q7: 401.53 | R7: =Q7*0.93 -> 373.4229 | S7: 373.28 | T7: =Q7*1.25 -> 501.9125 | U7: =Q7*1.5 -> 602.295 | V7: =Q7*2 -> 803.06 | W7: =H7-(H7*0.07) -> 384.31324 | X7: 399 | Y7: =(X7-H7)/H7 -> -0.034459495 | Z7: =F7/F$22 -> 0.098459082 | AB7: 45140 | AC7: 88 | AD7: Bought after pullback to 10dma
A8: DXCM | B8: Long | C8: DexCom | D8: 278.2008 | E8: 137.32 | F8: =E8*D8 -> 38202.534 | G8: 35723.77 | H8: =G8/D8 -> 128.41002 | I8: =F8-G8 -> 2478.7639 | J8: =E8-H8 -> 8.909981 | K8: 45106 | L8: =DAYS360(K8,$C$1) -> 15 | M8: =(I8/G8) -> 0.069386962 | N8: 47 | O8: 89 | P8: 98 | Q8: 126.44 | R8: =Q8*0.93 -> 117.5892 | S8: 121.79 | T8: =Q8*1.25 -> 158.05 | U8: =Q8*1.5 -> 189.66 | V8: =Q8*2 -> 252.88 | W8: =H8-(H8*0.07) -> 119.42132 | X8: 122.45 | Y8: =(X8-H8)/H8 -> -0.046413971 | Z8: =F8/F$22 -> 0.074439452 | AB8: 45140 | AC8: 97 | AD8: Bought after pullback to 50dma and pivot area.
A9: HXL | B9: Long | C9: Hexcel | D9: 665.9739 | E9: 76.17 | F9: =E9*D9 -> 50727.232 | G9: 51028 | H9: =G9/D9 -> 76.621621 | I9: =F9-G9 -> -300.76804 | J9: =E9-H9 -> -0.45162136 | K9: 45112 | L9: =DAYS360(K9,$C$1) -> 9 | M9: =(I9/G9) -> -0.0058941765 | N9: 44 | O9: 90 | P9: 82 | Q9: 74.44 | R9: =Q9*0.93 -> 69.2292 | S9: 70.88 | T9: =Q9*1.25 -> 93.05 | U9: =Q9*1.5 -> 111.66 | V9: =Q9*2 -> 148.88 | W9: =H9-(H9*0.07) -> 71.258108 | X9: 73.25 | Y9: =(X9-H9)/H9 -> -0.044003524 | Z9: =F9/F$22 -> 0.098844422 | AB9: 45131 | AC9: 97 | AD9: Bought after pivot test. Katie recommends also.
A10: SNPS | B10: Long | C10: Synopsys | D10: 115.8536 | E10: 454.11 | F10: =E10*D10 -> 52610.278 | G10: 51225.83 | H10: =G10/D10 -> 442.16002 | I10: =F10-G10 -> 1384.4483 | J10: =E10-H10 -> 11.949981 | K10: 45117 | L10: =DAYS360(K10,$C$1) -> 4 | M10: =(I10/G10) -> 0.027026371 | N10: 22 | O10: 89 | P10: 90 | Q10: 392.79 | R10: =Q10*0.93 -> 365.2947 | S10: 416.87 | T10: =Q10*1.25 -> 490.9875 | U10: =Q10*1.5 -> 589.185 | V10: =Q10*2 -> 785.58 | W10: =H10-(H10*0.07) -> 411.20882 | X10: 415 | Y10: =(X10-H10)/H10 -> -0.061425769 | Z10: =F10/F$22 -> 0.10251363 | AB10: 45154 | AC10: 96 | AD10: Bought when breaking out of bull flag in volume.
F11: =E11*D11 -> 0 | H11: =G11/D11 -> #DIV/0! | I11: =F11-G11 -> 0 | J11: =E11-H11 -> #DIV/0! | L11: =DAYS360(K11,$C$1) -> 44474 | M11: =(I11/G11) -> #DIV/0! | R11: =Q11*0.93 -> 0 | T11: =Q11*1.25 -> 0 | U11: =Q11*1.5 -> 0 | V11: =Q11*2 -> 0 | W11: =H11-(H11*0.07) -> #DIV/0! | Y11: =(X11-H11)/H11 -> #DIV/0! | Z11: =F11/F$22 -> 0 | AB11: 44581 | AC11: 99
F12: =E12*D12 -> 0 | H12: =G12/D12 -> #DIV/0! | I12: =F12-G12 -> 0 | J12: =E12-H12 -> #DIV/0! | L12: =DAYS360(K12,$C$1) -> 44474 | M12: =(I12/G12) -> #DIV/0! | R12: =Q12*0.93 -> 0 | T12: =Q12*1.25 -> 0 | U12: =Q12*1.5 -> 0 | V12: =Q12*2 -> 0 | W12: =H12-(H12*0.07) -> #DIV/0! | Y12: =(X12-H12)/H12 -> #DIV/0! | Z12: =F12/F$22 -> 0 | AB12: 44568 | AC12: 90
F13: =E13*D13 -> 0 | H13: =G13/D13 -> #DIV/0! | I13: =F13-G13 -> 0 | J13: =E13-H13 -> #DIV/0! | L13: =DAYS360(K13,$C$1) -> 44474 | M13: =(I13/G13) -> #DIV/0! | R13: =Q13*0.93 -> 0 | T13: =Q13*1.25 -> 0 | U13: =Q13*1.5 -> 0 | V13: =Q13*2 -> 0 | W13: =H13-(H13*0.07) -> #DIV/0! | Y13: =(X13-H13)/H13 -> #DIV/0! | Z13: =F13/F$22 -> 0 | AB13: 44601 | AC13: 99
F14: =E14*D14 -> 0 | H14: =G14/D14 -> #DIV/0! | I14: =F14-G14 -> 0 | J14: =E14-H14 -> #DIV/0! | L14: =DAYS360(K14,$C$1) -> 44474 | M14: =(I14/G14) -> #DIV/0! | R14: =Q14*0.93 -> 0 | T14: =Q14*1.25 -> 0 | U14: =Q14*1.5 -> 0 | V14: =Q14*2 -> 0 | W14: =H14-(H14*0.07) -> #DIV/0! | Y14: =(X14-H14)/H14 -> #DIV/0! | Z14: =F14/F$22 -> 0 | AB14: 44610 | AC14: 92
F15: =E15*D15 -> 0 | H15: =G15/D15 -> #DIV/0! | I15: =F15-G15 -> 0 | J15: =E15-H15 -> #DIV/0! | L15: =DAYS360(K15,$C$1) -> 44474 | M15: =(I15/G15) -> #DIV/0! | R15: =Q15*0.93 -> 0 | T15: =Q15*1.25 -> 0 | U15: =Q15*1.5 -> 0 | V15: =Q15*2 -> 0 | W15: =H15-(H15*0.07) -> #DIV/0! | Y15: =(X15-H15)/H15 -> #DIV/0! | Z15: =F15/F$22 -> 0
F16: =E16*D16 -> 0 | H16: =G16/D16 -> #DIV/0! | I16: =F16-G16 -> 0 | J16: =E16-H16 -> #DIV/0! | L16: =DAYS360(K16,$C$1) -> 44474 | M16: =(I16/G16) -> #DIV/0! | R16: =Q16*0.93 -> 0 | T16: =Q16*1.25 -> 0 | U16: =Q16*1.5 -> 0 | V16: =Q16*2 -> 0 | W16: =H16-(H16*0.07) -> #DIV/0! | Y16: =(X16-H16)/H16 -> #DIV/0! | Z16: =F16/F$22 -> 0
A17: BIL | B17: Long | C17: Tbill ETF | D17: 2778.4118 | E17: 91.62 | F17: =E17*D17 -> 254558.09 | G17: 254613.66 | H17: =G17/D17 -> 91.640001 | I17: =F17-G17 -> -55.570884 | J17: =E17-H17 -> -0.020000953 | L17: =DAYS360(K17,$C$1) -> 44474 | M17: =(I17/G17) -> -0.00021825571 | R17: =Q17*0.93 -> 0 | T17: =Q17*1.25 -> 0 | U17: =Q17*1.5 -> 0 | V17: =Q17*2 -> 0 | W17: =H17-(H17*0.07) -> 85.225201 | Y17: =(X17-H17)/H17 -> -1 | Z17: =F17/F$22 -> 0.49601853
A18: SQQQ | B18: Long | C18: QQQ Triple short | D18: 511.2918 | E18: 17.55 | F18: =E18*D18 -> 8973.1711 | G18: 24797.66 | H18: =G18/D18 -> 48.500015 | I18: =F18-G18 -> -15824.489 | J18: =E18-H18 -> -30.950015 | L18: =DAYS360(K18,$C$1) -> 44474 | M18: =(I18/G18) -> -0.63814444 | R18: =Q18*0.93 -> 0 | T18: =Q18*1.25 -> 0 | U18: =Q18*1.5 -> 0 | V18: =Q18*2 -> 0 | W18: =H18-(H18*0.07) -> 45.105014 | Y18: =(X18-H18)/H18 -> -1 | Z18: =F18/F$22 -> 0.01748465
F19: =E19*D19 -> 0 | H19: =G19/D19 -> #DIV/0! | I19: =F19-G19 -> 0 | J19: =E19-H19 -> #DIV/0! | L19: =DAYS360(K19,$C$1) -> 44474 | M19: =(I19/G19) -> #DIV/0! | R19: =Q19*0.93 -> 0 | T19: =Q19*1.25 -> 0 | U19: =Q19*1.5 -> 0 | V19: =Q19*2 -> 0 | W19: =H19-(H19*0.07) -> #DIV/0! | Y19: =(X19-H19)/H19 -> #DIV/0! | Z19: =F19/F$22 -> 0
A20: Sub-Total | F20: =SUM(F6:F19) -> 455600.78 | G20: =SUM(G6:G19) -> 468379.89 | I20: =SUM(I6:I19) -> -12779.111
D21: Cash, other | F21: 57602 | G21: =F21/F22 -> 0.11224023
D22: Total | F22: =SUM(F20:F21) -> 513202.78
F23: Yesterday's close >>>> | H23: Last week's close | I23: 509611.27
F24: Day's change >>> | G24: =(F22-G23)/G23 -> #DIV/0! | H24: Week's change | I24: =(F22-I23-F25)/I23 -> 0.0070475458
M26: days
A27: 2023 Closed Trades - Managed Acct | D27: Qty | E27: Cost/sh | F27: $ cost | G27: Proc/sh | H27: $Proc | I27: Profit/loss | J27: % | K27: Date purch | L27: Date sold | M27: held | P27: Comments

Sheet 07-21-23
C1: 45128
C3: MANAGED ACCT | X3: Current | AC3: IBD
H4: Cost | J4: P/L | N4: Group | P4: EPS | R4: pivot | S4: last | W4: cost | X4: Stop | Y4: Stop | Z4: % | AB4: EPS | AC4: Comp
A5: Symbol | B5: Position | C5: Name | D5: Qty | E5: Current | F5: Value | G5: Cost | H5: per share | I5: P/L $ | J5: per sh | K5: Date purch | L5: days held | M5: % incr | N5: Rank | O5: RS | P5: RS | Q5: pivot | R5: -0.07 | S5: low | T5: 0.25 | U5: 0.5 | V5: 1 | W5: -0.07 | X5: Loss | Y5: Loss% | Z5: of port | AB5: Due | AC5: Rank
F6: =E6*D6 -> 0 | H6: =G6/D6 -> #DIV/0! | I6: =F6-G6 -> 0 | J6: =E6-H6 -> #DIV/0! | L6: =DAYS360(K6,$C$1) -> 44481 | M6: =(I6/G6) -> #DIV/0! | R6: =Q6*0.93 -> 0 | T6: =Q6*1.25 -> 0 | U6: =Q6*1.5 -> 0 | V6: =Q6*2 -> 0 | W6: =H6-(H6*0.07) -> #DIV/0! | Y6: =(X6-H6)/H6 -> #DIV/0! | Z6: =F6/F$22 -> 0
A7: MCK | B7: Long | C7: McKesson | D7: 123.3931 | E7: 414.25 | F7: =E7*D7 -> 51115.592 | G7: 50990.97 | H7: =G7/D7 -> 413.24004 | I7: =F7-G7 -> 124.62168 | J7: =E7-H7 -> 1.0099566 | K7: 45104 | L7: =DAYS360(K7,$C$1) -> 24 | M7: =(I7/G7) -> 0.002443995 | N7: 67 | O7: 79 | P7: 95 | Q7: 401.53 | R7: =Q7*0.93 -> 373.4229 | S7: 373.28 | T7: =Q7*1.25 -> 501.9125 | U7: =Q7*1.5 -> 602.295 | V7: =Q7*2 -> 803.06 | W7: =H7-(H7*0.07) -> 384.31324 | X7: 399 | Y7: =(X7-H7)/H7 -> -0.034459495 | Z7: =F7/F$22 -> 0.099867344 | AB7: 45140 | AC7: 84 | AD7: Bought after pullback to 10dma
A8: DXCM | B8: Long | C8: DexCom | D8: 278.2008 | E8: 130.6 | F8: =E8*D8 -> 36333.024 | G8: 35723.77 | H8: =G8/D8 -> 128.41002 | I8: =F8-G8 -> 609.25448 | J8: =E8-H8 -> 2.189981 | K8: 45106 | L8: =DAYS360(K8,$C$1) -> 22 | M8: =(I8/G8) -> 0.017054596 | N8: 56 | O8: 87 | P8: 98 | Q8: 126.44 | R8: =Q8*0.93 -> 117.5892 | S8: 121.79 | T8: =Q8*1.25 -> 158.05 | U8: =Q8*1.5 -> 189.66 | V8: =Q8*2 -> 252.88 | W8: =H8-(H8*0.07) -> 119.42132 | X8: 122.45 | Y8: =(X8-H8)/H8 -> -0.046413971 | Z8: =F8/F$22 -> 0.070985829 | AB8: 45140 | AC8: 96 | AD8: Bought after pullback to 50dma and pivot area.
A9: HXL | B9: Long | C9: Hexcel | D9: 665.9739 | E9: 75.36 | F9: =E9*D9 -> 50187.793 | G9: 51028 | H9: =G9/D9 -> 76.621621 | I9: =F9-G9 -> -840.2069 | J9: =E9-H9 -> -1.2616214 | K9: 45112 | L9: =DAYS360(K9,$C$1) -> 16 | M9: =(I9/G9) -> -0.016465605 | N9: 47 | O9: 85 | P9: 82 | Q9: 74.44 | R9: =Q9*0.93 -> 69.2292 | S9: 70.88 | T9: =Q9*1.25 -> 93.05 | U9: =Q9*1.5 -> 111.66 | V9: =Q9*2 -> 148.88 | W9: =H9-(H9*0.07) -> 71.258108 | X9: 73.25 | Y9: =(X9-H9)/H9 -> -0.044003524 | Z9: =F9/F$22 -> 0.098054653 | AB9: 45131 | AC9: 93 | AD9: Bought after pivot test. Katie recommends also.
A10: SNPS | B10: Long | C10: Synopsys | D10: 115.8536 | E10: 454 | F10: =E10*D10 -> 52597.534 | G10: 51225.83 | H10: =G10/D10 -> 442.16002 | I10: =F10-G10 -> 1371.7044 | J10: =E10-H10 -> 11.839981 | K10: 45117 | L10: =DAYS360(K10,$C$1) -> 11 | M10: =(I10/G10) -> 0.026777592 | N10: 19 | O10: 90 | P10: 90 | Q10: 392.79 | R10: =Q10*0.93 -> 365.2947 | S10: 416.87 | T10: =Q10*1.25 -> 490.9875 | U10: =Q10*1.5 -> 589.185 | V10: =Q10*2 -> 785.58 | W10: =H10-(H10*0.07) -> 411.20882 | X10: 415 | Y10: =(X10-H10)/H10 -> -0.061425769 | Z10: =F10/F$22 -> 0.1027627 | AB10: 45154 | AC10: 96 | AD10: Bought when breaking out of bull flag in volume.
F11: =E11*D11 -> 0 | H11: =G11/D11 -> #DIV/0! | I11: =F11-G11 -> 0 | J11: =E11-H11 -> #DIV/0! | L11: =DAYS360(K11,$C$1) -> 44481 | M11: =(I11/G11) -> #DIV/0! | R11: =Q11*0.93 -> 0 | T11: =Q11*1.25 -> 0 | U11: =Q11*1.5 -> 0 | V11: =Q11*2 -> 0 | W11: =H11-(H11*0.07) -> #DIV/0! | Y11: =(X11-H11)/H11 -> #DIV/0! | Z11: =F11/F$22 -> 0 | AB11: 44581 | AC11: 99
F12: =E12*D12 -> 0 | H12: =G12/D12 -> #DIV/0! | I12: =F12-G12 -> 0 | J12: =E12-H12 -> #DIV/0! | L12: =DAYS360(K12,$C$1) -> 44481 | M12: =(I12/G12) -> #DIV/0! | R12: =Q12*0.93 -> 0 | T12: =Q12*1.25 -> 0 | U12: =Q12*1.5 -> 0 | V12: =Q12*2 -> 0 | W12: =H12-(H12*0.07) -> #DIV/0! | Y12: =(X12-H12)/H12 -> #DIV/0! | Z12: =F12/F$22 -> 0 | AB12: 44568 | AC12: 90
F13: =E13*D13 -> 0 | H13: =G13/D13 -> #DIV/0! | I13: =F13-G13 -> 0 | J13: =E13-H13 -> #DIV/0! | L13: =DAYS360(K13,$C$1) -> 44481 | M13: =(I13/G13) -> #DIV/0! | R13: =Q13*0.93 -> 0 | T13: =Q13*1.25 -> 0 | U13: =Q13*1.5 -> 0 | V13: =Q13*2 -> 0 | W13: =H13-(H13*0.07) -> #DIV/0! | Y13: =(X13-H13)/H13 -> #DIV/0! | Z13: =F13/F$22 -> 0 | AB13: 44601 | AC13: 99
F14: =E14*D14 -> 0 | H14: =G14/D14 -> #DIV/0! | I14: =F14-G14 -> 0 | J14: =E14-H14 -> #DIV/0! | L14: =DAYS360(K14,$C$1) -> 44481 | M14: =(I14/G14) -> #DIV/0! | R14: =Q14*0.93 -> 0 | T14: =Q14*1.25 -> 0 | U14: =Q14*1.5 -> 0 | V14: =Q14*2 -> 0 | W14: =H14-(H14*0.07) -> #DIV/0! | Y14: =(X14-H14)/H14 -> #DIV/0! | Z14: =F14/F$22 -> 0 | AB14: 44610 | AC14: 92
F15: =E15*D15 -> 0 | H15: =G15/D15 -> #DIV/0! | I15: =F15-G15 -> 0 | J15: =E15-H15 -> #DIV/0! | L15: =DAYS360(K15,$C$1) -> 44481 | M15: =(I15/G15) -> #DIV/0! | R15: =Q15*0.93 -> 0 | T15: =Q15*1.25 -> 0 | U15: =Q15*1.5 -> 0 | V15: =Q15*2 -> 0 | W15: =H15-(H15*0.07) -> #DIV/0! | Y15: =(X15-H15)/H15 -> #DIV/0! | Z15: =F15/F$22 -> 0
F16: =E16*D16 -> 0 | H16: =G16/D16 -> #DIV/0! | I16: =F16-G16 -> 0 | J16: =E16-H16 -> #DIV/0! | L16: =DAYS360(K16,$C$1) -> 44481 | M16: =(I16/G16) -> #DIV/0! | R16: =Q16*0.93 -> 0 | T16: =Q16*1.25 -> 0 | U16: =Q16*1.5 -> 0 | V16: =Q16*2 -> 0 | W16: =H16-(H16*0.07) -> #DIV/0! | Y16: =(X16-H16)/H16 -> #DIV/0! | Z16: =F16/F$22 -> 0
A17: BIL | B17: Long | C17: Tbill ETF | D17: 2778.4118 | E17: 91.7 | F17: =E17*D17 -> 254780.36 | G17: 254613.66 | H17: =G17/D17 -> 91.640001 | I17: =F17-G17 -> 166.70206 | J17: =E17-H17 -> 0.059999047 | L17: =DAYS360(K17,$C$1) -> 44481 | M17: =(I17/G17) -> 0.00065472552 | R17: =Q17*0.93 -> 0 | T17: =Q17*1.25 -> 0 | U17: =Q17*1.5 -> 0 | V17: =Q17*2 -> 0 | W17: =H17-(H17*0.07) -> 85.225201 | Y17: =(X17-H17)/H17 -> -1 | Z17: =F17/F$22 -> 0.49777841
A18: SQQQ | B18: Long | C18: QQQ Triple short | D18: 511.2918 | E18: 18.03 | F18: =E18*D18 -> 9218.5912 | G18: 24797.66 | H18: =G18/D18 -> 48.500015 | I18: =F18-G18 -> -15579.069 | J18: =E18-H18 -> -30.470015 | L18: =DAYS360(K18,$C$1) -> 44481 | M18: =(I18/G18) -> -0.62824754 | R18: =Q18*0.93 -> 0 | T18: =Q18*1.25 -> 0 | U18: =Q18*1.5 -> 0 | V18: =Q18*2 -> 0 | W18: =H18-(H18*0.07) -> 45.105014 | Y18: =(X18-H18)/H18 -> -1 | Z18: =F18/F$22 -> 0.018010869
F19: =E19*D19 -> 0 | H19: =G19/D19 -> #DIV/0! | I19: =F19-G19 -> 0 | J19: =E19-H19 -> #DIV/0! | L19: =DAYS360(K19,$C$1) -> 44481 | M19: =(I19/G19) -> #DIV/0! | R19: =Q19*0.93 -> 0 | T19: =Q19*1.25 -> 0 | U19: =Q19*1.5 -> 0 | V19: =Q19*2 -> 0 | W19: =H19-(H19*0.07) -> #DIV/0! | Y19: =(X19-H19)/H19 -> #DIV/0! | Z19: =F19/F$22 -> 0
A20: Sub-Total | F20: =SUM(F6:F19) -> 454232.9 | G20: =SUM(G6:G19) -> 468379.89 | I20: =SUM(I6:I19) -> -14146.993
D21: Cash, other | F21: 57602 | G21: =F21/F22 -> 0.1125402
D22: Total | F22: =SUM(F20:F21) -> 511834.9
H23: Last week's close | I23: 513598.81
H24: Week's change | I24: =(F22-I23-F25)/I23 -> -0.0034344183
M26: days
A27: 2023 Closed Trades - Managed Acct | D27: Qty | E27: Cost/sh | F27: $ cost | G27: Proc/sh | H27: $Proc | I27: Profit/loss | J27: % | K27: Date purch | L27: Date sold | M27: held | P27: Comments

Sheet 07-28-23
C1: 45135
C3: MANAGED ACCT | X3: Current | AC3: IBD
H4: Cost | J4: P/L | N4: Group | P4: EPS | R4: pivot | S4: last | W4: cost | X4: Stop | Y4: Stop | Z4: % | AB4: EPS | AC4: Comp
A5: Symbol | B5: Position | C5: Name | D5: Qty | E5: Current | F5: Value | G5: Cost | H5: per share | I5: P/L $ | J5: per sh | K5: Date purch | L5: days held | M5: % incr | N5: Rank | O5: RS | P5: RS | Q5: pivot | R5: -0.07 | S5: low | T5: 0.25 | U5: 0.5 | V5: 1 | W5: -0.07 | X5: Loss | Y5: Loss% | Z5: of port | AB5: Due | AC5: Rank
F6: =E6*D6 -> 0 | H6: =G6/D6 -> #DIV/0! | I6: =F6-G6 -> 0 | J6: =E6-H6 -> #DIV/0! | L6: =DAYS360(K6,$C$1) -> 44488 | M6: =(I6/G6) -> #DIV/0! | R6: =Q6*0.93 -> 0 | T6: =Q6*1.25 -> 0 | U6: =Q6*1.5 -> 0 | V6: =Q6*2 -> 0 | W6: =H6-(H6*0.07) -> #DIV/0! | Y6: =(X6-H6)/H6 -> #DIV/0! | Z6: =F6/F$16 -> 0
A7: MCK | B7: Long | C7: McKesson | D7: 123.3931 | E7: 402.97 | F7: =E7*D7 -> 49723.718 | G7: 50990.97 | H7: =G7/D7 -> 413.24004 | I7: =F7-G7 -> -1267.2525 | J7: =E7-H7 -> -10.270043 | K7: 45104 | L7: =DAYS360(K7,$C$1) -> 31 | M7: =(I7/G7) -> -0.024852488 | N7: 74 | O7: 72 | P7: 95 | Q7: 401.53 | R7: =Q7*0.93 -> 373.4229 | S7: 373.28 | T7: =Q7*1.25 -> 501.9125 | U7: =Q7*1.5 -> 602.295 | V7: =Q7*2 -> 803.06 | W7: =H7-(H7*0.07) -> 384.31324 | X7: 399 | Y7: =(X7-H7)/H7 -> -0.034459495 | Z7: =F7/F$16 -> 0.098356884 | AB7: 45140 | AC7: 78 | AD7: Bought after pullback to 10dma
A8: DXCM | B8: Long | C8: DexCom | D8: 278.2008 | E8: 132.38 | F8: =E8*D8 -> 36828.222 | G8: 35723.77 | H8: =G8/D8 -> 128.41002 | I8: =F8-G8 -> 1104.4519 | J8: =E8-H8 -> 3.969981 | K8: 45106 | L8: =DAYS360(K8,$C$1) -> 29 | M8: =(I8/G8) -> 0.030916443 | N8: 60 | O8: 86 | P8: 98 | Q8: 126.44 | R8: =Q8*0.93 -> 117.5892 | S8: 126.81 | T8: =Q8*1.25 -> 158.05 | U8: =Q8*1.5 -> 189.66 | V8: =Q8*2 -> 252.88 | W8: =H8-(H8*0.07) -> 119.42132 | X8: 124 | Y8: =(X8-H8)/H8 -> -0.034343262 | Z8: =F8/F$16 -> 0.072848719 | AB8: 45140 | AC8: 94 | AD8: Bought after pullback to 50dma and pivot area.
A9: SNPS | B9: Long | C9: Synopsys | D9: 115.8536 | E9: 450.94 | F9: =E9*D9 -> 52243.022 | G9: 51225.83 | H9: =G9/D9 -> 442.16002 | I9: =F9-G9 -> 1017.1924 | J9: =E9-H9 -> 8.7799808 | K9: 45117 | L9: =DAYS360(K9,$C$1) -> 18 | M9: =(I9/G9) -> 0.019857021 | N9: 31 | O9: 91 | P9: 91 | Q9: 392.79 | R9: =Q9*0.93 -> 365.2947 | S9: 416.87 | T9: =Q9*1.25 -> 490.9875 | U9: =Q9*1.5 -> 589.185 | V9: =Q9*2 -> 785.58 | W9: =H9-(H9*0.07) -> 411.20882 | X9: 415 | Y9: =(X9-H9)/H9 -> -0.061425769 | Z9: =F9/F$16 -> 0.10334024 | AB9: 45154 | AC9: 97 | AD9: Bought when breaking out of bull flag in volume.
B10: Long | C10: MNSO | D10: 1211.7123 | E10: 21 | F10: =E10*D10 -> 25445.958 | G10: 25318.9 | H10: =G10/D10 -> 20.895142 | I10: =F10-G10 -> 127.0583 | J10: =E10-H10 -> 0.10485847 | K10: 45135 | L10: =DAYS360(K10,$C$1) -> 0 | M10: =(I10/G10) -> 0.0050183183 | N10: 148 | O10: 99 | P10: 98 | Q10: 19.48 | R10: =Q10*0.93 -> 18.1164 | S10: 17.57 | T10: =Q10*1.25 -> 24.35 | U10: =Q10*1.5 -> 29.22 | V10: =Q10*2 -> 38.96 | W10: =H10-(H10*0.07) -> 19.432482 | X10: 18.12 | Y10: =(X10-H10)/H10 -> -0.13281277 | Z10: =F10/F$16 -> 0.05033383 | AB10: 45162 | AC10: 99 | AD10: Bought after 07/24 b/o.
A11: BIL | B11: Long | C11: Tbill ETF | D11: 2778.4118 | E11: 91.79 | F11: =E11*D11 -> 255030.42 | G11: 254613.66 | H11: =G11/D11 -> 91.640001 | I11: =F11-G11 -> 416.75912 | J11: =E11-H11 -> 0.14999905 | L11: =DAYS360(K11,$C$1) -> 44488 | M11: =(I11/G11) -> 0.0016368294 | R11: =Q11*0.93 -> 0 | T11: =Q11*1.25 -> 0 | U11: =Q11*1.5 -> 0 | V11: =Q11*2 -> 0 | W11: =H11-(H11*0.07) -> 85.225201 | Y11: =(X11-H11)/H11 -> -1 | Z11: =F11/F$16 -> 0.50446746
A12: SQQQ | B12: Long | C12: QQQ Triple short | D12: 511.2918 | E12: 16.96 | F12: =E12*D12 -> 8671.5089 | G12: 24797.66 | H12: =G12/D12 -> 48.500015 | I12: =F12-G12 -> -16126.151 | J12: =E12-H12 -> -31.540015 | L12: =DAYS360(K12,$C$1) -> 44488 | M12: =(I12/G12) -> -0.65030939 | R12: =Q12*0.93 -> 0 | T12: =Q12*1.25 -> 0 | U12: =Q12*1.5 -> 0 | V12: =Q12*2 -> 0 | W12: =H12-(H12*0.07) -> 45.105014 | Y12: =(X12-H12)/H12 -> -1 | Z12: =F12/F$16 -> 0.017152832
F13: =E13*D13 -> 0 | H13: =G13/D13 -> #DIV/0! | I13: =F13-G13 -> 0 | J13: =E13-H13 -> #DIV/0! | L13: =DAYS360(K13,$C$1) -> 44488 | M13: =(I13/G13) -> #DIV/0! | R13: =Q13*0.93 -> 0 | T13: =Q13*1.25 -> 0 | U13: =Q13*1.5 -> 0 | V13: =Q13*2 -> 0 | W13: =H13-(H13*0.07) -> #DIV/0! | Y13: =(X13-H13)/H13 -> #DIV/0! | Z13: =F13/F$16 -> 0
A14: Sub-Total | F14: =SUM(F6:F13) -> 427942.85 | G14: =SUM(G6:G13) -> 442670.79 | I14: =SUM(I6:I13) -> -14727.942
D15: Cash, other | F15: 77601 | G15: =F15/F16 -> 0.15350004
D16: Total | F16: =SUM(F14:F15) -> 505543.85
H17: Last week's close | I17: 511834.9
H18: Week's change | I18: =(F16-I17-F19)/I17 -> -0.012291174
M20: days
A21: 2023 Closed Trades - Managed Acct | D21: Qty | E21: Cost/sh | F21: $ cost | G21: Proc/sh | H21: $Proc | I21: Profit/loss | J21: % | K21: Date purch | L21: Date sold | M21: held | P21: Comments
A23: HXL | B23: Long | C23: Hexcel | D23: 665.9739 | E23: =F23/D23 -> 76.621621 | F23: 51028 | G23: 45324.79 | H23: =G23/D23 -> 68.057907 | I23: =G23-F23 -> -5703.21 | J23: =I23/F23 -> -0.11176629 | K23: 45106 | L23: 45132 | O23: Bad reaction to EPS report. Stopped out.

Sheet 08-04-23
C1: 45142
C3: MANAGED ACCT | X3: Current | AC3: IBD
H4: Cost | J4: P/L | N4: Group | P4: EPS | R4: pivot | S4: last | W4: cost | X4: Stop | Y4: Stop | Z4: % | AB4: EPS | AC4: Comp
A5: Symbol | B5: Position | C5: Name | D5: Qty | E5: Current | F5: Value | G5: Cost | H5: per share | I5: P/L $ | J5: per sh | K5: Date purch | L5: days held | M5: % incr | N5: Rank | O5: RS | P5: RS | Q5: pivot | R5: -0.07 | S5: low | T5: 0.25 | U5: 0.5 | V5: 1 | W5: -0.07 | X5: Loss | Y5: Loss% | Z5: of port | AB5: Due | AC5: Rank
F6: =E6*D6 -> 0 | H6: =G6/D6 -> #DIV/0! | I6: =F6-G6 -> 0 | J6: =E6-H6 -> #DIV/0! | L6: =DAYS360(K6,$C$1) -> 44494 | M6: =(I6/G6) -> #DIV/0! | R6: =Q6*0.93 -> 0 | T6: =Q6*1.25 -> 0 | U6: =Q6*1.5 -> 0 | V6: =Q6*2 -> 0 | W6: =H6-(H6*0.07) -> #DIV/0! | Y6: =(X6-H6)/H6 -> #DIV/0! | Z6: =F6/F$16 -> 0
F7: =E7*D7 -> 0 | H7: =G7/D7 -> #DIV/0! | I7: =F7-G7 -> 0 | J7: =E7-H7 -> #DIV/0! | L7: =DAYS360(K7,$C$1) -> 44494 | M7: =(I7/G7) -> #DIV/0! | R7: =Q7*0.93 -> 0 | T7: =Q7*1.25 -> 0 | U7: =Q7*1.5 -> 0 | V7: =Q7*2 -> 0 | W7: =H7-(H7*0.07) -> #DIV/0! | Y7: =(X7-H7)/H7 -> #DIV/0! | Z7: =F7/F$16 -> 0
F8: =E8*D8 -> 0 | H8: =G8/D8 -> #DIV/0! | I8: =F8-G8 -> 0 | J8: =E8-H8 -> #DIV/0! | L8: =DAYS360(K8,$C$1) -> 44494 | M8: =(I8/G8) -> #DIV/0! | R8: =Q8*0.93 -> 0 | T8: =Q8*1.25 -> 0 | U8: =Q8*1.5 -> 0 | V8: =Q8*2 -> 0 | W8: =H8-(H8*0.07) -> #DIV/0! | Y8: =(X8-H8)/H8 -> #DIV/0! | Z8: =F8/F$16 -> 0
A9: SNPS | B9: Long | C9: Synopsys | D9: 115.8536 | E9: 441.42 | F9: =E9*D9 -> 51140.096 | G9: 51225.83 | H9: =G9/D9 -> 442.16002 | I9: =F9-G9 -> -85.733888 | J9: =E9-H9 -> -0.7400192 | K9: 45117 | L9: =DAYS360(K9,$C$1) -> 24 | M9: =(I9/G9) -> -0.0016736457 | N9: 39 | O9: 90 | P9: 90 | Q9: 392.79 | R9: =Q9*0.93 -> 365.2947 | S9: 416.87 | T9: =Q9*1.25 -> 490.9875 | U9: =Q9*1.5 -> 589.185 | V9: =Q9*2 -> 785.58 | W9: =H9-(H9*0.07) -> 411.20882 | X9: 415 | Y9: =(X9-H9)/H9 -> -0.061425769 | Z9: =F9/F$16 -> 0.10178489 | AB9: 45154 | AC9: 96 | AD9: Bought when breaking out of bull flag in volume.
A10: MNSO | B10: Long | C10: Minoso | D10: 1211.7123 | E10: 20.97 | F10: =E10*D10 -> 25409.607 | G10: 25318.9 | H10: =G10/D10 -> 20.895142 | I10: =F10-G10 -> 90.706931 | J10: =E10-H10 -> 0.074858472 | K10: 45135 | L10: =DAYS360(K10,$C$1) -> 6 | M10: =(I10/G10) -> 0.0035825779 | N10: 150 | O10: 99 | P10: 98 | Q10: 19.48 | R10: =Q10*0.93 -> 18.1164 | S10: 17.57 | T10: =Q10*1.25 -> 24.35 | U10: =Q10*1.5 -> 29.22 | V10: =Q10*2 -> 38.96 | W10: =H10-(H10*0.07) -> 19.432482 | X10: 18.12 | Y10: =(X10-H10)/H10 -> -0.13281277 | Z10: =F10/F$16 -> 0.050573118 | AB10: 45162 | AC10: 95 | AD10: Bought after 07/24 b/o.
A11: BIL | B11: Long | C11: Tbill ETF | D11: 2778.4118 | E11: 91.5 | F11: =E11*D11 -> 254224.68 | G11: 254613.66 | H11: =G11/D11 -> 91.640001 | I11: =F11-G11 -> -388.9803 | J11: =E11-H11 -> -0.14000095 | L11: =DAYS360(K11,$C$1) -> 44494 | M11: =(I11/G11) -> -0.0015277275 | R11: =Q11*0.93 -> 0 | T11: =Q11*1.25 -> 0 | U11: =Q11*1.5 -> 0 | V11: =Q11*2 -> 0 | W11: =H11-(H11*0.07) -> 85.225201 | Y11: =(X11-H11)/H11 -> -1 | Z11: =F11/F$16 -> 0.50598715
A12: SQQQ | B12: Long | C12: QQQ Triple short | D12: 511.2918 | E12: 18.57 | F12: =E12*D12 -> 9494.6887 | G12: 24797.66 | H12: =G12/D12 -> 48.500015 | I12: =F12-G12 -> -15302.971 | J12: =E12-H12 -> -29.930015 | L12: =DAYS360(K12,$C$1) -> 44494 | M12: =(I12/G12) -> -0.61711352 | R12: =Q12*0.93 -> 0 | T12: =Q12*1.25 -> 0 | U12: =Q12*1.5 -> 0 | V12: =Q12*2 -> 0 | W12: =H12-(H12*0.07) -> 45.105014 | Y12: =(X12-H12)/H12 -> -1 | Z12: =F12/F$16 -> 0.01889742
F13: =E13*D13 -> 0 | H13: =G13/D13 -> #DIV/0! | I13: =F13-G13 -> 0 | J13: =E13-H13 -> #DIV/0! | L13: =DAYS360(K13,$C$1) -> 44494 | M13: =(I13/G13) -> #DIV/0! | R13: =Q13*0.93 -> 0 | T13: =Q13*1.25 -> 0 | U13: =Q13*1.5 -> 0 | V13: =Q13*2 -> 0 | W13: =H13-(H13*0.07) -> #DIV/0! | Y13: =(X13-H13)/H13 -> #DIV/0! | Z13: =F13/F$16 -> 0
A14: Sub-Total | F14: =SUM(F6:F13) -> 340269.07 | G14: =SUM(G6:G13) -> 355956.05 | I14: =SUM(I6:I13) -> -15686.979
D15: Cash, other | F15: 162164 | G15: =F15/F16 -> 0.32275742
D16: Total | F16: =SUM(F14:F15) -> 502433.07
H17: Last week's close | I17: 505543.83
H18: Week's change | I18: =(F16-I17-F19)/I17 -> -0.0061532915
M20: days
A21: 2023 Closed Trades - Managed Acct | D21: Qty | E21: Cost/sh | F21: $ cost | G21: $Proc | H21: Proc/sh | I21: Profit/loss | J21: % | K21: Date purch | L21: Date sold | M21: held | P21: Comments
A23: HXL | B23: Long | C23: Hexcel | D23: 665.9739 | E23: =F23/D23 -> 76.621621 | F23: 51028 | G23: 45324.79 | H23: =G23/D23 -> 68.057907 | I23: =G23-F23 -> -5703.21 | J23: =I23/F23 -> -0.11176629 | K23: 45106 | L23: 45132 | O23: Bad reaction to EPS report. Stopped out.
A24: MCK | B24: Long | C24: McKesson | D24: 123.3931 | E24: =F24/D24 -> 413.24004 | F24: 50990.97 | G24: 48894.94 | H24: =G24/D24 -> 396.25344 | I24: =G24-F24 -> -2096.03 | J24: =I24/F24 -> -0.041105906 | K24: 45104 | L24: 45138 | O24: Broke original stop and 50dma. EPS coming in a few days.
A25: DXCM | B25: Long | C25: DexCom | D25: 278.2008 | E25: =F25/D25 -> 128.41002 | F25: 35723.77 | G25: 34855.72 | H25: =G25/D25 -> 125.28979 | I25: =G25-F25 -> -868.05 | J25: =I25/F25 -> -0.024298947 | K25: 45106 | L25: 45138 | O25: The positive reaction to EPS report was rejected at the old high and reversed. Didn't like the action.

Sheet 08-11-23
C1: 45149
C3: MANAGED ACCT | X3: Current | AC3: IBD
H4: Cost | J4: P/L | N4: Group | P4: EPS | R4: pivot | S4: last | W4: cost | X4: Stop | Y4: Stop | Z4: % | AB4: EPS | AC4: Comp
A5: Symbol | B5: Position | C5: Name | D5: Qty | E5: Current | F5: Value | G5: Cost | H5: per share | I5: P/L $ | J5: per sh | K5: Date purch | L5: days held | M5: % incr | N5: Rank | O5: RS | P5: RS | Q5: pivot | R5: -0.07 | S5: low | T5: 0.25 | U5: 0.5 | V5: 1 | W5: -0.07 | X5: Loss | Y5: Loss% | Z5: of port | AB5: Due | AC5: Rank
F6: =E6*D6 -> 0 | H6: =G6/D6 -> #DIV/0! | I6: =F6-G6 -> 0 | J6: =E6-H6 -> #DIV/0! | L6: =DAYS360(K6,$C$1) -> 44501 | M6: =(I6/G6) -> #DIV/0! | R6: =Q6*0.93 -> 0 | T6: =Q6*1.25 -> 0 | U6: =Q6*1.5 -> 0 | V6: =Q6*2 -> 0 | W6: =H6-(H6*0.07) -> #DIV/0! | Y6: =(X6-H6)/H6 -> #DIV/0! | Z6: =F6/F$16 -> 0
F7: =E7*D7 -> 0 | H7: =G7/D7 -> #DIV/0! | I7: =F7-G7 -> 0 | J7: =E7-H7 -> #DIV/0! | L7: =DAYS360(K7,$C$1) -> 44501 | M7: =(I7/G7) -> #DIV/0! | R7: =Q7*0.93 -> 0 | T7: =Q7*1.25 -> 0 | U7: =Q7*1.5 -> 0 | V7: =Q7*2 -> 0 | W7: =H7-(H7*0.07) -> #DIV/0! | Y7: =(X7-H7)/H7 -> #DIV/0! | Z7: =F7/F$16 -> 0
F8: =E8*D8 -> 0 | H8: =G8/D8 -> #DIV/0! | I8: =F8-G8 -> 0 | J8: =E8-H8 -> #DIV/0! | L8: =DAYS360(K8,$C$1) -> 44501 | M8: =(I8/G8) -> #DIV/0! | R8: =Q8*0.93 -> 0 | T8: =Q8*1.25 -> 0 | U8: =Q8*1.5 -> 0 | V8: =Q8*2 -> 0 | W8: =H8-(H8*0.07) -> #DIV/0! | Y8: =(X8-H8)/H8 -> #DIV/0! | Z8: =F8/F$16 -> 0
A9: SNPS | B9: Long | C9: Synopsys | D9: 115.8536 | E9: 428.46 | F9: =E9*D9 -> 49638.633 | G9: 51225.83 | H9: =G9/D9 -> 442.16002 | I9: =F9-G9 -> -1587.1965 | J9: =E9-H9 -> -13.700019 | K9: 45117 | L9: =DAYS360(K9,$C$1) -> 31 | M9: =(I9/G9) -> -0.030984301 | N9: 64 | O9: 87 | P9: 90 | Q9: 392.79 | R9: =Q9*0.93 -> 365.2947 | S9: 416.87 | T9: =Q9*1.25 -> 490.9875 | U9: =Q9*1.5 -> 589.185 | V9: =Q9*2 -> 785.58 | W9: =H9-(H9*0.07) -> 411.20882 | X9: 415 | Y9: =(X9-H9)/H9 -> -0.061425769 | Z9: =F9/F$16 -> 0.099218525 | AB9: 45154 | AC9: 93 | AD9: Bought when breaking out of bull flag in volume.
A10: MNSO | B10: Long | C10: Minoso | D10: =1211.7123+804.6763 -> 2016.3886 | E10: 19.12 | F10: =E10*D10 -> 38553.35 | G10: =25318.9+15999 -> 41317.9 | H10: =G10/D10 -> 20.49104 | I10: =F10-G10 -> -2764.55 | J10: =E10-H10 -> -1.3710403 | K10: 45135 | L10: =DAYS360(K10,$C$1) -> 13 | M10: =(I10/G10) -> -0.066909256 | N10: 161 | O10: 98 | P10: 98 | Q10: 19.48 | R10: =Q10*0.93 -> 18.1164 | S10: 17.57 | T10: =Q10*1.25 -> 24.35 | U10: =Q10*1.5 -> 29.22 | V10: =Q10*2 -> 38.96 | W10: =H10-(H10*0.07) -> 19.056667 | X10: 18.12 | Y10: =(X10-H10)/H10 -> -0.11571107 | Z10: =F10/F$16 -> 0.077061076 | AB10: 45162 | AC10: 92 | AD10: Bought after 07/24 b/o. Added at the 21dema.
A11: BIL | B11: Long | C11: Tbill ETF | D11: 2778.4118 | E11: 91.59 | F11: =E11*D11 -> 254474.74 | G11: 254613.66 | H11: =G11/D11 -> 91.640001 | I11: =F11-G11 -> -138.92324 | J11: =E11-H11 -> -0.050000953 | L11: =DAYS360(K11,$C$1) -> 44501 | M11: =(I11/G11) -> -0.00054562366 | R11: =Q11*0.93 -> 0 | T11: =Q11*1.25 -> 0 | U11: =Q11*1.5 -> 0 | V11: =Q11*2 -> 0 | W11: =H11-(H11*0.07) -> 85.225201 | Y11: =(X11-H11)/H11 -> -1 | Z11: =F11/F$16 -> 0.50864833
A12: SQQQ | B12: Long | C12: QQQ Triple short | D12: 511.2918 | E12: 19.51 | F12: =E12*D12 -> 9975.303 | G12: 24797.66 | H12: =G12/D12 -> 48.500015 | I12: =F12-G12 -> -14822.357 | J12: =E12-H12 -> -28.990015 | L12: =DAYS360(K12,$C$1) -> 44501 | M12: =(I12/G12) -> -0.59773208 | R12: =Q12*0.93 -> 0 | T12: =Q12*1.25 -> 0 | U12: =Q12*1.5 -> 0 | V12: =Q12*2 -> 0 | W12: =H12-(H12*0.07) -> 45.105014 | Y12: =(X12-H12)/H12 -> -1 | Z12: =F12/F$16 -> 0.019938801
F13: =E13*D13 -> 0 | H13: =G13/D13 -> #DIV/0! | I13: =F13-G13 -> 0 | J13: =E13-H13 -> #DIV/0! | L13: =DAYS360(K13,$C$1) -> 44501 | M13: =(I13/G13) -> #DIV/0! | R13: =Q13*0.93 -> 0 | T13: =Q13*1.25 -> 0 | U13: =Q13*1.5 -> 0 | V13: =Q13*2 -> 0 | W13: =H13-(H13*0.07) -> #DIV/0! | Y13: =(X13-H13)/H13 -> #DIV/0! | Z13: =F13/F$16 -> 0
A14: Sub-Total | F14: =SUM(F6:F13) -> 352642.02 | G14: =SUM(G6:G13) -> 371955.05 | I14: =SUM(I6:I13) -> -19313.027
D15: Cash, other | F15: 147654 | G15: =F15/F16 -> 0.29513327
D16: Total | F16: =SUM(F14:F15) -> 500296.02
H17: Last week's close | I17: 502433.07 | K17: 45107 | L17: 509801
H18: Week's change | I18: =(F16-I17-F19)/I17 -> -0.0042533958 | K18: chg % | L18: =(F16-L17)/L17 -> -0.018644484
M20: days
A21: 2023 Closed Trades - Managed Acct | D21: Qty | E21: Cost/sh | F21: $ cost | G21: $Proc | H21: Proc/sh | I21: Profit/loss | J21: % | K21: Date purch | L21: Date sold | M21: held | P21: Comments
A23: HXL | B23: Long | C23: Hexcel | D23: 665.9739 | E23: =F23/D23 -> 76.621621 | F23: 51028 | G23: 45324.79 | H23: =G23/D23 -> 68.057907 | I23: =G23-F23 -> -5703.21 | J23: =I23/F23 -> -0.11176629 | K23: 45106 | L23: 45132 | O23: Bad reaction to EPS report. Stopped out.
A24: MCK | B24: Long | C24: McKesson | D24: 123.3931 | E24: =F24/D24 -> 413.24004 | F24: 50990.97 | G24: 48894.94 | H24: =G24/D24 -> 396.25344 | I24: =G24-F24 -> -2096.03 | J24: =I24/F24 -> -0.041105906 | K24: 45104 | L24: 45138 | O24: Broke original stop and 50dma. EPS coming in a few days.
A25: DXCM | B25: Long | C25: DexCom | D25: 278.2008 | E25: =F25/D25 -> 128.41002 | F25: 35723.77 | G25: 34855.72 | H25: =G25/D25 -> 125.28979 | I25: =G25-F25 -> -868.05 | J25: =I25/F25 -> -0.024298947 | K25: 45106 | L25: 45138 | O25: The positive reaction to EPS report was rejected at the old high and reversed. Didn't like the action.

Sheet 08-18-23
C1: 45156
C3: MANAGED ACCT | X3: Current | AC3: IBD
H4: Cost | J4: P/L | N4: Group | P4: EPS | R4: pivot | S4: last | W4: cost | X4: Stop | Y4: Stop | Z4: % | AB4: EPS | AC4: Comp
A5: Symbol | B5: Position | C5: Name | D5: Qty | E5: Current | F5: Value | G5: Cost | H5: per share | I5: P/L $ | J5: per sh | K5: Date purch | L5: days held | M5: % incr | N5: Rank | O5: RS | P5: RS | Q5: pivot | R5: -0.07 | S5: low | T5: 0.25 | U5: 0.5 | V5: 1 | W5: -0.07 | X5: Loss | Y5: Loss% | Z5: of port | AB5: Due | AC5: Rank
F6: =E6*D6 -> 0 | H6: =G6/D6 -> #DIV/0! | I6: =F6-G6 -> 0 | J6: =E6-H6 -> #DIV/0! | L6: =DAYS360(K6,$C$1) -> 44508 | M6: =(I6/G6) -> #DIV/0! | R6: =Q6*0.93 -> 0 | T6: =Q6*1.25 -> 0 | U6: =Q6*1.5 -> 0 | V6: =Q6*2 -> 0 | W6: =H6-(H6*0.07) -> #DIV/0! | Y6: =(X6-H6)/H6 -> #DIV/0! | Z6: =F6/F$16 -> 0
F7: =E7*D7 -> 0 | H7: =G7/D7 -> #DIV/0! | I7: =F7-G7 -> 0 | J7: =E7-H7 -> #DIV/0! | L7: =DAYS360(K7,$C$1) -> 44508 | M7: =(I7/G7) -> #DIV/0! | R7: =Q7*0.93 -> 0 | T7: =Q7*1.25 -> 0 | U7: =Q7*1.5 -> 0 | V7: =Q7*2 -> 0 | W7: =H7-(H7*0.07) -> #DIV/0! | Y7: =(X7-H7)/H7 -> #DIV/0! | Z7: =F7/F$16 -> 0
A8: AIT | B8: Long | C8: Applied Ind Tec | D8: 266.8733 | E8: 147.4 | F8: =E8*D8 -> 39337.124 | G8: 40425.83 | H8: =G8/D8 -> 151.47948 | I8: =F8-G8 -> -1088.7056 | J8: =E8-H8 -> -4.0794848 | K8: 45153 | L8: =DAYS360(K8,$C$1) -> 3 | M8: =(I8/G8) -> -0.026930939 | N8: 110 | O8: 88 | P8: 94 | Q8: 150.07 | R8: =Q8*0.93 -> 139.5651 | S8: 138.38 | T8: =Q8*1.25 -> 187.5875 | U8: =Q8*1.5 -> 225.105 | V8: =Q8*2 -> 300.14 | W8: =H8-(H8*0.07) -> 140.87592 | X8: 145.2 | Y8: =(X8-H8)/H8 -> -0.041454358 | Z8: =F8/F$16 -> 0.078368319 | AB8: 45225 | AC8: 91 | AD8: Bought at pivot test area.
A9: SNPS | B9: Long | C9: Synopsys | D9: 115.8536 | E9: 426.02 | F9: =E9*D9 -> 49355.951 | G9: 51225.83 | H9: =G9/D9 -> 442.16002 | I9: =F9-G9 -> -1869.8793 | J9: =E9-H9 -> -16.140019 | K9: 45117 | L9: =DAYS360(K9,$C$1) -> 38 | M9: =(I9/G9) -> -0.036502665 | N9: 77 | O9: 88 | P9: 95 | Q9: 392.79 | R9: =Q9*0.93 -> 365.2947 | S9: 416.87 | T9: =Q9*1.25 -> 490.9875 | U9: =Q9*1.5 -> 589.185 | V9: =Q9*2 -> 785.58 | W9: =H9-(H9*0.07) -> 411.20882 | X9: 415 | Y9: =(X9-H9)/H9 -> -0.061425769 | Z9: =F9/F$16 -> 0.098328054 | AB9: 45259 | AC9: 97 | AD9: Bought when breaking out of bull flag in volume.
A10: MNSO | B10: Long | C10: Minoso | D10: =1211.7123+804.6763 -> 2016.3886 | E10: 20.15 | F10: =E10*D10 -> 40630.23 | G10: =25318.9+15999 -> 41317.9 | H10: =G10/D10 -> 20.49104 | I10: =F10-G10 -> -687.66971 | J10: =E10-H10 -> -0.34104027 | K10: 45135 | L10: =DAYS360(K10,$C$1) -> 20 | M10: =(I10/G10) -> -0.016643385 | N10: 144 | O10: 99 | P10: 98 | Q10: 19.48 | R10: =Q10*0.93 -> 18.1164 | S10: 17.57 | T10: =Q10*1.25 -> 24.35 | U10: =Q10*1.5 -> 29.22 | V10: =Q10*2 -> 38.96 | W10: =H10-(H10*0.07) -> 19.056667 | X10: 18.12 | Y10: =(X10-H10)/H10 -> -0.11571107 | Z10: =F10/F$16 -> 0.080944474 | AB10: 45160 | AC10: 96 | AD10: Bought after 07/24 b/o. Added at the 21dema.
A11: BIL | B11: Long | C11: Tbill ETF | D11: 2778.4118 | E11: 91.68 | F11: =E11*D11 -> 254724.79 | G11: 254613.66 | H11: =G11/D11 -> 91.640001 | I11: =F11-G11 -> 111.13382 | J11: =E11-H11 -> 0.039999047 | L11: =DAYS360(K11,$C$1) -> 44508 | M11: =(I11/G11) -> 0.00043648021 | R11: =Q11*0.93 -> 0 | T11: =Q11*1.25 -> 0 | U11: =Q11*1.5 -> 0 | V11: =Q11*2 -> 0 | W11: =H11-(H11*0.07) -> 85.225201 | Y11: =(X11-H11)/H11 -> -1 | Z11: =F11/F$16 -> 0.50746856
A12: SQQQ | B12: Long | C12: QQQ Triple short | D12: 511.2918 | E12: 20.88 | F12: =E12*D12 -> 10675.773 | G12: 24797.66 | H12: =G12/D12 -> 48.500015 | I12: =F12-G12 -> -14121.887 | J12: =E12-H12 -> -27.620015 | L12: =DAYS360(K12,$C$1) -> 44508 | M12: =(I12/G12) -> -0.56948467 | R12: =Q12*0.93 -> 0 | T12: =Q12*1.25 -> 0 | U12: =Q12*1.5 -> 0 | V12: =Q12*2 -> 0 | W12: =H12-(H12*0.07) -> 45.105014 | Y12: =(X12-H12)/H12 -> -1 | Z12: =F12/F$16 -> 0.021268519
F13: =E13*D13 -> 0 | H13: =G13/D13 -> #DIV/0! | I13: =F13-G13 -> 0 | J13: =E13-H13 -> #DIV/0! | L13: =DAYS360(K13,$C$1) -> 44508 | M13: =(I13/G13) -> #DIV/0! | R13: =Q13*0.93 -> 0 | T13: =Q13*1.25 -> 0 | U13: =Q13*1.5 -> 0 | V13: =Q13*2 -> 0 | W13: =H13-(H13*0.07) -> #DIV/0! | Y13: =(X13-H13)/H13 -> #DIV/0! | Z13: =F13/F$16 -> 0
A14: Sub-Total | F14: =SUM(F6:F13) -> 394723.87 | G14: =SUM(G6:G13) -> 412380.88 | I14: =SUM(I6:I13) -> -17657.008
D15: Cash, other | F15: 107228 | G15: =F15/F16 -> 0.21362207
D16: Total | F16: =SUM(F14:F15) -> 501951.87
H17: Last week's close | I17: 500296.07 | K17: 45107 | L17: 509801
H18: Week's change | I18: =(F16-I17-F19)/I17 -> 0.0033096442 | K18: chg % | L18: =(F16-L17)/L17 -> -0.015396455
M20: days
A21: 2023 Closed Trades - Managed Acct | D21: Qty | E21: Cost/sh | F21: $ cost | G21: $Proc | H21: Proc/sh | I21: Profit/loss | J21: % | K21: Date purch | L21: Date sold | M21: held | P21: Comments
A23: HXL | B23: Long | C23: Hexcel | D23: 665.9739 | E23: =F23/D23 -> 76.621621 | F23: 51028 | G23: 45324.79 | H23: =G23/D23 -> 68.057907 | I23: =G23-F23 -> -5703.21 | J23: =I23/F23 -> -0.11176629 | K23: 45106 | L23: 45132 | O23: Bad reaction to EPS report. Stopped out.
A24: MCK | B24: Long | C24: McKesson | D24: 123.3931 | E24: =F24/D24 -> 413.24004 | F24: 50990.97 | G24: 48894.94 | H24: =G24/D24 -> 396.25344 | I24: =G24-F24 -> -2096.03 | J24: =I24/F24 -> -0.041105906 | K24: 45104 | L24: 45138 | O24: Broke original stop and 50dma. EPS coming in a few days.
A25: DXCM | B25: Long | C25: DexCom | D25: 278.2008 | E25: =F25/D25 -> 128.41002 | F25: 35723.77 | G25: 34855.72 | H25: =G25/D25 -> 125.28979 | I25: =G25-F25 -> -868.05 | J25: =I25/F25 -> -0.024298947 | K25: 45106 | L25: 45138 | O25: The positive reaction to EPS report was rejected at the old high and reversed. Didn't like the action.
J31: Avg
H32: # of losses | I32: 3 | J32: =(J23+J24+J25)/3 -> -0.059057046

Sheet 08-25-23
C1: 45163
C3: MANAGED ACCT | X3: Current | AC3: IBD
H4: Cost | J4: P/L | N4: Group | P4: EPS | R4: pivot | S4: last | W4: cost | X4: Stop | Y4: Stop | Z4: % | AB4: EPS | AC4: Comp
A5: Symbol | B5: Position | C5: Name | D5: Qty | E5: Current | F5: Value | G5: Cost | H5: per share | I5: P/L $ | J5: per sh | K5: Date purch | L5: days held | M5: % incr | N5: Rank | O5: RS | P5: RS | Q5: pivot | R5: -0.07 | S5: low | T5: 0.25 | U5: 0.5 | V5: 1 | W5: -0.07 | X5: Loss | Y5: Loss% | Z5: of port | AB5: Due | AC5: Rank
F6: =E6*D6 -> 0 | H6: =G6/D6 -> #DIV/0! | I6: =F6-G6 -> 0 | J6: =E6-H6 -> #DIV/0! | L6: =DAYS360(K6,$C$1) -> 44515 | M6: =(I6/G6) -> #DIV/0! | R6: =Q6*0.93 -> 0 | T6: =Q6*1.25 -> 0 | U6: =Q6*1.5 -> 0 | V6: =Q6*2 -> 0 | W6: =H6-(H6*0.07) -> #DIV/0! | Y6: =(X6-H6)/H6 -> #DIV/0! | Z6: =F6/F$16 -> 0
F7: =E7*D7 -> 0 | H7: =G7/D7 -> #DIV/0! | I7: =F7-G7 -> 0 | J7: =E7-H7 -> #DIV/0! | L7: =DAYS360(K7,$C$1) -> 44515 | M7: =(I7/G7) -> #DIV/0! | R7: =Q7*0.93 -> 0 | T7: =Q7*1.25 -> 0 | U7: =Q7*1.5 -> 0 | V7: =Q7*2 -> 0 | W7: =H7-(H7*0.07) -> #DIV/0! | Y7: =(X7-H7)/H7 -> #DIV/0! | Z7: =F7/F$16 -> 0
A8: AIT | B8: Long | C8: Applied Ind Tec | D8: 266.8733 | E8: 153.98 | F8: =E8*D8 -> 41093.151 | G8: 40425.83 | H8: =G8/D8 -> 151.47948 | I8: =F8-G8 -> 667.32073 | J8: =E8-H8 -> 2.5005152 | K8: 45153 | L8: =DAYS360(K8,$C$1) -> 10 | M8: =(I8/G8) -> 0.016507286 | N8: 91 | O8: 91 | P8: 94 | Q8: 150.07 | R8: =Q8*0.93 -> 139.5651 | S8: 138.38 | T8: =Q8*1.25 -> 187.5875 | U8: =Q8*1.5 -> 225.105 | V8: =Q8*2 -> 300.14 | W8: =H8-(H8*0.07) -> 140.87592 | X8: 145.2 | Y8: =(X8-H8)/H8 -> -0.041454358 | Z8: =F8/F$16 -> 0.080531285 | AB8: 45225 | AC8: 93 | AD8: Bought at pivot test area.
A9: SNPS | B9: Long | C9: Synopsys | D9: 115.8536 | E9: 442.24 | F9: =E9*D9 -> 51235.096 | G9: 51225.83 | H9: =G9/D9 -> 442.16002 | I9: =F9-G9 -> 9.266064 | J9: =E9-H9 -> 0.079980803 | K9: 45117 | L9: =DAYS360(K9,$C$1) -> 45 | M9: =(I9/G9) -> 0.00018088656 | N9: 89 | O9: 87 | P9: 95 | Q9: 392.79 | R9: =Q9*0.93 -> 365.2947 | S9: 416.87 | T9: =Q9*1.25 -> 490.9875 | U9: =Q9*1.5 -> 589.185 | V9: =Q9*2 -> 785.58 | W9: =H9-(H9*0.07) -> 411.20882 | X9: 415 | Y9: =(X9-H9)/H9 -> -0.061425769 | Z9: =F9/F$16 -> 0.10040671 | AB9: 45259 | AC9: 97 | AD9: Bought when breaking out of bull flag in volume.
A10: MNSO | B10: Long | C10: Minoso | D10: =1211.7123+804.6763 -> 2016.3886 | E10: 22.62 | F10: =E10*D10 -> 45610.71 | G10: =25318.9+15999 -> 41317.9 | H10: =G10/D10 -> 20.49104 | I10: =F10-G10 -> 4292.8101 | J10: =E10-H10 -> 2.1289597 | K10: 45135 | L10: =DAYS360(K10,$C$1) -> 27 | M10: =(I10/G10) -> 0.1038971 | N10: 181 | O10: 99 | P10: 99 | Q10: 19.48 | R10: =Q10*0.93 -> 18.1164 | S10: 17.57 | T10: =Q10*1.25 -> 24.35 | U10: =Q10*1.5 -> 29.22 | V10: =Q10*2 -> 38.96 | W10: =H10-(H10*0.07) -> 19.056667 | X10: 20.5 | Y10: =(X10-H10)/H10 -> 0.00043725117 | Z10: =F10/F$16 -> 0.08938446 | AB10: 45245 | AC10: 97 | AD10: Bought after 07/24 b/o. Added at the 21dema.
A11: BIL | B11: Long | C11: Tbill ETF | D11: 2778.4118 | E11: 91.77 | F11: =E11*D11 -> 254974.85 | G11: 254613.66 | H11: =G11/D11 -> 91.640001 | I11: =F11-G11 -> 361.19089 | J11: =E11-H11 -> 0.12999905 | L11: =DAYS360(K11,$C$1) -> 44515 | M11: =(I11/G11) -> 0.0014185841 | R11: =Q11*0.93 -> 0 | T11: =Q11*1.25 -> 0 | U11: =Q11*1.5 -> 0 | V11: =Q11*2 -> 0 | W11: =H11-(H11*0.07) -> 85.225201 | Y11: =(X11-H11)/H11 -> -1 | Z11: =F11/F$16 -> 0.49968065
A12: SQQQ | B12: Long | C12: QQQ Triple short | D12: 511.2918 | E12: 19.82 | F12: =E12*D12 -> 10133.803 | G12: 24797.66 | H12: =G12/D12 -> 48.500015 | I12: =F12-G12 -> -14663.857 | J12: =E12-H12 -> -28.680015 | L12: =DAYS360(K12,$C$1) -> 44515 | M12: =(I12/G12) -> -0.59134033 | R12: =Q12*0.93 -> 0 | T12: =Q12*1.25 -> 0 | U12: =Q12*1.5 -> 0 | V12: =Q12*2 -> 0 | W12: =H12-(H12*0.07) -> 45.105014 | Y12: =(X12-H12)/H12 -> -1 | Z12: =F12/F$16 -> 0.019859471
F13: =E13*D13 -> 0 | H13: =G13/D13 -> #DIV/0! | I13: =F13-G13 -> 0 | J13: =E13-H13 -> #DIV/0! | L13: =DAYS360(K13,$C$1) -> 44515 | M13: =(I13/G13) -> #DIV/0! | R13: =Q13*0.93 -> 0 | T13: =Q13*1.25 -> 0 | U13: =Q13*1.5 -> 0 | V13: =Q13*2 -> 0 | W13: =H13-(H13*0.07) -> #DIV/0! | Y13: =(X13-H13)/H13 -> #DIV/0! | Z13: =F13/F$16 -> 0
A14: Sub-Total | F14: =SUM(F6:F13) -> 403047.61 | G14: =SUM(G6:G13) -> 412380.88 | I14: =SUM(I6:I13) -> -9333.2687
D15: Cash, other | F15: 107228 | G15: =F15/F16 -> 0.21013742
D16: Total | F16: =SUM(F14:F15) -> 510275.61
H17: Last week's close | I17: 501951.87 | K17: 45107 | L17: 509801
H18: Week's change | I18: =(F16-I17-F19)/I17 -> 0.016582748 | K18: chg % | L18: =(F16-L17)/L17 -> 0.00093097364
M20: days
A21: 2023 Closed Trades - Managed Acct | D21: Qty | E21: Cost/sh | F21: $ cost | G21: $Proc | H21: Proc/sh | I21: Profit/loss | J21: % | K21: Date purch | L21: Date sold | M21: held | P21: Comments
A23: HXL | B23: Long | C23: Hexcel | D23: 665.9739 | E23: =F23/D23 -> 76.621621 | F23: 51028 | G23: 45324.79 | H23: =G23/D23 -> 68.057907 | I23: =G23-F23 -> -5703.21 | J23: =I23/F23 -> -0.11176629 | K23: 45106 | L23: 45132 | O23: Bad reaction to EPS report. Stopped out.
A24: MCK | B24: Long | C24: McKesson | D24: 123.3931 | E24: =F24/D24 -> 413.24004 | F24: 50990.97 | G24: 48894.94 | H24: =G24/D24 -> 396.25344 | I24: =G24-F24 -> -2096.03 | J24: =I24/F24 -> -0.041105906 | K24: 45104 | L24: 45138 | O24: Broke original stop and 50dma. EPS coming in a few days.
A25: DXCM | B25: Long | C25: DexCom | D25: 278.2008 | E25: =F25/D25 -> 128.41002 | F25: 35723.77 | G25: 34855.72 | H25: =G25/D25 -> 125.28979 | I25: =G25-F25 -> -868.05 | J25: =I25/F25 -> -0.024298947 | K25: 45106 | L25: 45138 | O25: The positive reaction to EPS report was rejected at the old high and reversed. Didn't like the action.
I31: =SUM(I23:I30) -> -8667.29 | J31: Avg
H32: # of losses | I32: 3 | J32: =(J23+J24+J25)/3 -> -0.059057046

Sheet 09-01-23
C1: 45170
C3: MANAGED ACCT | X3: Current | AC3: IBD
H4: Cost | J4: P/L | N4: Group | P4: EPS | R4: pivot | S4: last | W4: cost | X4: Stop | Y4: Stop | Z4: % | AB4: EPS | AC4: Comp
A5: Symbol | B5: Position | C5: Name | D5: Qty | E5: Current | F5: Value | G5: Cost | H5: per share | I5: P/L $ | J5: per sh | K5: Date purch | L5: days held | M5: % incr | N5: Rank | O5: RS | P5: RS | Q5: pivot | R5: -0.07 | S5: low | T5: 0.25 | U5: 0.5 | V5: 1 | W5: -0.07 | X5: Loss | Y5: Loss% | Z5: of port | AB5: Due | AC5: Rank
F6: =E6*D6 -> 0 | H6: =G6/D6 -> #DIV/0! | I6: =F6-G6 -> 0 | J6: =E6-H6 -> #DIV/0! | L6: =DAYS360(K6,$C$1) -> 44521 | M6: =(I6/G6) -> #DIV/0! | R6: =Q6*0.93 -> 0 | T6: =Q6*1.25 -> 0 | U6: =Q6*1.5 -> 0 | V6: =Q6*2 -> 0 | W6: =H6-(H6*0.07) -> #DIV/0! | Y6: =(X6-H6)/H6 -> #DIV/0! | Z6: =F6/F$16 -> 0
A7: MTSI | B7: Long | C7: MACOM Tech Sol | D7: 507.0754 | E7: 83.12 | F7: 41156.14 | G7: 41151 | H7: =G7/D7 -> 81.153611 | I7: =F7-G7 -> 5.14 | J7: =E7-H7 -> 1.9663885 | K7: 45167 | L7: =DAYS360(K7,$C$1) -> 2 | M7: =(I7/G7) -> 0.00012490583 | N7: 130 | O7: 93 | P7: 90 | Q7: 77.47 | R7: =Q7*0.93 -> 72.0471 | S7: 70.6 | T7: =Q7*1.25 -> 96.8375 | U7: =Q7*1.5 -> 116.205 | V7: =Q7*2 -> 154.94 | W7: =H7-(H7*0.07) -> 75.472859 | X7: 75.75 | Y7: =(X7-H7)/H7 -> -0.066584978 | Z7: =F7/F$16 -> 0.079378129 | AB7: 45244 | AC7: 89 | AD7: B/o on 08/23. Bought after pivot test.
A8: AIT | B8: Long | C8: Applied Ind Tec | D8: 266.8733 | E8: 157.08 | F8: =E8*D8 -> 41920.458 | G8: 40425.83 | H8: =G8/D8 -> 151.47948 | I8: =F8-G8 -> 1494.628 | J8: =E8-H8 -> 5.6005152 | K8: 45153 | L8: =DAYS360(K8,$C$1) -> 16 | M8: =(I8/G8) -> 0.036972103 | N8: 91 | O8: 91 | P8: 94 | Q8: 150.07 | R8: =Q8*0.93 -> 139.5651 | S8: 138.38 | T8: =Q8*1.25 -> 187.5875 | U8: =Q8*1.5 -> 225.105 | V8: =Q8*2 -> 300.14 | W8: =H8-(H8*0.07) -> 140.87592 | X8: 145.2 | Y8: =(X8-H8)/H8 -> -0.041454358 | Z8: =F8/F$16 -> 0.080852275 | AB8: 45225 | AC8: 93 | AD8: Bought at pivot test area.
A9: SNPS | B9: Long | C9: Synopsys | D9: 115.8536 | E9: 460.45 | F9: =E9*D9 -> 53344.79 | G9: 51225.83 | H9: =G9/D9 -> 442.16002 | I9: =F9-G9 -> 2118.9601 | J9: =E9-H9 -> 18.289981 | K9: 45117 | L9: =DAYS360(K9,$C$1) -> 51 | M9: =(I9/G9) -> 0.041365071 | N9: 89 | O9: 87 | P9: 95 | Q9: 392.79 | R9: =Q9*0.93 -> 365.2947 | S9: 416.87 | T9: =Q9*1.25 -> 490.9875 | U9: =Q9*1.5 -> 589.185 | V9: =Q9*2 -> 785.58 | W9: =H9-(H9*0.07) -> 411.20882 | X9: 415 | Y9: =(X9-H9)/H9 -> -0.061425769 | Z9: =F9/F$16 -> 0.10288646 | AB9: 45259 | AC9: 97 | AD9: Bought when breaking out of bull flag in volume.
A10: MNSO | B10: Long | C10: Minoso | D10: =1211.7123+804.6763 -> 2016.3886 | E10: 26.07 | F10: =E10*D10 -> 52567.251 | G10: =25318.9+15999 -> 41317.9 | H10: =G10/D10 -> 20.49104 | I10: =F10-G10 -> 11249.351 | J10: =E10-H10 -> 5.5789597 | K10: 45135 | L10: =DAYS360(K10,$C$1) -> 33 | M10: =(I10/G10) -> 0.27226337 | N10: 181 | O10: 99 | P10: 99 | Q10: 19.48 | R10: =Q10*0.93 -> 18.1164 | S10: 17.57 | T10: =Q10*1.25 -> 24.35 | U10: =Q10*1.5 -> 29.22 | V10: =Q10*2 -> 38.96 | W10: =H10-(H10*0.07) -> 19.056667 | X10: 20.5 | Y10: =(X10-H10)/H10 -> 0.00043725117 | Z10: =F10/F$16 -> 0.10138682 | AB10: 45245 | AC10: 97 | AD10: Bought after 07/24 b/o. Added at the 21dema.
A11: BIL | B11: Long | C11: Tbill ETF | D11: 2778.4118 | E11: 91.54 | F11: =E11*D11 -> 254335.82 | G11: 254613.66 | H11: =G11/D11 -> 91.640001 | I11: =F11-G11 -> -277.84383 | J11: =E11-H11 -> -0.10000095 | L11: =DAYS360(K11,$C$1) -> 44521 | M11: =(I11/G11) -> -0.0010912369 | R11: =Q11*0.93 -> 0 | T11: =Q11*1.25 -> 0 | U11: =Q11*1.5 -> 0 | V11: =Q11*2 -> 0 | W11: =H11-(H11*0.07) -> 85.225201 | Y11: =(X11-H11)/H11 -> -1 | Z11: =F11/F$16 -> 0.49053923
A12: SQQQ | B12: Long | C12: QQQ Triple short | D12: 511.2918 | E12: 17.77 | F12: =E12*D12 -> 9085.6553 | G12: 24797.66 | H12: =G12/D12 -> 48.500015 | I12: =F12-G12 -> -15712.005 | J12: =E12-H12 -> -30.730015 | L12: =DAYS360(K12,$C$1) -> 44521 | M12: =(I12/G12) -> -0.63360836 | R12: =Q12*0.93 -> 0 | T12: =Q12*1.25 -> 0 | U12: =Q12*1.5 -> 0 | V12: =Q12*2 -> 0 | W12: =H12-(H12*0.07) -> 45.105014 | Y12: =(X12-H12)/H12 -> -1 | Z12: =F12/F$16 -> 0.017523566
F13: =E13*D13 -> 0 | H13: =G13/D13 -> #DIV/0! | I13: =F13-G13 -> 0 | J13: =E13-H13 -> #DIV/0! | L13: =DAYS360(K13,$C$1) -> 44521 | M13: =(I13/G13) -> #DIV/0! | R13: =Q13*0.93 -> 0 | T13: =Q13*1.25 -> 0 | U13: =Q13*1.5 -> 0 | V13: =Q13*2 -> 0 | W13: =H13-(H13*0.07) -> #DIV/0! | Y13: =(X13-H13)/H13 -> #DIV/0! | Z13: =F13/F$16 -> 0
A14: Sub-Total | F14: =SUM(F6:F13) -> 452410.11 | G14: =SUM(G6:G13) -> 453531.88 | I14: =SUM(I6:I13) -> -1121.7697
D15: Cash, other | F15: 66072 | G15: =F15/F16 -> 0.12743352
D16: Total | F16: =SUM(F14:F15) -> 518482.11
